Workbook

Sheet הוראות
B1: איך משתמשים בקובץ – תכנית חוסן
B3: חשוב – הגיליונות נעולים | C3: אפשר לכתוב רק בתאים הצבעוניים (צהוב בהגדרות, שמנת בהצעה). כל השאר – נוסחאות – נעול, כך שאי אפשר למחוק אותן בטעות. אם ממש צריך לשנות משהו אחר: סקירה ← ביטול הגנת גיליון (אין סיסמה).
B4: 1. פעם אחת | C4: ממלאים את גיליון "הגדרות": שם מלא, מס׳ עוסק מורשה, טלפון ואיש קשר בחווה. תאים צהובים = למילוי. כל הגיליונות מושכים את הפרטים משם.
B5: 2. אוגוסט–ספטמבר 2026 | C5: גיליון אחד ל־19/08–30/09/2026, עם כל ימי שלישי ורביעי בתקופה. מוחקים (Delete) את התאריך של מפגש שלא היה – השורה מתרוקנת ולא מחויבת. מתקנים תאריך שהשתנה, ובשורות הריקות בסוף מוסיפים מפגשים נוספים.
B6: 3. מאוקטובר – בסוף כל חודש | C6: פותחים את הגיליון של החודש. ימי המפגש (בהגדרות: רביעי, ואפשר להוסיף יום שני) ממולאים אוטומטית. גם כאן אפשר למחוק או לשנות כל תאריך, ולהוסיף תאריכים בשורות הריקות.
B7: 4. סטטוס כל מפגש | C7: בעמודה "סטטוס" בוחרים: "התקיים"; "בוטל בהתראה" – בוטל עד 48 שעות לפני, ללא חיוב (השורה תימחק בקו); "בוטל ללא התראה" – פחות מ־48 שעות לפני, בחיוב.
B8: 5. משתתפים | C8: "משתתפים שסוכמו" ממולא אוטומטית מההגדרות (6). אם החווה עדכנה עד 24 שעות לפני – מקלידים את המספר המעודכן. ב"הגיעו בפועל" רושמים כמה הגיעו (1–7). החיוב הוא לפי הגבוה מביניהם – כך אי־הגעה ללא עדכון מחויבת לפי מה שסוכם.
B9: 6. פרויקטים מיוחדים | C9: בשתי העמודות השמאליות רושמים פרויקטים שאושרו ע״י החווה – תיאור וסכום לפני מע״מ (לפי עלות החומרים). הם נכנסים לסיכום בנפרד.
B10: 7. שליחה | C10: קובץ ← שמירה בשם / ייצוא ← PDF, ושולחים לחווה. כל גיליון מוגדר לעמוד A4 אחד.
B11: חודש חדש אחרי ספטמבר 2027 | C11: לוחצים ימני על לשונית של חודש ← העבר או העתק ← יצירת עותק, ומשנים בעותק את התא "חודש השירות" לתאריך כלשהו בחודש החדש (למשל 1/10/2027).
B12: שינוי מחירים / תנאים | C12: משנים בגיליון "הגדרות" – כל הגיליונות מתעדכנים.
B14: מקרא צבעים
C15: תא צהוב בגיליון "הגדרות" – למילוי פעם אחת
C16: תא ברקע שמנת בגיליון הצעה – למילוי או לעריכה (תאריכים, סטטוס, משתתפים, פרויקטים)
B18: דוגמה לשורת פרויקט מיוחד
B19: פרויקט מיוחד – תיאור | C19: פרויקט מיוחד – סכום (₪)
B20: פרגולת עץ לפינת הישיבה | C20: 850

Sheet הגדרות
B1: הגדרות קבועות – ממלאים פעם אחת
B2: תאים צהובים = למילוי. כל הגיליונות מושכים את הנתונים מכאן.
B4: פרטי העסק (הספק) | F4: רשימת ימים
B5: שם העסק | C5: הנגרייה | F5: ראשון
B6: שם מלא | C6: (למילוי) | F6: שני
B7: עוסק מורשה מס׳ | C7: (למילוי) | F7: שלישי
B8: טלפון | C8: (למילוי) | F8: רביעי
B9: אימייל | C9: nettaamit21@gmail.com | F9: חמישי
F10: שישי
B11: פרטי הלקוח | F11: שבת
B12: שם הלקוח | C12: חוות רום
B13: כתובת | C13: הר כמון
B14: איש קשר | C14: (למילוי)
B16: המפגשים והתמחור
B17: שם התכנית | C17: תכנית חוסן
B18: שם הקבוצה (לא חובה) | C18: הוותיקה | D18: מס׳ יום
B19: יום מפגש קבוע | C19: רביעי | D19: =MATCH(C19,$F$5:$F$11,0) -> 4
B20: יום מפגש נוסף (לא חובה) | D20: =IFERROR(MATCH(C20,$F$5:$F$11,0),D19) -> 4
B21: שעות עבודה למפגש | C21: 6
B22: פירוט שעות העבודה | C22: שעת נסיעה לרכישת עצים ומלאי, שעתיים התארגנות וניקיון, שעתיים סדנא ומפגש צוות שבועי
B23: שכר עבודה למפגש (₪) | C23: 1000
B24: עלות אחזקה למפגש (₪) – שכירות, חשמל, ביטוח | C24: 150
B25: בלאי ציוד למפגש (₪) – מסורית גקסון, ניירות שיוף, ברגים | C25: 150
B26: תשלום בסיסי למפגש (מחושב) | C26: =SUM(C23:C25) -> 1300
B27: תקציב עץ למשתתף (₪) | C27: 100
B28: משתתפים שסוכמו – ברירת מחדל | C28: 6
B29: מקסימום משתתפים לחיוב | C29: 7
B30: ביטול ללא התראה (פחות מ־48 שעות) – שיעור חיוב | C30: 1
B31: שיעור מע״מ | C31: 0.18
B33: הערות שיופיעו בהצעה
B34: הערה 1 | C34: המחירים אינם כוללים מע״מ. מע״מ יתווסף כחוק.
B35: הערה 2 | C35: פרויקטים גדולים ומיוחדים מתומחרים בנפרד לפי עלות החומרים, באישור החווה.
B36: הערה 3 (למשל תנאי תשלום)
B38: תנאי ביטול ותנאים כלליים (מופיעים בתחתית ההצעה)
B39: תנאי 1 | C39: ביטול מלא של הסדנא: ביטול של עד 48 שעות לפני מועד הסדנא – ללא חיוב.
B40: תנאי 2 | C40: מספר המשתתפים: הסדנא מתוכננת ומוכנה מראש בהתאם למספר המשתתפים שסוכם, עד 6 משתתפים.
B41: תנאי 3 | C41: הפחתת מספר המשתתפים: יש לעדכן על שינוי במספר המשתתפים עד 24 שעות לפני הסדנא.
B42: תנאי 4 | C42: אי הגעה ללא עדכון מראש: במקרה שבו סוכם על 6 משתתפים ובפועל הגיעו פחות, ללא עדכון של 24 שעות לפני, החיוב יישאר בהתאם למספר המשתתפים שסוכם מראש, וזאת בשל הכנת ורכישת חומרי גלם מראש.

Sheet אוגוסט–ספטמבר 2026
A1: הצעת מחיר
A2: =הגדרות!$C$17&" · מפגשים בימי שלישי ורביעי · "&$I$11 -> תכנית חוסן · מפגשים בימי שלישי ורביעי · 19/08/2026 – 30/09/2026
A4: מאת | G4: לכבוד
A5: שם העסק | C5: =הגדרות!$C$5 -> הנגרייה | G5: שם הלקוח | I5: =הגדרות!$C$12 -> חוות רום
A6: שם מלא | C6: =הגדרות!$C$6 -> (למילוי) | G6: כתובת | I6: =הגדרות!$C$13 -> הר כמון
A7: עוסק מורשה | C7: =הגדרות!$C$7 -> (למילוי) | G7: איש קשר | I7: =הגדרות!$C$14 -> (למילוי)
A8: טלפון | C8: =הגדרות!$C$8 -> (למילוי)
A9: אימייל | C9: =הגדרות!$C$9 -> nettaamit21@gmail.com
A11: מס׳ הצעה | C11: חוסן-2026-08/09 | G11: תקופה | I11: 19/08/2026 – 30/09/2026
A12: תאריך | C12: 46314 | G12: תמחור | I12: =TEXT(הגדרות!$C$26,"#,##0")&" ₪ למפגש + "&TEXT(הגדרות!$C$27,"#,##0")&" ₪ למשתתף" -> 1,300 ₪ למפגש + 100 ₪ למשתתף
A13: ="מפגשי "&הגדרות!$C$17 -> מפגשי תכנית חוסן | K13: פרויקטים מיוחדים – באישור החווה
A14: # | B14: תאריך | C14: יום | D14: סטטוס | E14: משתתפים שסוכמו | F14: הגיעו בפועל | G14: משתתפים לחיוב | H14: תשלום בסיסי (₪) | I14: תקציב עץ (₪) | J14: סה״כ למפגש (₪) | K14: פרויקט מיוחד – תיאור | L14: פרויקט מיוחד – סכום (₪)
A15: =IF(B15="","",COUNT($B$15:B15)) -> 1 | B15: 46253 | C15: =IF(B15="","",INDEX(הגדרות!$F$5:$F$11,WEEKDAY(B15))) -> רביעי | D15: התקיים | E15: =IF(B15="","",הגדרות!$C$28) -> 6 | G15: =IF(B15="","",IF(O15=0,0,MIN(הגדרות!$C$29,MAX(E15,F15)))) -> 6 | H15: =IF(B15="","",O15*הגדרות!$C$26) -> 1300 | I15: =IF(B15="","",O15*G15*הגדרות!$C$27) -> 600 | J15: =IF(B15="","",H15+I15) -> 1900 | O15: =IF(B15="","",IF(D15="בוטל בהתראה",0,IF(D15="בוטל ללא התראה",הגדרות!$C$30,1))) -> 1
A16: =IF(B16="","",COUNT($B$15:B16)) -> 2 | B16: 46259 | C16: =IF(B16="","",INDEX(הגדרות!$F$5:$F$11,WEEKDAY(B16))) -> שלישי | D16: התקיים | E16: =IF(B16="","",הגדרות!$C$28) -> 6 | G16: =IF(B16="","",IF(O16=0,0,MIN(הגדרות!$C$29,MAX(E16,F16)))) -> 6 | H16: =IF(B16="","",O16*הגדרות!$C$26) -> 1300 | I16: =IF(B16="","",O16*G16*הגדרות!$C$27) -> 600 | J16: =IF(B16="","",H16+I16) -> 1900 | O16: =IF(B16="","",IF(D16="בוטל בהתראה",0,IF(D16="בוטל ללא התראה",הגדרות!$C$30,1))) -> 1
A17: =IF(B17="","",COUNT($B$15:B17)) -> 3 | B17: 46260 | C17: =IF(B17="","",INDEX(הגדרות!$F$5:$F$11,WEEKDAY(B17))) -> רביעי | D17: התקיים | E17: =IF(B17="","",הגדרות!$C$28) -> 6 | G17: =IF(B17="","",IF(O17=0,0,MIN(הגדרות!$C$29,MAX(E17,F17)))) -> 6 | H17: =IF(B17="","",O17*הגדרות!$C$26) -> 1300 | I17: =IF(B17="","",O17*G17*הגדרות!$C$27) -> 600 | J17: =IF(B17="","",H17+I17) -> 1900 | O17: =IF(B17="","",IF(D17="בוטל בהתראה",0,IF(D17="בוטל ללא התראה",הגדרות!$C$30,1))) -> 1
A18: =IF(B18="","",COUNT($B$15:B18)) -> 4 | B18: 46266 | C18: =IF(B18="","",INDEX(הגדרות!$F$5:$F$11,WEEKDAY(B18))) -> שלישי | D18: התקיים | E18: =IF(B18="","",הגדרות!$C$28) -> 6 | G18: =IF(B18="","",IF(O18=0,0,MIN(הגדרות!$C$29,MAX(E18,F18)))) -> 6 | H18: =IF(B18="","",O18*הגדרות!$C$26) -> 1300 | I18: =IF(B18="","",O18*G18*הגדרות!$C$27) -> 600 | J18: =IF(B18="","",H18+I18) -> 1900 | O18: =IF(B18="","",IF(D18="בוטל בהתראה",0,IF(D18="בוטל ללא התראה",הגדרות!$C$30,1))) -> 1
A19: =IF(B19="","",COUNT($B$15:B19)) -> 5 | B19: 46267 | C19: =IF(B19="","",INDEX(הגדרות!$F$5:$F$11,WEEKDAY(B19))) -> רביעי | D19: התקיים | E19: =IF(B19="","",הגדרות!$C$28) -> 6 | G19: =IF(B19="","",IF(O19=0,0,MIN(הגדרות!$C$29,MAX(E19,F19)))) -> 6 | H19: =IF(B19="","",O19*הגדרות!$C$26) -> 1300 | I19: =IF(B19="","",O19*G19*הגדרות!$C$27) -> 600 | J19: =IF(B19="","",H19+I19) -> 1900 | O19: =IF(B19="","",IF(D19="בוטל בהתראה",0,IF(D19="בוטל ללא התראה",הגדרות!$C$30,1))) -> 1
A20: =IF(B20="","",COUNT($B$15:B20)) -> 6 | B20: 46273 | C20: =IF(B20="","",INDEX(הגדרות!$F$5:$F$11,WEEKDAY(B20))) -> שלישי | D20: התקיים | E20: =IF(B20="","",הגדרות!$C$28) -> 6 | G20: =IF(B20="","",IF(O20=0,0,MIN(הגדרות!$C$29,MAX(E20,F20)))) -> 6 | H20: =IF(B20="","",O20*הגדרות!$C$26) -> 1300 | I20: =IF(B20="","",O20*G20*הגדרות!$C$27) -> 600 | J20: =IF(B20="","",H20+I20) -> 1900 | O20: =IF(B20="","",IF(D20="בוטל בהתראה",0,IF(D20="בוטל ללא התראה",הגדרות!$C$30,1))) -> 1
A21: =IF(B21="","",COUNT($B$15:B21)) -> 7 | B21: 46274 | C21: =IF(B21="","",INDEX(הגדרות!$F$5:$F$11,WEEKDAY(B21))) -> רביעי | D21: התקיים | E21: =IF(B21="","",הגדרות!$C$28) -> 6 | G21: =IF(B21="","",IF(O21=0,0,MIN(הגדרות!$C$29,MAX(E21,F21)))) -> 6 | H21: =IF(B21="","",O21*הגדרות!$C$26) -> 1300 | I21: =IF(B21="","",O21*G21*הגדרות!$C$27) -> 600 | J21: =IF(B21="","",H21+I21) -> 1900 | O21: =IF(B21="","",IF(D21="בוטל בהתראה",0,IF(D21="בוטל ללא התראה",הגדרות!$C$30,1))) -> 1
A22: =IF(B22="","",COUNT($B$15:B22)) -> 8 | B22: 46280 | C22: =IF(B22="","",INDEX(הגדרות!$F$5:$F$11,WEEKDAY(B22))) -> שלישי | D22: התקיים | E22: =IF(B22="","",הגדרות!$C$28) -> 6 | G22: =IF(B22="","",IF(O22=0,0,MIN(הגדרות!$C$29,MAX(E22,F22)))) -> 6 | H22: =IF(B22="","",O22*הגדרות!$C$26) -> 1300 | I22: =IF(B22="","",O22*G22*הגדרות!$C$27) -> 600 | J22: =IF(B22="","",H22+I22) -> 1900 | O22: =IF(B22="","",IF(D22="בוטל בהתראה",0,IF(D22="בוטל ללא התראה",הגדרות!$C$30,1))) -> 1
A23: =IF(B23="","",COUNT($B$15:B23)) -> 9 | B23: 46281 | C23: =IF(B23="","",INDEX(הגדרות!$F$5:$F$11,WEEKDAY(B23))) -> רביעי | D23: התקיים | E23: =IF(B23="","",הגדרות!$C$28) -> 6 | G23: =IF(B23="","",IF(O23=0,0,MIN(הגדרות!$C$29,MAX(E23,F23)))) -> 6 | H23: =IF(B23="","",O23*הגדרות!$C$26) -> 1300 | I23: =IF(B23="","",O23*G23*הגדרות!$C$27) -> 600 | J23: =IF(B23="","",H23+I23) -> 1900 | O23: =IF(B23="","",IF(D23="בוטל בהתראה",0,IF(D23="בוטל ללא התראה",הגדרות!$C$30,1))) -> 1
A24: =IF(B24="","",COUNT($B$15:B24)) -> 10 | B24: 46287 | C24: =IF(B24="","",INDEX(הגדרות!$F$5:$F$11,WEEKDAY(B24))) -> שלישי | D24: התקיים | E24: =IF(B24="","",הגדרות!$C$28) -> 6 | G24: =IF(B24="","",IF(O24=0,0,MIN(הגדרות!$C$29,MAX(E24,F24)))) -> 6 | H24: =IF(B24="","",O24*הגדרות!$C$26) -> 1300 | I24: =IF(B24="","",O24*G24*הגדרות!$C$27) -> 600 | J24: =IF(B24="","",H24+I24) -> 1900 | O24: =IF(B24="","",IF(D24="בוטל בהתראה",0,IF(D24="בוטל ללא התראה",הגדרות!$C$30,1))) -> 1
A25: =IF(B25="","",COUNT($B$15:B25)) -> 11 | B25: 46288 | C25: =IF(B25="","",INDEX(הגדרות!$F$5:$F$11,WEEKDAY(B25))) -> רביעי | D25: התקיים | E25: =IF(B25="","",הגדרות!$C$28) -> 6 | G25: =IF(B25="","",IF(O25=0,0,MIN(הגדרות!$C$29,MAX(E25,F25)))) -> 6 | H25: =IF(B25="","",O25*הגדרות!$C$26) -> 1300 | I25: =IF(B25="","",O25*G25*הגדרות!$C$27) -> 600 | J25: =IF(B25="","",H25+I25) -> 1900 | O25: =IF(B25="","",IF(D25="בוטל בהתראה",0,IF(D25="בוטל ללא התראה",הגדרות!$C$30,1))) -> 1
A26: =IF(B26="","",COUNT($B$15:B26)) -> 12 | B26: 46294 | C26: =IF(B26="","",INDEX(הגדרות!$F$5:$F$11,WEEKDAY(B26))) -> שלישי | D26: התקיים | E26: =IF(B26="","",הגדרות!$C$28) -> 6 | G26: =IF(B26="","",IF(O26=0,0,MIN(הגדרות!$C$29,MAX(E26,F26)))) -> 6 | H26: =IF(B26="","",O26*הגדרות!$C$26) -> 1300 | I26: =IF(B26="","",O26*G26*הגדרות!$C$27) -> 600 | J26: =IF(B26="","",H26+I26) -> 1900 | O26: =IF(B26="","",IF(D26="בוטל בהתראה",0,IF(D26="בוטל ללא התראה",הגדרות!$C$30,1))) -> 1
A27: =IF(B27="","",COUNT($B$15:B27)) -> 13 | B27: 46295 | C27: =IF(B27="","",INDEX(הגדרות!$F$5:$F$11,WEEKDAY(B27))) -> רביעי | D27: התקיים | E27: =IF(B27="","",הגדרות!$C$28) -> 6 | G27: =IF(B27="","",IF(O27=0,0,MIN(הגדרות!$C$29,MAX(E27,F27)))) -> 6 | H27: =IF(B27="","",O27*הגדרות!$C$26) -> 1300 | I27: =IF(B27="","",O27*G27*הגדרות!$C$27) -> 600 | J27: =IF(B27="","",H27+I27) -> 1900 | O27: =IF(B27="","",IF(D27="בוטל בהתראה",0,IF(D27="בוטל ללא התראה",הגדרות!$C$30,1))) -> 1
A28: =IF(B28="","",COUNT($B$15:B28)) | C28: =IF(B28="","",INDEX(הגדרות!$F$5:$F$11,WEEKDAY(B28))) | D28: התקיים | E28: =IF(B28="","",הגדרות!$C$28) | G28: =IF(B28="","",IF(O28=0,0,MIN(הגדרות!$C$29,MAX(E28,F28)))) | H28: =IF(B28="","",O28*הגדרות!$C$26) | I28: =IF(B28="","",O28*G28*הגדרות!$C$27) | J28: =IF(B28="","",H28+I28) | O28: =IF(B28="","",IF(D28="בוטל בהתראה",0,IF(D28="בוטל ללא התראה",הגדרות!$C$30,1)))
A29: =IF(B29="","",COUNT($B$15:B29)) | C29: =IF(B29="","",INDEX(הגדרות!$F$5:$F$11,WEEKDAY(B29))) | D29: התקיים | E29: =IF(B29="","",הגדרות!$C$28) | G29: =IF(B29="","",IF(O29=0,0,MIN(הגדרות!$C$29,MAX(E29,F29)))) | H29: =IF(B29="","",O29*הגדרות!$C$26) | I29: =IF(B29="","",O29*G29*הגדרות!$C$27) | J29: =IF(B29="","",H29+I29) | O29: =IF(B29="","",IF(D29="בוטל בהתראה",0,IF(D29="בוטל ללא התראה",הגדרות!$C$30,1)))
A30: =IF(B30="","",COUNT($B$15:B30)) | C30: =IF(B30="","",INDEX(הגדרות!$F$5:$F$11,WEEKDAY(B30))) | D30: התקיים | E30: =IF(B30="","",הגדרות!$C$28) | G30: =IF(B30="","",IF(O30=0,0,MIN(הגדרות!$C$29,MAX(E30,F30)))) | H30: =IF(B30="","",O30*הגדרות!$C$26) | I30: =IF(B30="","",O30*G30*הגדרות!$C$27) | J30: =IF(B30="","",H30+I30) | O30: =IF(B30="","",IF(D30="בוטל בהתראה",0,IF(D30="בוטל ללא התראה",הגדרות!$C$30,1)))
A31: =IF(B31="","",COUNT($B$15:B31)) | C31: =IF(B31="","",INDEX(הגדרות!$F$5:$F$11,WEEKDAY(B31))) | D31: התקיים | E31: =IF(B31="","",הגדרות!$C$28) | G31: =IF(B31="","",IF(O31=0,0,MIN(הגדרות!$C$29,MAX(E31,F31)))) | H31: =IF(B31="","",O31*הגדרות!$C$26) | I31: =IF(B31="","",O31*G31*הגדרות!$C$27) | J31: =IF(B31="","",H31+I31) | O31: =IF(B31="","",IF(D31="בוטל בהתראה",0,IF(D31="בוטל ללא התראה",הגדרות!$C$30,1)))
A32: סה״כ | G32: =SUM(G15:G31) -> 78 | H32: =SUM(H15:H31) -> 16900 | I32: =SUM(I15:I31) -> 7800 | J32: =SUM(J15:J31) -> 24700 | L32: =SUM(L15:L31) -> 0
A33: סטטוס: "בוטל בהתראה" – עד 48 שעות לפני המפגש, ללא חיוב · "בוטל ללא התראה" – פחות מ־48 שעות לפני, בחיוב לפי מספר המשתתפים שסוכם · משתתפים לחיוב = הגבוה מבין שסוכמו (כפי שעודכן עד 24 שעות לפני) ומי שהגיעו בפועל.
A35: פירוט התמחור | H35: ="תשלום בסיסי ("&COUNTIF(O15:O31,">0")&" מפגשים)" -> תשלום בסיסי (13 מפגשים) | L35: =H32 -> 16900
A36: ="• תשלום בסיסי למפגש – "&TEXT(הגדרות!$C$26,"#,##0")&" ₪: "&הגדרות!$C$21&" שעות עבודה ("&TEXT(הגדרות!$C$23,"#,##0")&" ₪) – "&הגדרות!$C$22&"." -> • תשלום בסיסי למפגש – 1,300 ₪: 6 שעות עבודה (1,000 ₪) – שעת נסיעה לרכישת עצים ומלאי, שעתיים התארגנות וניקיון, שעתיים סדנא ומפגש צוות שבועי. | H36: ="תקציב עץ ("&G32&" משתתפים)" -> תקציב עץ (78 משתתפים) | L36: =I32 -> 7800
A37: ="• עלות אחזקה "&TEXT(הגדרות!$C$24,"#,##0")&" ₪ (שכירות, חשמל, ביטוח) ובלאי ציוד "&TEXT(הגדרות!$C$25,"#,##0")&" ₪ (מסורית גקסון, ניירות שיוף, ברגים)." -> • עלות אחזקה 150 ₪ (שכירות, חשמל, ביטוח) ובלאי ציוד 150 ₪ (מסורית גקסון, ניירות שיוף, ברגים). | H37: פרויקטים מיוחדים | L37: =L32 -> 0
A38: ="• תקציב עץ: "&TEXT(הגדרות!$C$27,"#,##0")&" ₪ למשתתף." -> • תקציב עץ: 100 ₪ למשתתף. | H38: סה״כ לפני מע״מ | L38: =L35+L36+L37 -> 24700
A39: =IF(הגדרות!$C$34="","","• "&הגדרות!$C$34) -> • המחירים אינם כוללים מע״מ. מע״מ יתווסף כחוק. | H39: ="מע״מ "&ROUND(הגדרות!$C$31*100,1)&"%" -> מע״מ 18% | L39: =ROUND(L38*הגדרות!$C$31,2) -> 4446
A40: =IF(הגדרות!$C$35="","","• "&הגדרות!$C$35) -> • פרויקטים גדולים ומיוחדים מתומחרים בנפרד לפי עלות החומרים, באישור החווה. | H40: סה״כ לתשלום (כולל מע״מ) | L40: =L38+L39 -> 29146
A41: =IF(הגדרות!$C$36="","","• "&הגדרות!$C$36)
A42: תנאי ביטול ותנאים כלליים
A43: ="• "&הגדרות!$C$39 -> • ביטול מלא של הסדנא: ביטול של עד 48 שעות לפני מועד הסדנא – ללא חיוב.
...

Sheet אוקטובר 2026
A1: הצעת מחיר | N1: =DATE(YEAR($I$11),MONTH($I$11),1) -> 46296
A2: =הגדרות!$C$17&" · "&"מפגש שבועי בימי "&הגדרות!$C$19&IF(הגדרות!$C$20="",""," ו"&הגדרות!$C$20)&IF(הגדרות!$C$18="",""," ("&הגדרות!$C$18&")")&" · "&CHOOSE(MONTH($N$1),"ינואר","פברואר","מרץ","אפריל","מאי","יוני","יולי","אוגוסט","ספטמבר","אוקטובר","נובמבר","דצמבר")&" "&YEAR($N$1) -> תכנית חוסן · מפגש שבועי בימי רביעי (הוותיקה) · אוקטובר 2026 | N2: =EOMONTH($N$1,0) -> 46326
A4: מאת | G4: לכבוד
A5: שם העסק | C5: =הגדרות!$C$5 -> הנגרייה | G5: שם הלקוח | I5: =הגדרות!$C$12 -> חוות רום
A6: שם מלא | C6: =הגדרות!$C$6 -> (למילוי) | G6: כתובת | I6: =הגדרות!$C$13 -> הר כמון
A7: עוסק מורשה | C7: =הגדרות!$C$7 -> (למילוי) | G7: איש קשר | I7: =הגדרות!$C$14 -> (למילוי)
A8: טלפון | C8: =הגדרות!$C$8 -> (למילוי)
A9: אימייל | C9: =הגדרות!$C$9 -> nettaamit21@gmail.com
A11: מס׳ הצעה | C11: ="חוסן-"&YEAR($N$1)&"-"&TEXT(MONTH($N$1),"00") -> חוסן-2026-10 | G11: חודש השירות | I11: 46296
A12: תאריך | C12: =$N$2 -> 46326 | G12: תמחור | I12: =TEXT(הגדרות!$C$26,"#,##0")&" ₪ למפגש + "&TEXT(הגדרות!$C$27,"#,##0")&" ₪ למשתתף" -> 1,300 ₪ למפגש + 100 ₪ למשתתף
A13: ="מפגשי "&הגדרות!$C$17 -> מפגשי תכנית חוסן | K13: פרויקטים מיוחדים – באישור החווה
A14: # | B14: תאריך | C14: יום | D14: סטטוס | E14: משתתפים שסוכמו | F14: הגיעו בפועל | G14: משתתפים לחיוב | H14: תשלום בסיסי (₪) | I14: תקציב עץ (₪) | J14: סה״כ למפגש (₪) | K14: פרויקט מיוחד – תיאור | L14: פרויקט מיוחד – סכום (₪)
A15: =IF(B15="","",COUNT($B$15:B15)) -> 1 | B15: =IF(N15="","",N15) -> 46302 | C15: =IF(B15="","",INDEX(הגדרות!$F$5:$F$11,WEEKDAY(B15))) -> רביעי | D15: התקיים | E15: =IF(B15="","",הגדרות!$C$28) -> 6 | G15: =IF(B15="","",IF(O15=0,0,MIN(הגדרות!$C$29,MAX(E15,F15)))) -> 6 | H15: =IF(B15="","",O15*הגדרות!$C$26) -> 1300 | I15: =IF(B15="","",O15*G15*הגדרות!$C$27) -> 600 | J15: =IF(B15="","",H15+I15) -> 1900 | N15: =$N$1+MIN(MOD(הגדרות!$D$19-WEEKDAY($N$1),7),MOD(הגדרות!$D$20-WEEKDAY($N$1),7)) -> 46302 | O15: =IF(B15="","",IF(D15="בוטל בהתראה",0,IF(D15="בוטל ללא התראה",הגדרות!$C$30,1))) -> 1
A16: =IF(B16="","",COUNT($B$15:B16)) -> 2 | B16: =IF(N16="","",N16) -> 46309 | C16: =IF(B16="","",INDEX(הגדרות!$F$5:$F$11,WEEKDAY(B16))) -> רביעי | D16: התקיים | E16: =IF(B16="","",הגדרות!$C$28) -> 6 | G16: =IF(B16="","",IF(O16=0,0,MIN(הגדרות!$C$29,MAX(E16,F16)))) -> 6 | H16: =IF(B16="","",O16*הגדרות!$C$26) -> 1300 | I16: =IF(B16="","",O16*G16*הגדרות!$C$27) -> 600 | J16: =IF(B16="","",H16+I16) -> 1900 | N16: =IF(N15="","",IF(N15+MIN(MOD(הגדרות!$D$19-WEEKDAY(N15)-1,7)+1,MOD(הגדרות!$D$20-WEEKDAY(N15)-1,7)+1)>$N$2,"",N15+MIN(MOD(הגדרות!$D$19-WEEKDAY(N15)-1,7)+1,MOD(הגדרות!$D$20-WEEKDAY(N15)-1,7)+1))) -> 46309 | O16: =IF(B16="","",IF(D16="בוטל בהתראה",0,IF(D16="בוטל ללא התראה",הגדרות!$C$30,1))) -> 1
A17: =IF(B17="","",COUNT($B$15:B17)) -> 3 | B17: =IF(N17="","",N17) -> 46316 | C17: =IF(B17="","",INDEX(הגדרות!$F$5:$F$11,WEEKDAY(B17))) -> רביעי | D17: התקיים | E17: =IF(B17="","",הגדרות!$C$28) -> 6 | G17: =IF(B17="","",IF(O17=0,0,MIN(הגדרות!$C$29,MAX(E17,F17)))) -> 6 | H17: =IF(B17="","",O17*הגדרות!$C$26) -> 1300 | I17: =IF(B17="","",O17*G17*הגדרות!$C$27) -> 600 | J17: =IF(B17="","",H17+I17) -> 1900 | N17: =IF(N16="","",IF(N16+MIN(MOD(הגדרות!$D$19-WEEKDAY(N16)-1,7)+1,MOD(הגדרות!$D$20-WEEKDAY(N16)-1,7)+1)>$N$2,"",N16+MIN(MOD(הגדרות!$D$19-WEEKDAY(N16)-1,7)+1,MOD(הגדרות!$D$20-WEEKDAY(N16)-1,7)+1))) -> 46316 | O17: =IF(B17="","",IF(D17="בוטל בהתראה",0,IF(D17="בוטל ללא התראה",הגדרות!$C$30,1))) -> 1
A18: =IF(B18="","",COUNT($B$15:B18)) -> 4 | B18: =IF(N18="","",N18) -> 46323 | C18: =IF(B18="","",INDEX(הגדרות!$F$5:$F$11,WEEKDAY(B18))) -> רביעי | D18: התקיים | E18: =IF(B18="","",הגדרות!$C$28) -> 6 | G18: =IF(B18="","",IF(O18=0,0,MIN(הגדרות!$C$29,MAX(E18,F18)))) -> 6 | H18: =IF(B18="","",O18*הגדרות!$C$26) -> 1300 | I18: =IF(B18="","",O18*G18*הגדרות!$C$27) -> 600 | J18: =IF(B18="","",H18+I18) -> 1900 | N18: =IF(N17="","",IF(N17+MIN(MOD(הגדרות!$D$19-WEEKDAY(N17)-1,7)+1,MOD(הגדרות!$D$20-WEEKDAY(N17)-1,7)+1)>$N$2,"",N17+MIN(MOD(הגדרות!$D$19-WEEKDAY(N17)-1,7)+1,MOD(הגדרות!$D$20-WEEKDAY(N17)-1,7)+1))) -> 46323 | O18: =IF(B18="","",IF(D18="בוטל בהתראה",0,IF(D18="בוטל ללא התראה",הגדרות!$C$30,1))) -> 1
A19: =IF(B19="","",COUNT($B$15:B19)) | B19: =IF(N19="","",N19) | C19: =IF(B19="","",INDEX(הגדרות!$F$5:$F$11,WEEKDAY(B19))) | D19: התקיים | E19: =IF(B19="","",הגדרות!$C$28) | G19: =IF(B19="","",IF(O19=0,0,MIN(הגדרות!$C$29,MAX(E19,F19)))) | H19: =IF(B19="","",O19*הגדרות!$C$26) | I19: =IF(B19="","",O19*G19*הגדרות!$C$27) | J19: =IF(B19="","",H19+I19) | N19: =IF(N18="","",IF(N18+MIN(MOD(הגדרות!$D$19-WEEKDAY(N18)-1,7)+1,MOD(הגדרות!$D$20-WEEKDAY(N18)-1,7)+1)>$N$2,"",N18+MIN(MOD(הגדרות!$D$19-WEEKDAY(N18)-1,7)+1,MOD(הגדרות!$D$20-WEEKDAY(N18)-1,7)+1))) | O19: =IF(B19="","",IF(D19="בוטל בהתראה",0,IF(D19="בוטל ללא התראה",הגדרות!$C$30,1)))
A20: =IF(B20="","",COUNT($B$15:B20)) | B20: =IF(N20="","",N20) | C20: =IF(B20="","",INDEX(הגדרות!$F$5:$F$11,WEEKDAY(B20))) | D20: התקיים | E20: =IF(B20="","",הגדרות!$C$28) | G20: =IF(B20="","",IF(O20=0,0,MIN(הגדרות!$C$29,MAX(E20,F20)))) | H20: =IF(B20="","",O20*הגדרות!$C$26) | I20: =IF(B20="","",O20*G20*הגדרות!$C$27) | J20: =IF(B20="","",H20+I20) | N20: =IF(N19="","",IF(N19+MIN(MOD(הגדרות!$D$19-WEEKDAY(N19)-1,7)+1,MOD(הגדרות!$D$20-WEEKDAY(N19)-1,7)+1)>$N$2,"",N19+MIN(MOD(הגדרות!$D$19-WEEKDAY(N19)-1,7)+1,MOD(הגדרות!$D$20-WEEKDAY(N19)-1,7)+1))) | O20: =IF(B20="","",IF(D20="בוטל בהתראה",0,IF(D20="בוטל ללא התראה",הגדרות!$C$30,1)))
A21: =IF(B21="","",COUNT($B$15:B21)) | B21: =IF(N21="","",N21) | C21: =IF(B21="","",INDEX(הגדרות!$F$5:$F$11,WEEKDAY(B21))) | D21: התקיים | E21: =IF(B21="","",הגדרות!$C$28) | G21: =IF(B21="","",IF(O21=0,0,MIN(הגדרות!$C$29,MAX(E21,F21)))) | H21: =IF(B21="","",O21*הגדרות!$C$26) | I21: =IF(B21="","",O21*G21*הגדרות!$C$27) | J21: =IF(B21="","",H21+I21) | N21: =IF(N20="","",IF(N20+MIN(MOD(הגדרות!$D$19-WEEKDAY(N20)-1,7)+1,MOD(הגדרות!$D$20-WEEKDAY(N20)-1,7)+1)>$N$2,"",N20+MIN(MOD(הגדרות!$D$19-WEEKDAY(N20)-1,7)+1,MOD(הגדרות!$D$20-WEEKDAY(N20)-1,7)+1))) | O21: =IF(B21="","",IF(D21="בוטל בהתראה",0,IF(D21="בוטל ללא התראה",הגדרות!$C$30,1)))
A22: =IF(B22="","",COUNT($B$15:B22)) | B22: =IF(N22="","",N22) | C22: =IF(B22="","",INDEX(הגדרות!$F$5:$F$11,WEEKDAY(B22))) | D22: התקיים | E22: =IF(B22="","",הגדרות!$C$28) | G22: =IF(B22="","",IF(O22=0,0,MIN(הגדרות!$C$29,MAX(E22,F22)))) | H22: =IF(B22="","",O22*הגדרות!$C$26) | I22: =IF(B22="","",O22*G22*הגדרות!$C$27) | J22: =IF(B22="","",H22+I22) | N22: =IF(N21="","",IF(N21+MIN(MOD(הגדרות!$D$19-WEEKDAY(N21)-1,7)+1,MOD(הגדרות!$D$20-WEEKDAY(N21)-1,7)+1)>$N$2,"",N21+MIN(MOD(הגדרות!$D$19-WEEKDAY(N21)-1,7)+1,MOD(הגדרות!$D$20-WEEKDAY(N21)-1,7)+1))) | O22: =IF(B22="","",IF(D22="בוטל בהתראה",0,IF(D22="בוטל ללא התראה",הגדרות!$C$30,1)))
A23: =IF(B23="","",COUNT($B$15:B23)) | B23: =IF(N23="","",N23) | C23: =IF(B23="","",INDEX(הגדרות!$F$5:$F$11,WEEKDAY(B23))) | D23: התקיים | E23: =IF(B23="","",הגדרות!$C$28) | G23: =IF(B23="","",IF(O23=0,0,MIN(הגדרות!$C$29,MAX(E23,F23)))) | H23: =IF(B23="","",O23*הגדרות!$C$26) | I23: =IF(B23="","",O23*G23*הגדרות!$C$27) | J23: =IF(B23="","",H23+I23) | N23: =IF(N22="","",IF(N22+MIN(MOD(הגדרות!$D$19-WEEKDAY(N22)-1,7)+1,MOD(הגדרות!$D$20-WEEKDAY(N22)-1,7)+1)>$N$2,"",N22+MIN(MOD(הגדרות!$D$19-WEEKDAY(N22)-1,7)+1,MOD(הגדרות!$D$20-WEEKDAY(N22)-1,7)+1))) | O23: =IF(B23="","",IF(D23="בוטל בהתראה",0,IF(D23="בוטל ללא התראה",הגדרות!$C$30,1)))
A24: =IF(B24="","",COUNT($B$15:B24)) | B24: =IF(N24="","",N24) | C24: =IF(B24="","",INDEX(הגדרות!$F$5:$F$11,WEEKDAY(B24))) | D24: התקיים | E24: =IF(B24="","",הגדרות!$C$28) | G24: =IF(B24="","",IF(O24=0,0,MIN(הגדרות!$C$29,MAX(E24,F24)))) | H24: =IF(B24="","",O24*הגדרות!$C$26) | I24: =IF(B24="","",O24*G24*הגדרות!$C$27) | J24: =IF(B24="","",H24+I24) | N24: =IF(N23="","",IF(N23+MIN(MOD(הגדרות!$D$19-WEEKDAY(N23)-1,7)+1,MOD(הגדרות!$D$20-WEEKDAY(N23)-1,7)+1)>$N$2,"",N23+MIN(MOD(הגדרות!$D$19-WEEKDAY(N23)-1,7)+1,MOD(הגדרות!$D$20-WEEKDAY(N23)-1,7)+1))) | O24: =IF(B24="","",IF(D24="בוטל בהתראה",0,IF(D24="בוטל ללא התראה",הגדרות!$C$30,1)))
A25: סה״כ | G25: =SUM(G15:G24) -> 24 | H25: =SUM(H15:H24) -> 5200 | I25: =SUM(I15:I24) -> 2400 | J25: =SUM(J15:J24) -> 7600 | L25: =SUM(L15:L24) -> 0
A26: סטטוס: "בוטל בהתראה" – עד 48 שעות לפני המפגש, ללא חיוב · "בוטל ללא התראה" – פחות מ־48 שעות לפני, בחיוב לפי מספר המשתתפים שסוכם · משתתפים לחיוב = הגבוה מבין שסוכמו (כפי שעודכן עד 24 שעות לפני) ומי שהגיעו בפועל.
A28: פירוט התמחור | H28: ="תשלום בסיסי ("&COUNTIF(O15:O24,">0")&" מפגשים)" -> תשלום בסיסי (4 מפגשים) | L28: =H25 -> 5200
A29: ="• תשלום בסיסי למפגש – "&TEXT(הגדרות!$C$26,"#,##0")&" ₪: "&הגדרות!$C$21&" שעות עבודה ("&TEXT(הגדרות!$C$23,"#,##0")&" ₪) – "&הגדרות!$C$22&"." -> • תשלום בסיסי למפגש – 1,300 ₪: 6 שעות עבודה (1,000 ₪) – שעת נסיעה לרכישת עצים ומלאי, שעתיים התארגנות וניקיון, שעתיים סדנא ומפגש צוות שבועי. | H29: ="תקציב עץ ("&G25&" משתתפים)" -> תקציב עץ (24 משתתפים) | L29: =I25 -> 2400
A30: ="• עלות אחזקה "&TEXT(הגדרות!$C$24,"#,##0")&" ₪ (שכירות, חשמל, ביטוח) ובלאי ציוד "&TEXT(הגדרות!$C$25,"#,##0")&" ₪ (מסורית גקסון, ניירות שיוף, ברגים)." -> • עלות אחזקה 150 ₪ (שכירות, חשמל, ביטוח) ובלאי ציוד 150 ₪ (מסורית גקסון, ניירות שיוף, ברגים). | H30: פרויקטים מיוחדים | L30: =L25 -> 0
A31: ="• תקציב עץ: "&TEXT(הגדרות!$C$27,"#,##0")&" ₪ למשתתף." -> • תקציב עץ: 100 ₪ למשתתף. | H31: סה״כ לפני מע״מ | L31: =L28+L29+L30 -> 7600
A32: =IF(הגדרות!$C$34="","","• "&הגדרות!$C$34) -> • המחירים אינם כוללים מע״מ. מע״מ יתווסף כחוק. | H32: ="מע״מ "&ROUND(הגדרות!$C$31*100,1)&"%" -> מע״מ 18% | L32: =ROUND(L31*הגדרות!$C$31,2) -> 1368
A33: =IF(הגדרות!$C$35="","","• "&הגדרות!$C$35) -> • פרויקטים גדולים ומיוחדים מתומחרים בנפרד לפי עלות החומרים, באישור החווה. | H33: סה״כ לתשלום (כולל מע״מ) | L33: =L31+L32 -> 8968
A34: =IF(הגדרות!$C$36="","","• "&הגדרות!$C$36)
A35: תנאי ביטול ותנאים כלליים
A36: ="• "&הגדרות!$C$39 -> • ביטול מלא של הסדנא: ביטול של עד 48 שעות לפני מועד הסדנא – ללא חיוב.
A37: ="• "&הגדרות!$C$40 -> • מספר המשתתפים: הסדנא מתוכננת ומוכנה מראש בהתאם למספר המשתתפים שסוכם, עד 6 משתתפים.
A38: ="• "&הגדרות!$C$41 -> • הפחתת מספר המשתתפים: יש לעדכן על שינוי במספר המשתתפים עד 24 שעות לפני הסדנא.
A39: ="• "&הגדרות!$C$42 -> • אי הגעה ללא עדכון מראש: במקרה שבו סוכם על 6 משתתפים ובפועל הגיעו פחות, ללא עדכון של 24 שעות לפני, החיוב יישאר בהתאם למספר המשתתפים שסוכם מראש, וזאת בשל הכנת ורכישת חומרי גלם מראש.
A42: ="בברכה, "&הגדרות!$C$6 -> בברכה, (למילוי) | H42: חתימה: ____________________

Sheet נובמבר 2026
A1: הצעת מחיר | N1: =DATE(YEAR($I$11),MONTH($I$11),1) -> 46327
A2: =הגדרות!$C$17&" · "&"מפגש שבועי בימי "&הגדרות!$C$19&IF(הגדרות!$C$20="",""," ו"&הגדרות!$C$20)&IF(הגדרות!$C$18="",""," ("&הגדרות!$C$18&")")&" · "&CHOOSE(MONTH($N$1),"ינואר","פברואר","מרץ","אפריל","מאי","יוני","יולי","אוגוסט","ספטמבר","אוקטובר","נובמבר","דצמבר")&" "&YEAR($N$1) -> תכנית חוסן · מפגש שבועי בימי רביעי (הוותיקה) · נובמבר 2026 | N2: =EOMONTH($N$1,0) -> 46356
A4: מאת | G4: לכבוד
A5: שם העסק | C5: =הגדרות!$C$5 -> הנגרייה | G5: שם הלקוח | I5: =הגדרות!$C$12 -> חוות רום
A6: שם מלא | C6: =הגדרות!$C$6 -> (למילוי) | G6: כתובת | I6: =הגדרות!$C$13 -> הר כמון
A7: עוסק מורשה | C7: =הגדרות!$C$7 -> (למילוי) | G7: איש קשר | I7: =הגדרות!$C$14 -> (למילוי)
A8: טלפון | C8: =הגדרות!$C$8 -> (למילוי)
A9: אימייל | C9: =הגדרות!$C$9 -> nettaamit21@gmail.com
A11: מס׳ הצעה | C11: ="חוסן-"&YEAR($N$1)&"-"&TEXT(MONTH($N$1),"00") -> חוסן-2026-11 | G11: חודש השירות | I11: 46327
A12: תאריך | C12: =$N$2 -> 46356 | G12: תמחור | I12: =TEXT(הגדרות!$C$26,"#,##0")&" ₪ למפגש + "&TEXT(הגדרות!$C$27,"#,##0")&" ₪ למשתתף" -> 1,300 ₪ למפגש + 100 ₪ למשתתף
A13: ="מפגשי "&הגדרות!$C$17 -> מפגשי תכנית חוסן | K13: פרויקטים מיוחדים – באישור החווה
A14: # | B14: תאריך | C14: יום | D14: סטטוס | E14: משתתפים שסוכמו | F14: הגיעו בפועל | G14: משתתפים לחיוב | H14: תשלום בסיסי (₪) | I14: תקציב עץ (₪) | J14: סה״כ למפגש (₪) | K14: פרויקט מיוחד – תיאור | L14: פרויקט מיוחד – סכום (₪)
A15: =IF(B15="","",COUNT($B$15:B15)) -> 1 | B15: =IF(N15="","",N15) -> 46330 | C15: =IF(B15="","",INDEX(הגדרות!$F$5:$F$11,WEEKDAY(B15))) -> רביעי | D15: התקיים | E15: =IF(B15="","",הגדרות!$C$28) -> 6 | G15: =IF(B15="","",IF(O15=0,0,MIN(הגדרות!$C$29,MAX(E15,F15)))) -> 6 | H15: =IF(B15="","",O15*הגדרות!$C$26) -> 1300 | I15: =IF(B15="","",O15*G15*הגדרות!$C$27) -> 600 | J15: =IF(B15="","",H15+I15) -> 1900 | N15: =$N$1+MIN(MOD(הגדרות!$D$19-WEEKDAY($N$1),7),MOD(הגדרות!$D$20-WEEKDAY($N$1),7)) -> 46330 | O15: =IF(B15="","",IF(D15="בוטל בהתראה",0,IF(D15="בוטל ללא התראה",הגדרות!$C$30,1))) -> 1
A16: =IF(B16="","",COUNT($B$15:B16)) -> 2 | B16: =IF(N16="","",N16) -> 46337 | C16: =IF(B16="","",INDEX(הגדרות!$F$5:$F$11,WEEKDAY(B16))) -> רביעי | D16: התקיים | E16: =IF(B16="","",הגדרות!$C$28) -> 6 | G16: =IF(B16="","",IF(O16=0,0,MIN(הגדרות!$C$29,MAX(E16,F16)))) -> 6 | H16: =IF(B16="","",O16*הגדרות!$C$26) -> 1300 | I16: =IF(B16="","",O16*G16*הגדרות!$C$27) -> 600 | J16: =IF(B16="","",H16+I16) -> 1900 | N16: =IF(N15="","",IF(N15+MIN(MOD(הגדרות!$D$19-WEEKDAY(N15)-1,7)+1,MOD(הגדרות!$D$20-WEEKDAY(N15)-1,7)+1)>$N$2,"",N15+MIN(MOD(הגדרות!$D$19-WEEKDAY(N15)-1,7)+1,MOD(הגדרות!$D$20-WEEKDAY(N15)-1,7)+1))) -> 46337 | O16: =IF(B16="","",IF(D16="בוטל בהתראה",0,IF(D16="בוטל ללא התראה",הגדרות!$C$30,1))) -> 1
A17: =IF(B17="","",COUNT($B$15:B17)) -> 3 | B17: =IF(N17="","",N17) -> 46344 | C17: =IF(B17="","",INDEX(הגדרות!$F$5:$F$11,WEEKDAY(B17))) -> רביעי | D17: התקיים | E17: =IF(B17="","",הגדרות!$C$28) -> 6 | G17: =IF(B17="","",IF(O17=0,0,MIN(הגדרות!$C$29,MAX(E17,F17)))) -> 6 | H17: =IF(B17="","",O17*הגדרות!$C$26) -> 1300 | I17: =IF(B17="","",O17*G17*הגדרות!$C$27) -> 600 | J17: =IF(B17="","",H17+I17) -> 1900 | N17: =IF(N16="","",IF(N16+MIN(MOD(הגדרות!$D$19-WEEKDAY(N16)-1,7)+1,MOD(הגדרות!$D$20-WEEKDAY(N16)-1,7)+1)>$N$2,"",N16+MIN(MOD(הגדרות!$D$19-WEEKDAY(N16)-1,7)+1,MOD(הגדרות!$D$20-WEEKDAY(N16)-1,7)+1))) -> 46344 | O17: =IF(B17="","",IF(D17="בוטל בהתראה",0,IF(D17="בוטל ללא התראה",הגדרות!$C$30,1))) -> 1
A18: =IF(B18="","",COUNT($B$15:B18)) -> 4 | B18: =IF(N18="","",N18) -> 46351 | C18: =IF(B18="","",INDEX(הגדרות!$F$5:$F$11,WEEKDAY(B18))) -> רביעי | D18: התקיים | E18: =IF(B18="","",הגדרות!$C$28) -> 6 | G18: =IF(B18="","",IF(O18=0,0,MIN(הגדרות!$C$29,MAX(E18,F18)))) -> 6 | H18: =IF(B18="","",O18*הגדרות!$C$26) -> 1300 | I18: =IF(B18="","",O18*G18*הגדרות!$C$27) -> 600 | J18: =IF(B18="","",H18+I18) -> 1900 | N18: =IF(N17="","",IF(N17+MIN(MOD(הגדרות!$D$19-WEEKDAY(N17)-1,7)+1,MOD(הגדרות!$D$20-WEEKDAY(N17)-1,7)+1)>$N$2,"",N17+MIN(MOD(הגדרות!$D$19-WEEKDAY(N17)-1,7)+1,MOD(הגדרות!$D$20-WEEKDAY(N17)-1,7)+1))) -> 46351 | O18: =IF(B18="","",IF(D18="בוטל בהתראה",0,IF(D18="בוטל ללא התראה",הגדרות!$C$30,1))) -> 1
A19: =IF(B19="","",COUNT($B$15:B19)) | B19: =IF(N19="","",N19) | C19: =IF(B19="","",INDEX(הגדרות!$F$5:$F$11,WEEKDAY(B19))) | D19: התקיים | E19: =IF(B19="","",הגדרות!$C$28) | G19: =IF(B19="","",IF(O19=0,0,MIN(הגדרות!$C$29,MAX(E19,F19)))) | H19: =IF(B19="","",O19*הגדרות!$C$26) | I19: =IF(B19="","",O19*G19*הגדרות!$C$27) | J19: =IF(B19="","",H19+I19) | N19: =IF(N18="","",IF(N18+MIN(MOD(הגדרות!$D$19-WEEKDAY(N18)-1,7)+1,MOD(הגדרות!$D$20-WEEKDAY(N18)-1,7)+1)>$N$2,"",N18+MIN(MOD(הגדרות!$D$19-WEEKDAY(N18)-1,7)+1,MOD(הגדרות!$D$20-WEEKDAY(N18)-1,7)+1))) | O19: =IF(B19="","",IF(D19="בוטל בהתראה",0,IF(D19="בוטל ללא התראה",הגדרות!$C$30,1)))
A20: =IF(B20="","",COUNT($B$15:B20)) | B20: =IF(N20="","",N20) | C20: =IF(B20="","",INDEX(הגדרות!$F$5:$F$11,WEEKDAY(B20))) | D20: התקיים | E20: =IF(B20="","",הגדרות!$C$28) | G20: =IF(B20="","",IF(O20=0,0,MIN(הגדרות!$C$29,MAX(E20,F20)))) | H20: =IF(B20="","",O20*הגדרות!$C$26) | I20: =IF(B20="","",O20*G20*הגדרות!$C$27) | J20: =IF(B20="","",H20+I20) | N20: =IF(N19="","",IF(N19+MIN(MOD(הגדרות!$D$19-WEEKDAY(N19)-1,7)+1,MOD(הגדרות!$D$20-WEEKDAY(N19)-1,7)+1)>$N$2,"",N19+MIN(MOD(הגדרות!$D$19-WEEKDAY(N19)-1,7)+1,MOD(הגדרות!$D$20-WEEKDAY(N19)-1,7)+1))) | O20: =IF(B20="","",IF(D20="בוטל בהתראה",0,IF(D20="בוטל ללא התראה",הגדרות!$C$30,1)))
A21: =IF(B21="","",COUNT($B$15:B21)) | B21: =IF(N21="","",N21) | C21: =IF(B21="","",INDEX(הגדרות!$F$5:$F$11,WEEKDAY(B21))) | D21: התקיים | E21: =IF(B21="","",הגדרות!$C$28) | G21: =IF(B21="","",IF(O21=0,0,MIN(הגדרות!$C$29,MAX(E21,F21)))) | H21: =IF(B21="","",O21*הגדרות!$C$26) | I21: =IF(B21="","",O21*G21*הגדרות!$C$27) | J21: =IF(B21="","",H21+I21) | N21: =IF(N20="","",IF(N20+MIN(MOD(הגדרות!$D$19-WEEKDAY(N20)-1,7)+1,MOD(הגדרות!$D$20-WEEKDAY(N20)-1,7)+1)>$N$2,"",N20+MIN(MOD(הגדרות!$D$19-WEEKDAY(N20)-1,7)+1,MOD(הגדרות!$D$20-WEEKDAY(N20)-1,7)+1))) | O21: =IF(B21="","",IF(D21="בוטל בהתראה",0,IF(D21="בוטל ללא התראה",הגדרות!$C$30,1)))
A22: =IF(B22="","",COUNT($B$15:B22)) | B22: =IF(N22="","",N22) | C22: =IF(B22="","",INDEX(הגדרות!$F$5:$F$11,WEEKDAY(B22))) | D22: התקיים | E22: =IF(B22="","",הגדרות!$C$28) | G22: =IF(B22="","",IF(O22=0,0,MIN(הגדרות!$C$29,MAX(E22,F22)))) | H22: =IF(B22="","",O22*הגדרות!$C$26) | I22: =IF(B22="","",O22*G22*הגדרות!$C$27) | J22: =IF(B22="","",H22+I22) | N22: =IF(N21="","",IF(N21+MIN(MOD(הגדרות!$D$19-WEEKDAY(N21)-1,7)+1,MOD(הגדרות!$D$20-WEEKDAY(N21)-1,7)+1)>$N$2,"",N21+MIN(MOD(הגדרות!$D$19-WEEKDAY(N21)-1,7)+1,MOD(הגדרות!$D$20-WEEKDAY(N21)-1,7)+1))) | O22: =IF(B22="","",IF(D22="בוטל בהתראה",0,IF(D22="בוטל ללא התראה",הגדרות!$C$30,1)))
A23: =IF(B23="","",COUNT($B$15:B23)) | B23: =IF(N23="","",N23) | C23: =IF(B23="","",INDEX(הגדרות!$F$5:$F$11,WEEKDAY(B23))) | D23: התקיים | E23: =IF(B23="","",הגדרות!$C$28) | G23: =IF(B23="","",IF(O23=0,0,MIN(הגדרות!$C$29,MAX(E23,F23)))) | H23: =IF(B23="","",O23*הגדרות!$C$26) | I23: =IF(B23="","",O23*G23*הגדרות!$C$27) | J23: =IF(B23="","",H23+I23) | N23: =IF(N22="","",IF(N22+MIN(MOD(הגדרות!$D$19-WEEKDAY(N22)-1,7)+1,MOD(הגדרות!$D$20-WEEKDAY(N22)-1,7)+1)>$N$2,"",N22+MIN(MOD(הגדרות!$D$19-WEEKDAY(N22)-1,7)+1,MOD(הגדרות!$D$20-WEEKDAY(N22)-1,7)+1))) | O23: =IF(B23="","",IF(D23="בוטל בהתראה",0,IF(D23="בוטל ללא התראה",הגדרות!$C$30,1)))
A24: =IF(B24="","",COUNT($B$15:B24)) | B24: =IF(N24="","",N24) | C24: =IF(B24="","",INDEX(הגדרות!$F$5:$F$11,WEEKDAY(B24))) | D24: התקיים | E24: =IF(B24="","",הגדרות!$C$28) | G24: =IF(B24="","",IF(O24=0,0,MIN(הגדרות!$C$29,MAX(E24,F24)))) | H24: =IF(B24="","",O24*הגדרות!$C$26) | I24: =IF(B24="","",O24*G24*הגדרות!$C$27) | J24: =IF(B24="","",H24+I24) | N24: =IF(N23="","",IF(N23+MIN(MOD(הגדרות!$D$19-WEEKDAY(N23)-1,7)+1,MOD(הגדרות!$D$20-WEEKDAY(N23)-1,7)+1)>$N$2,"",N23+MIN(MOD(הגדרות!$D$19-WEEKDAY(N23)-1,7)+1,MOD(הגדרות!$D$20-WEEKDAY(N23)-1,7)+1))) | O24: =IF(B24="","",IF(D24="בוטל בהתראה",0,IF(D24="בוטל ללא התראה",הגדרות!$C$30,1)))
A25: סה״כ | G25: =SUM(G15:G24) -> 24 | H25: =SUM(H15:H24) -> 5200 | I25: =SUM(I15:I24) -> 2400 | J25: =SUM(J15:J24) -> 7600 | L25: =SUM(L15:L24) -> 0
A26: סטטוס: "בוטל בהתראה" – עד 48 שעות לפני המפגש, ללא חיוב · "בוטל ללא התראה" – פחות מ־48 שעות לפני, בחיוב לפי מספר המשתתפים שסוכם · משתתפים לחיוב = הגבוה מבין שסוכמו (כפי שעודכן עד 24 שעות לפני) ומי שהגיעו בפועל.
A28: פירוט התמחור | H28: ="תשלום בסיסי ("&COUNTIF(O15:O24,">0")&" מפגשים)" -> תשלום בסיסי (4 מפגשים) | L28: =H25 -> 5200
A29: ="• תשלום בסיסי למפגש – "&TEXT(הגדרות!$C$26,"#,##0")&" ₪: "&הגדרות!$C$21&" שעות עבודה ("&TEXT(הגדרות!$C$23,"#,##0")&" ₪) – "&הגדרות!$C$22&"." -> • תשלום בסיסי למפגש – 1,300 ₪: 6 שעות עבודה (1,000 ₪) – שעת נסיעה לרכישת עצים ומלאי, שעתיים התארגנות וניקיון, שעתיים סדנא ומפגש צוות שבועי. | H29: ="תקציב עץ ("&G25&" משתתפים)" -> תקציב עץ (24 משתתפים) | L29: =I25 -> 2400
A30: ="• עלות אחזקה "&TEXT(הגדרות!$C$24,"#,##0")&" ₪ (שכירות, חשמל, ביטוח) ובלאי ציוד "&TEXT(הגדרות!$C$25,"#,##0")&" ₪ (מסורית גקסון, ניירות שיוף, ברגים)." -> • עלות אחזקה 150 ₪ (שכירות, חשמל, ביטוח) ובלאי ציוד 150 ₪ (מסורית גקסון, ניירות שיוף, ברגים). | H30: פרויקטים מיוחדים | L30: =L25 -> 0
A31: ="• תקציב עץ: "&TEXT(הגדרות!$C$27,"#,##0")&" ₪ למשתתף." -> • תקציב עץ: 100 ₪ למשתתף. | H31: סה״כ לפני מע״מ | L31: =L28+L29+L30 -> 7600
A32: =IF(הגדרות!$C$34="","","• "&הגדרות!$C$34) -> • המחירים אינם כוללים מע״מ. מע״מ יתווסף כחוק. | H32: ="מע״מ "&ROUND(הגדרות!$C$31*100,1)&"%" -> מע״מ 18% | L32: =ROUND(L31*הגדרות!$C$31,2) -> 1368
A33: =IF(הגדרות!$C$35="","","• "&הגדרות!$C$35) -> • פרויקטים גדולים ומיוחדים מתומחרים בנפרד לפי עלות החומרים, באישור החווה. | H33: סה״כ לתשלום (כולל מע״מ) | L33: =L31+L32 -> 8968
A34: =IF(הגדרות!$C$36="","","• "&הגדרות!$C$36)
A35: תנאי ביטול ותנאים כלליים
A36: ="• "&הגדרות!$C$39 -> • ביטול מלא של הסדנא: ביטול של עד 48 שעות לפני מועד הסדנא – ללא חיוב.
A37: ="• "&הגדרות!$C$40 -> • מספר המשתתפים: הסדנא מתוכננת ומוכנה מראש בהתאם למספר המשתתפים שסוכם, עד 6 משתתפים.
A38: ="• "&הגדרות!$C$41 -> • הפחתת מספר המשתתפים: יש לעדכן על שינוי במספר המשתתפים עד 24 שעות לפני הסדנא.
A39: ="• "&הגדרות!$C$42 -> • אי הגעה ללא עדכון מראש: במקרה שבו סוכם על 6 משתתפים ובפועל הגיעו פחות, ללא עדכון של 24 שעות לפני, החיוב יישאר בהתאם למספר המשתתפים שסוכם מראש, וזאת בשל הכנת ורכישת חומרי גלם מראש.
A42: ="בברכה, "&הגדרות!$C$6 -> בברכה, (למילוי) | H42: חתימה: ____________________

Sheet דצמבר 2026
A1: הצעת מחיר | N1: =DATE(YEAR($I$11),MONTH($I$11),1) -> 46357
A2: =הגדרות!$C$17&" · "&"מפגש שבועי בימי "&הגדרות!$C$19&IF(הגדרות!$C$20="",""," ו"&הגדרות!$C$20)&IF(הגדרות!$C$18="",""," ("&הגדרות!$C$18&")")&" · "&CHOOSE(MONTH($N$1),"ינואר","פברואר","מרץ","אפריל","מאי","יוני","יולי","אוגוסט","ספטמבר","אוקטובר","נובמבר","דצמבר")&" "&YEAR($N$1) -> תכנית חוסן · מפגש שבועי בימי רביעי (הוותיקה) · דצמבר 2026 | N2: =EOMONTH($N$1,0) -> 46387
A4: מאת | G4: לכבוד
A5: שם העסק | C5: =הגדרות!$C$5 -> הנגרייה | G5: שם הלקוח | I5: =הגדרות!$C$12 -> חוות רום
A6: שם מלא | C6: =הגדרות!$C$6 -> (למילוי) | G6: כתובת | I6: =הגדרות!$C$13 -> הר כמון
A7: עוסק מורשה | C7: =הגדרות!$C$7 -> (למילוי) | G7: איש קשר | I7: =הגדרות!$C$14 -> (למילוי)
A8: טלפון | C8: =הגדרות!$C$8 -> (למילוי)
A9: אימייל | C9: =הגדרות!$C$9 -> nettaamit21@gmail.com
A11: מס׳ הצעה | C11: ="חוסן-"&YEAR($N$1)&"-"&TEXT(MONTH($N$1),"00") -> חוסן-2026-12 | G11: חודש השירות | I11: 46357
A12: תאריך | C12: =$N$2 -> 46387 | G12: תמחור | I12: =TEXT(הגדרות!$C$26,"#,##0")&" ₪ למפגש + "&TEXT(הגדרות!$C$27,"#,##0")&" ₪ למשתתף" -> 1,300 ₪ למפגש + 100 ₪ למשתתף
A13: ="מפגשי "&הגדרות!$C$17 -> מפגשי תכנית חוסן | K13: פרויקטים מיוחדים – באישור החווה
A14: # | B14: תאריך | C14: יום | D14: סטטוס | E14: משתתפים שסוכמו | F14: הגיעו בפועל | G14: משתתפים לחיוב | H14: תשלום בסיסי (₪) | I14: תקציב עץ (₪) | J14: סה״כ למפגש (₪) | K14: פרויקט מיוחד – תיאור | L14: פרויקט מיוחד – סכום (₪)
A15: =IF(B15="","",COUNT($B$15:B15)) -> 1 | B15: =IF(N15="","",N15) -> 46358 | C15: =IF(B15="","",INDEX(הגדרות!$F$5:$F$11,WEEKDAY(B15))) -> רביעי | D15: התקיים | E15: =IF(B15="","",הגדרות!$C$28) -> 6 | G15: =IF(B15="","",IF(O15=0,0,MIN(הגדרות!$C$29,MAX(E15,F15)))) -> 6 | H15: =IF(B15="","",O15*הגדרות!$C$26) -> 1300 | I15: =IF(B15="","",O15*G15*הגדרות!$C$27) -> 600 | J15: =IF(B15="","",H15+I15) -> 1900 | N15: =$N$1+MIN(MOD(הגדרות!$D$19-WEEKDAY($N$1),7),MOD(הגדרות!$D$20-WEEKDAY($N$1),7)) -> 46358 | O15: =IF(B15="","",IF(D15="בוטל בהתראה",0,IF(D15="בוטל ללא התראה",הגדרות!$C$30,1))) -> 1
A16: =IF(B16="","",COUNT($B$15:B16)) -> 2 | B16: =IF(N16="","",N16) -> 46365 | C16: =IF(B16="","",INDEX(הגדרות!$F$5:$F$11,WEEKDAY(B16))) -> רביעי | D16: התקיים | E16: =IF(B16="","",הגדרות!$C$28) -> 6 | G16: =IF(B16="","",IF(O16=0,0,MIN(הגדרות!$C$29,MAX(E16,F16)))) -> 6 | H16: =IF(B16="","",O16*הגדרות!$C$26) -> 1300 | I16: =IF(B16="","",O16*G16*הגדרות!$C$27) -> 600 | J16: =IF(B16="","",H16+I16) -> 1900 | N16: =IF(N15="","",IF(N15+MIN(MOD(הגדרות!$D$19-WEEKDAY(N15)-1,7)+1,MOD(הגדרות!$D$20-WEEKDAY(N15)-1,7)+1)>$N$2,"",N15+MIN(MOD(הגדרות!$D$19-WEEKDAY(N15)-1,7)+1,MOD(הגדרות!$D$20-WEEKDAY(N15)-1,7)+1))) -> 46365 | O16: =IF(B16="","",IF(D16="בוטל בהתראה",0,IF(D16="בוטל ללא התראה",הגדרות!$C$30,1))) -> 1
A17: =IF(B17="","",COUNT($B$15:B17)) -> 3 | B17: =IF(N17="","",N17) -> 46372 | C17: =IF(B17="","",INDEX(הגדרות!$F$5:$F$11,WEEKDAY(B17))) -> רביעי | D17: התקיים | E17: =IF(B17="","",הגדרות!$C$28) -> 6 | G17: =IF(B17="","",IF(O17=0,0,MIN(הגדרות!$C$29,MAX(E17,F17)))) -> 6 | H17: =IF(B17="","",O17*הגדרות!$C$26) -> 1300 | I17: =IF(B17="","",O17*G17*הגדרות!$C$27) -> 600 | J17: =IF(B17="","",H17+I17) -> 1900 | N17: =IF(N16="","",IF(N16+MIN(MOD(הגדרות!$D$19-WEEKDAY(N16)-1,7)+1,MOD(הגדרות!$D$20-WEEKDAY(N16)-1,7)+1)>$N$2,"",N16+MIN(MOD(הגדרות!$D$19-WEEKDAY(N16)-1,7)+1,MOD(הגדרות!$D$20-WEEKDAY(N16)-1,7)+1))) -> 46372 | O17: =IF(B17="","",IF(D17="בוטל בהתראה",0,IF(D17="בוטל ללא התראה",הגדרות!$C$30,1))) -> 1
A18: =IF(B18="","",COUNT($B$15:B18)) -> 4 | B18: =IF(N18="","",N18) -> 46379 | C18: =IF(B18="","",INDEX(הגדרות!$F$5:$F$11,WEEKDAY(B18))) -> רביעי | D18: התקיים | E18: =IF(B18="","",הגדרות!$C$28) -> 6 | G18: =IF(B18="","",IF(O18=0,0,MIN(הגדרות!$C$29,MAX(E18,F18)))) -> 6 | H18: =IF(B18="","",O18*הגדרות!$C$26) -> 1300 | I18: =IF(B18="","",O18*G18*הגדרות!$C$27) -> 600 | J18: =IF(B18="","",H18+I18) -> 1900 | N18: =IF(N17="","",IF(N17+MIN(MOD(הגדרות!$D$19-WEEKDAY(N17)-1,7)+1,MOD(הגדרות!$D$20-WEEKDAY(N17)-1,7)+1)>$N$2,"",N17+MIN(MOD(הגדרות!$D$19-WEEKDAY(N17)-1,7)+1,MOD(הגדרות!$D$20-WEEKDAY(N17)-1,7)+1))) -> 46379 | O18: =IF(B18="","",IF(D18="בוטל בהתראה",0,IF(D18="בוטל ללא התראה",הגדרות!$C$30,1))) -> 1
A19: =IF(B19="","",COUNT($B$15:B19)) -> 5 | B19: =IF(N19="","",N19) -> 46386 | C19: =IF(B19="","",INDEX(הגדרות!$F$5:$F$11,WEEKDAY(B19))) -> רביעי | D19: התקיים | E19: =IF(B19="","",הגדרות!$C$28) -> 6 | G19: =IF(B19="","",IF(O19=0,0,MIN(הגדרות!$C$29,MAX(E19,F19)))) -> 6 | H19: =IF(B19="","",O19*הגדרות!$C$26) -> 1300 | I19: =IF(B19="","",O19*G19*הגדרות!$C$27) -> 600 | J19: =IF(B19="","",H19+I19) -> 1900 | N19: =IF(N18="","",IF(N18+MIN(MOD(הגדרות!$D$19-WEEKDAY(N18)-1,7)+1,MOD(הגדרות!$D$20-WEEKDAY(N18)-1,7)+1)>$N$2,"",N18+MIN(MOD(הגדרות!$D$19-WEEKDAY(N18)-1,7)+1,MOD(הגדרות!$D$20-WEEKDAY(N18)-1,7)+1))) -> 46386 | O19: =IF(B19="","",IF(D19="בוטל בהתראה",0,IF(D19="בוטל ללא התראה",הגדרות!$C$30,1))) -> 1
A20: =IF(B20="","",COUNT($B$15:B20)) | B20: =IF(N20="","",N20) | C20: =IF(B20="","",INDEX(הגדרות!$F$5:$F$11,WEEKDAY(B20))) | D20: התקיים | E20: =IF(B20="","",הגדרות!$C$28) | G20: =IF(B20="","",IF(O20=0,0,MIN(הגדרות!$C$29,MAX(E20,F20)))) | H20: =IF(B20="","",O20*הגדרות!$C$26) | I20: =IF(B20="","",O20*G20*הגדרות!$C$27) | J20: =IF(B20="","",H20+I20) | N20: =IF(N19="","",IF(N19+MIN(MOD(הגדרות!$D$19-WEEKDAY(N19)-1,7)+1,MOD(הגדרות!$D$20-WEEKDAY(N19)-1,7)+1)>$N$2,"",N19+MIN(MOD(הגדרות!$D$19-WEEKDAY(N19)-1,7)+1,MOD(הגדרות!$D$20-WEEKDAY(N19)-1,7)+1))) | O20: =IF(B20="","",IF(D20="בוטל בהתראה",0,IF(D20="בוטל ללא התראה",הגדרות!$C$30,1)))
A21: =IF(B21="","",COUNT($B$15:B21)) | B21: =IF(N21="","",N21) | C21: =IF(B21="","",INDEX(הגדרות!$F$5:$F$11,WEEKDAY(B21))) | D21: התקיים | E21: =IF(B21="","",הגדרות!$C$28) | G21: =IF(B21="","",IF(O21=0,0,MIN(הגדרות!$C$29,MAX(E21,F21)))) | H21: =IF(B21="","",O21*הגדרות!$C$26) | I21: =IF(B21="","",O21*G21*הגדרות!$C$27) | J21: =IF(B21="","",H21+I21) | N21: =IF(N20="","",IF(N20+MIN(MOD(הגדרות!$D$19-WEEKDAY(N20)-1,7)+1,MOD(הגדרות!$D$20-WEEKDAY(N20)-1,7)+1)>$N$2,"",N20+MIN(MOD(הגדרות!$D$19-WEEKDAY(N20)-1,7)+1,MOD(הגדרות!$D$20-WEEKDAY(N20)-1,7)+1))) | O21: =IF(B21="","",IF(D21="בוטל בהתראה",0,IF(D21="בוטל ללא התראה",הגדרות!$C$30,1)))
A22: =IF(B22="","",COUNT($B$15:B22)) | B22: =IF(N22="","",N22) | C22: =IF(B22="","",INDEX(הגדרות!$F$5:$F$11,WEEKDAY(B22))) | D22: התקיים | E22: =IF(B22="","",הגדרות!$C$28) | G22: =IF(B22="","",IF(O22=0,0,MIN(הגדרות!$C$29,MAX(E22,F22)))) | H22: =IF(B22="","",O22*הגדרות!$C$26) | I22: =IF(B22="","",O22*G22*הגדרות!$C$27) | J22: =IF(B22="","",H22+I22) | N22: =IF(N21="","",IF(N21+MIN(MOD(הגדרות!$D$19-WEEKDAY(N21)-1,7)+1,MOD(הגדרות!$D$20-WEEKDAY(N21)-1,7)+1)>$N$2,"",N21+MIN(MOD(הגדרות!$D$19-WEEKDAY(N21)-1,7)+1,MOD(הגדרות!$D$20-WEEKDAY(N21)-1,7)+1))) | O22: =IF(B22="","",IF(D22="בוטל בהתראה",0,IF(D22="בוטל ללא התראה",הגדרות!$C$30,1)))
A23: =IF(B23="","",COUNT($B$15:B23)) | B23: =IF(N23="","",N23) | C23: =IF(B23="","",INDEX(הגדרות!$F$5:$F$11,WEEKDAY(B23))) | D23: התקיים | E23: =IF(B23="","",הגדרות!$C$28) | G23: =IF(B23="","",IF(O23=0,0,MIN(הגדרות!$C$29,MAX(E23,F23)))) | H23: =IF(B23="","",O23*הגדרות!$C$26) | I23: =IF(B23="","",O23*G23*הגדרות!$C$27) | J23: =IF(B23="","",H23+I23) | N23: =IF(N22="","",IF(N22+MIN(MOD(הגדרות!$D$19-WEEKDAY(N22)-1,7)+1,MOD(הגדרות!$D$20-WEEKDAY(N22)-1,7)+1)>$N$2,"",N22+MIN(MOD(הגדרות!$D$19-WEEKDAY(N22)-1,7)+1,MOD(הגדרות!$D$20-WEEKDAY(N22)-1,7)+1))) | O23: =IF(B23="","",IF(D23="בוטל בהתראה",0,IF(D23="בוטל ללא התראה",הגדרות!$C$30,1)))
A24: =IF(B24="","",COUNT($B$15:B24)) | B24: =IF(N24="","",N24) | C24: =IF(B24="","",INDEX(הגדרות!$F$5:$F$11,WEEKDAY(B24))) | D24: התקיים | E24: =IF(B24="","",הגדרות!$C$28) | G24: =IF(B24="","",IF(O24=0,0,MIN(הגדרות!$C$29,MAX(E24,F24)))) | H24: =IF(B24="","",O24*הגדרות!$C$26) | I24: =IF(B24="","",O24*G24*הגדרות!$C$27) | J24: =IF(B24="","",H24+I24) | N24: =IF(N23="","",IF(N23+MIN(MOD(הגדרות!$D$19-WEEKDAY(N23)-1,7)+1,MOD(הגדרות!$D$20-WEEKDAY(N23)-1,7)+1)>$N$2,"",N23+MIN(MOD(הגדרות!$D$19-WEEKDAY(N23)-1,7)+1,MOD(הגדרות!$D$20-WEEKDAY(N23)-1,7)+1))) | O24: =IF(B24="","",IF(D24="בוטל בהתראה",0,IF(D24="בוטל ללא התראה",הגדרות!$C$30,1)))
A25: סה״כ | G25: =SUM(G15:G24) -> 30 | H25: =SUM(H15:H24) -> 6500 | I25: =SUM(I15:I24) -> 3000 | J25: =SUM(J15:J24) -> 9500 | L25: =SUM(L15:L24) -> 0
A26: סטטוס: "בוטל בהתראה" – עד 48 שעות לפני המפגש, ללא חיוב · "בוטל ללא התראה" – פחות מ־48 שעות לפני, בחיוב לפי מספר המשתתפים שסוכם · משתתפים לחיוב = הגבוה מבין שסוכמו (כפי שעודכן עד 24 שעות לפני) ומי שהגיעו בפועל.
A28: פירוט התמחור | H28: ="תשלום בסיסי ("&COUNTIF(O15:O24,">0")&" מפגשים)" -> תשלום בסיסי (5 מפגשים) | L28: =H25 -> 6500
A29: ="• תשלום בסיסי למפגש – "&TEXT(הגדרות!$C$26,"#,##0")&" ₪: "&הגדרות!$C$21&" שעות עבודה ("&TEXT(הגדרות!$C$23,"#,##0")&" ₪) – "&הגדרות!$C$22&"." -> • תשלום בסיסי למפגש – 1,300 ₪: 6 שעות עבודה (1,000 ₪) – שעת נסיעה לרכישת עצים ומלאי, שעתיים התארגנות וניקיון, שעתיים סדנא ומפגש צוות שבועי. | H29: ="תקציב עץ ("&G25&" משתתפים)" -> תקציב עץ (30 משתתפים) | L29: =I25 -> 3000
A30: ="• עלות אחזקה "&TEXT(הגדרות!$C$24,"#,##0")&" ₪ (שכירות, חשמל, ביטוח) ובלאי ציוד "&TEXT(הגדרות!$C$25,"#,##0")&" ₪ (מסורית גקסון, ניירות שיוף, ברגים)." -> • עלות אחזקה 150 ₪ (שכירות, חשמל, ביטוח) ובלאי ציוד 150 ₪ (מסורית גקסון, ניירות שיוף, ברגים). | H30: פרויקטים מיוחדים | L30: =L25 -> 0
A31: ="• תקציב עץ: "&TEXT(הגדרות!$C$27,"#,##0")&" ₪ למשתתף." -> • תקציב עץ: 100 ₪ למשתתף. | H31: סה״כ לפני מע״מ | L31: =L28+L29+L30 -> 9500
A32: =IF(הגדרות!$C$34="","","• "&הגדרות!$C$34) -> • המחירים אינם כוללים מע״מ. מע״מ יתווסף כחוק. | H32: ="מע״מ "&ROUND(הגדרות!$C$31*100,1)&"%" -> מע״מ 18% | L32: =ROUND(L31*הגדרות!$C$31,2) -> 1710
A33: =IF(הגדרות!$C$35="","","• "&הגדרות!$C$35) -> • פרויקטים גדולים ומיוחדים מתומחרים בנפרד לפי עלות החומרים, באישור החווה. | H33: סה״כ לתשלום (כולל מע״מ) | L33: =L31+L32 -> 11210
A34: =IF(הגדרות!$C$36="","","• "&הגדרות!$C$36)
A35: תנאי ביטול ותנאים כלליים
A36: ="• "&הגדרות!$C$39 -> • ביטול מלא של הסדנא: ביטול של עד 48 שעות לפני מועד הסדנא – ללא חיוב.
A37: ="• "&הגדרות!$C$40 -> • מספר המשתתפים: הסדנא מתוכננת ומוכנה מראש בהתאם למספר המשתתפים שסוכם, עד 6 משתתפים.
A38: ="• "&הגדרות!$C$41 -> • הפחתת מספר המשתתפים: יש לעדכן על שינוי במספר המשתתפים עד 24 שעות לפני הסדנא.
A39: ="• "&הגדרות!$C$42 -> • אי הגעה ללא עדכון מראש: במקרה שבו סוכם על 6 משתתפים ובפועל הגיעו פחות, ללא עדכון של 24 שעות לפני, החיוב יישאר בהתאם למספר המשתתפים שסוכם מראש, וזאת בשל הכנת ורכישת חומרי גלם מראש.
A42: ="בברכה, "&הגדרות!$C$6 -> בברכה, (למילוי) | H42: חתימה: ____________________

Sheet ינואר 2027
A1: הצעת מחיר | N1: =DATE(YEAR($I$11),MONTH($I$11),1) -> 46388
A2: =הגדרות!$C$17&" · "&"מפגש שבועי בימי "&הגדרות!$C$19&IF(הגדרות!$C$20="",""," ו"&הגדרות!$C$20)&IF(הגדרות!$C$18="",""," ("&הגדרות!$C$18&")")&" · "&CHOOSE(MONTH($N$1),"ינואר","פברואר","מרץ","אפריל","מאי","יוני","יולי","אוגוסט","ספטמבר","אוקטובר","נובמבר","דצמבר")&" "&YEAR($N$1) -> תכנית חוסן · מפגש שבועי בימי רביעי (הוותיקה) · ינואר 2027 | N2: =EOMONTH($N$1,0) -> 46418
A4: מאת | G4: לכבוד
A5: שם העסק | C5: =הגדרות!$C$5 -> הנגרייה | G5: שם הלקוח | I5: =הגדרות!$C$12 -> חוות רום
A6: שם מלא | C6: =הגדרות!$C$6 -> (למילוי) | G6: כתובת | I6: =הגדרות!$C$13 -> הר כמון
A7: עוסק מורשה | C7: =הגדרות!$C$7 -> (למילוי) | G7: איש קשר | I7: =הגדרות!$C$14 -> (למילוי)
A8: טלפון | C8: =הגדרות!$C$8 -> (למילוי)
A9: אימייל | C9: =הגדרות!$C$9 -> nettaamit21@gmail.com
A11: מס׳ הצעה | C11: ="חוסן-"&YEAR($N$1)&"-"&TEXT(MONTH($N$1),"00") -> חוסן-2027-01 | G11: חודש השירות | I11: 46388
A12: תאריך | C12: =$N$2 -> 46418 | G12: תמחור | I12: =TEXT(הגדרות!$C$26,"#,##0")&" ₪ למפגש + "&TEXT(הגדרות!$C$27,"#,##0")&" ₪ למשתתף" -> 1,300 ₪ למפגש + 100 ₪ למשתתף
A13: ="מפגשי "&הגדרות!$C$17 -> מפגשי תכנית חוסן | K13: פרויקטים מיוחדים – באישור החווה
A14: # | B14: תאריך | C14: יום | D14: סטטוס | E14: משתתפים שסוכמו | F14: הגיעו בפועל | G14: משתתפים לחיוב | H14: תשלום בסיסי (₪) | I14: תקציב עץ (₪) | J14: סה״כ למפגש (₪) | K14: פרויקט מיוחד – תיאור | L14: פרויקט מיוחד – סכום (₪)
A15: =IF(B15="","",COUNT($B$15:B15)) -> 1 | B15: =IF(N15="","",N15) -> 46393 | C15: =IF(B15="","",INDEX(הגדרות!$F$5:$F$11,WEEKDAY(B15))) -> רביעי | D15: התקיים | E15: =IF(B15="","",הגדרות!$C$28) -> 6 | G15: =IF(B15="","",IF(O15=0,0,MIN(הגדרות!$C$29,MAX(E15,F15)))) -> 6 | H15: =IF(B15="","",O15*הגדרות!$C$26) -> 1300 | I15: =IF(B15="","",O15*G15*הגדרות!$C$27) -> 600 | J15: =IF(B15="","",H15+I15) -> 1900 | N15: =$N$1+MIN(MOD(הגדרות!$D$19-WEEKDAY($N$1),7),MOD(הגדרות!$D$20-WEEKDAY($N$1),7)) -> 46393 | O15: =IF(B15="","",IF(D15="בוטל בהתראה",0,IF(D15="בוטל ללא התראה",הגדרות!$C$30,1))) -> 1
A16: =IF(B16="","",COUNT($B$15:B16)) -> 2 | B16: =IF(N16="","",N16) -> 46400 | C16: =IF(B16="","",INDEX(הגדרות!$F$5:$F$11,WEEKDAY(B16))) -> רביעי | D16: התקיים | E16: =IF(B16="","",הגדרות!$C$28) -> 6 | G16: =IF(B16="","",IF(O16=0,0,MIN(הגדרות!$C$29,MAX(E16,F16)))) -> 6 | H16: =IF(B16="","",O16*הגדרות!$C$26) -> 1300 | I16: =IF(B16="","",O16*G16*הגדרות!$C$27) -> 600 | J16: =IF(B16="","",H16+I16) -> 1900 | N16: =IF(N15="","",IF(N15+MIN(MOD(הגדרות!$D$19-WEEKDAY(N15)-1,7)+1,MOD(הגדרות!$D$20-WEEKDAY(N15)-1,7)+1)>$N$2,"",N15+MIN(MOD(הגדרות!$D$19-WEEKDAY(N15)-1,7)+1,MOD(הגדרות!$D$20-WEEKDAY(N15)-1,7)+1))) -> 46400 | O16: =IF(B16="","",IF(D16="בוטל בהתראה",0,IF(D16="בוטל ללא התראה",הגדרות!$C$30,1))) -> 1
A17: =IF(B17="","",COUNT($B$15:B17)) -> 3 | B17: =IF(N17="","",N17) -> 46407 | C17: =IF(B17="","",INDEX(הגדרות!$F$5:$F$11,WEEKDAY(B17))) -> רביעי | D17: התקיים | E17: =IF(B17="","",הגדרות!$C$28) -> 6 | G17: =IF(B17="","",IF(O17=0,0,MIN(הגדרות!$C$29,MAX(E17,F17)))) -> 6 | H17: =IF(B17="","",O17*הגדרות!$C$26) -> 1300 | I17: =IF(B17="","",O17*G17*הגדרות!$C$27) -> 600 | J17: =IF(B17="","",H17+I17) -> 1900 | N17: =IF(N16="","",IF(N16+MIN(MOD(הגדרות!$D$19-WEEKDAY(N16)-1,7)+1,MOD(הגדרות!$D$20-WEEKDAY(N16)-1,7)+1)>$N$2,"",N16+MIN(MOD(הגדרות!$D$19-WEEKDAY(N16)-1,7)+1,MOD(הגדרות!$D$20-WEEKDAY(N16)-1,7)+1))) -> 46407 | O17: =IF(B17="","",IF(D17="בוטל בהתראה",0,IF(D17="בוטל ללא התראה",הגדרות!$C$30,1))) -> 1
A18: =IF(B18="","",COUNT($B$15:B18)) -> 4 | B18: =IF(N18="","",N18) -> 46414 | C18: =IF(B18="","",INDEX(הגדרות!$F$5:$F$11,WEEKDAY(B18))) -> רביעי | D18: התקיים | E18: =IF(B18="","",הגדרות!$C$28) -> 6 | G18: =IF(B18="","",IF(O18=0,0,MIN(הגדרות!$C$29,MAX(E18,F18)))) -> 6 | H18: =IF(B18="","",O18*הגדרות!$C$26) -> 1300 | I18: =IF(B18="","",O18*G18*הגדרות!$C$27) -> 600 | J18: =IF(B18="","",H18+I18) -> 1900 | N18: =IF(N17="","",IF(N17+MIN(MOD(הגדרות!$D$19-WEEKDAY(N17)-1,7)+1,MOD(הגדרות!$D$20-WEEKDAY(N17)-1,7)+1)>$N$2,"",N17+MIN(MOD(הגדרות!$D$19-WEEKDAY(N17)-1,7)+1,MOD(הגדרות!$D$20-WEEKDAY(N17)-1,7)+1))) -> 46414 | O18: =IF(B18="","",IF(D18="בוטל בהתראה",0,IF(D18="בוטל ללא התראה",הגדרות!$C$30,1))) -> 1
A19: =IF(B19="","",COUNT($B$15:B19)) | B19: =IF(N19="","",N19) | C19: =IF(B19="","",INDEX(הגדרות!$F$5:$F$11,WEEKDAY(B19))) | D19: התקיים | E19: =IF(B19="","",הגדרות!$C$28) | G19: =IF(B19="","",IF(O19=0,0,MIN(הגדרות!$C$29,MAX(E19,F19)))) | H19: =IF(B19="","",O19*הגדרות!$C$26) | I19: =IF(B19="","",O19*G19*הגדרות!$C$27) | J19: =IF(B19="","",H19+I19) | N19: =IF(N18="","",IF(N18+MIN(MOD(הגדרות!$D$19-WEEKDAY(N18)-1,7)+1,MOD(הגדרות!$D$20-WEEKDAY(N18)-1,7)+1)>$N$2,"",N18+MIN(MOD(הגדרות!$D$19-WEEKDAY(N18)-1,7)+1,MOD(הגדרות!$D$20-WEEKDAY(N18)-1,7)+1))) | O19: =IF(B19="","",IF(D19="בוטל בהתראה",0,IF(D19="בוטל ללא התראה",הגדרות!$C$30,1)))
A20: =IF(B20="","",COUNT($B$15:B20)) | B20: =IF(N20="","",N20) | C20: =IF(B20="","",INDEX(הגדרות!$F$5:$F$11,WEEKDAY(B20))) | D20: התקיים | E20: =IF(B20="","",הגדרות!$C$28) | G20: =IF(B20="","",IF(O20=0,0,MIN(הגדרות!$C$29,MAX(E20,F20)))) | H20: =IF(B20="","",O20*הגדרות!$C$26) | I20: =IF(B20="","",O20*G20*הגדרות!$C$27) | J20: =IF(B20="","",H20+I20) | N20: =IF(N19="","",IF(N19+MIN(MOD(הגדרות!$D$19-WEEKDAY(N19)-1,7)+1,MOD(הגדרות!$D$20-WEEKDAY(N19)-1,7)+1)>$N$2,"",N19+MIN(MOD(הגדרות!$D$19-WEEKDAY(N19)-1,7)+1,MOD(הגדרות!$D$20-WEEKDAY(N19)-1,7)+1))) | O20: =IF(B20="","",IF(D20="בוטל בהתראה",0,IF(D20="בוטל ללא התראה",הגדרות!$C$30,1)))
A21: =IF(B21="","",COUNT($B$15:B21)) | B21: =IF(N21="","",N21) | C21: =IF(B21="","",INDEX(הגדרות!$F$5:$F$11,WEEKDAY(B21))) | D21: התקיים | E21: =IF(B21="","",הגדרות!$C$28) | G21: =IF(B21="","",IF(O21=0,0,MIN(הגדרות!$C$29,MAX(E21,F21)))) | H21: =IF(B21="","",O21*הגדרות!$C$26) | I21: =IF(B21="","",O21*G21*הגדרות!$C$27) | J21: =IF(B21="","",H21+I21) | N21: =IF(N20="","",IF(N20+MIN(MOD(הגדרות!$D$19-WEEKDAY(N20)-1,7)+1,MOD(הגדרות!$D$20-WEEKDAY(N20)-1,7)+1)>$N$2,"",N20+MIN(MOD(הגדרות!$D$19-WEEKDAY(N20)-1,7)+1,MOD(הגדרות!$D$20-WEEKDAY(N20)-1,7)+1))) | O21: =IF(B21="","",IF(D21="בוטל בהתראה",0,IF(D21="בוטל ללא התראה",הגדרות!$C$30,1)))
A22: =IF(B22="","",COUNT($B$15:B22)) | B22: =IF(N22="","",N22) | C22: =IF(B22="","",INDEX(הגדרות!$F$5:$F$11,WEEKDAY(B22))) | D22: התקיים | E22: =IF(B22="","",הגדרות!$C$28) | G22: =IF(B22="","",IF(O22=0,0,MIN(הגדרות!$C$29,MAX(E22,F22)))) | H22: =IF(B22="","",O22*הגדרות!$C$26) | I22: =IF(B22="","",O22*G22*הגדרות!$C$27) | J22: =IF(B22="","",H22+I22) | N22: =IF(N21="","",IF(N21+MIN(MOD(הגדרות!$D$19-WEEKDAY(N21)-1,7)+1,MOD(הגדרות!$D$20-WEEKDAY(N21)-1,7)+1)>$N$2,"",N21+MIN(MOD(הגדרות!$D$19-WEEKDAY(N21)-1,7)+1,MOD(הגדרות!$D$20-WEEKDAY(N21)-1,7)+1))) | O22: =IF(B22="","",IF(D22="בוטל בהתראה",0,IF(D22="בוטל ללא התראה",הגדרות!$C$30,1)))
A23: =IF(B23="","",COUNT($B$15:B23)) | B23: =IF(N23="","",N23) | C23: =IF(B23="","",INDEX(הגדרות!$F$5:$F$11,WEEKDAY(B23))) | D23: התקיים | E23: =IF(B23="","",הגדרות!$C$28) | G23: =IF(B23="","",IF(O23=0,0,MIN(הגדרות!$C$29,MAX(E23,F23)))) | H23: =IF(B23="","",O23*הגדרות!$C$26) | I23: =IF(B23="","",O23*G23*הגדרות!$C$27) | J23: =IF(B23="","",H23+I23) | N23: =IF(N22="","",IF(N22+MIN(MOD(הגדרות!$D$19-WEEKDAY(N22)-1,7)+1,MOD(הגדרות!$D$20-WEEKDAY(N22)-1,7)+1)>$N$2,"",N22+MIN(MOD(הגדרות!$D$19-WEEKDAY(N22)-1,7)+1,MOD(הגדרות!$D$20-WEEKDAY(N22)-1,7)+1))) | O23: =IF(B23="","",IF(D23="בוטל בהתראה",0,IF(D23="בוטל ללא התראה",הגדרות!$C$30,1)))
A24: =IF(B24="","",COUNT($B$15:B24)) | B24: =IF(N24="","",N24) | C24: =IF(B24="","",INDEX(הגדרות!$F$5:$F$11,WEEKDAY(B24))) | D24: התקיים | E24: =IF(B24="","",הגדרות!$C$28) | G24: =IF(B24="","",IF(O24=0,0,MIN(הגדרות!$C$29,MAX(E24,F24)))) | H24: =IF(B24="","",O24*הגדרות!$C$26) | I24: =IF(B24="","",O24*G24*הגדרות!$C$27) | J24: =IF(B24="","",H24+I24) | N24: =IF(N23="","",IF(N23+MIN(MOD(הגדרות!$D$19-WEEKDAY(N23)-1,7)+1,MOD(הגדרות!$D$20-WEEKDAY(N23)-1,7)+1)>$N$2,"",N23+MIN(MOD(הגדרות!$D$19-WEEKDAY(N23)-1,7)+1,MOD(הגדרות!$D$20-WEEKDAY(N23)-1,7)+1))) | O24: =IF(B24="","",IF(D24="בוטל בהתראה",0,IF(D24="בוטל ללא התראה",הגדרות!$C$30,1)))
A25: סה״כ | G25: =SUM(G15:G24) -> 24 | H25: =SUM(H15:H24) -> 5200 | I25: =SUM(I15:I24) -> 2400 | J25: =SUM(J15:J24) -> 7600 | L25: =SUM(L15:L24) -> 0
A26: סטטוס: "בוטל בהתראה" – עד 48 שעות לפני המפגש, ללא חיוב · "בוטל ללא התראה" – פחות מ־48 שעות לפני, בחיוב לפי מספר המשתתפים שסוכם · משתתפים לחיוב = הגבוה מבין שסוכמו (כפי שעודכן עד 24 שעות לפני) ומי שהגיעו בפועל.
A28: פירוט התמחור | H28: ="תשלום בסיסי ("&COUNTIF(O15:O24,">0")&" מפגשים)" -> תשלום בסיסי (4 מפגשים) | L28: =H25 -> 5200
A29: ="• תשלום בסיסי למפגש – "&TEXT(הגדרות!$C$26,"#,##0")&" ₪: "&הגדרות!$C$21&" שעות עבודה ("&TEXT(הגדרות!$C$23,"#,##0")&" ₪) – "&הגדרות!$C$22&"." -> • תשלום בסיסי למפגש – 1,300 ₪: 6 שעות עבודה (1,000 ₪) – שעת נסיעה לרכישת עצים ומלאי, שעתיים התארגנות וניקיון, שעתיים סדנא ומפגש צוות שבועי. | H29: ="תקציב עץ ("&G25&" משתתפים)" -> תקציב עץ (24 משתתפים) | L29: =I25 -> 2400
A30: ="• עלות אחזקה "&TEXT(הגדרות!$C$24,"#,##0")&" ₪ (שכירות, חשמל, ביטוח) ובלאי ציוד "&TEXT(הגדרות!$C$25,"#,##0")&" ₪ (מסורית גקסון, ניירות שיוף, ברגים)." -> • עלות אחזקה 150 ₪ (שכירות, חשמל, ביטוח) ובלאי ציוד 150 ₪ (מסורית גקסון, ניירות שיוף, ברגים). | H30: פרויקטים מיוחדים | L30: =L25 -> 0
A31: ="• תקציב עץ: "&TEXT(הגדרות!$C$27,"#,##0")&" ₪ למשתתף." -> • תקציב עץ: 100 ₪ למשתתף. | H31: סה״כ לפני מע״מ | L31: =L28+L29+L30 -> 7600
A32: =IF(הגדרות!$C$34="","","• "&הגדרות!$C$34) -> • המחירים אינם כוללים מע״מ. מע״מ יתווסף כחוק. | H32: ="מע״מ "&ROUND(הגדרות!$C$31*100,1)&"%" -> מע״מ 18% | L32: =ROUND(L31*הגדרות!$C$31,2) -> 1368
A33: =IF(הגדרות!$C$35="","","• "&הגדרות!$C$35) -> • פרויקטים גדולים ומיוחדים מתומחרים בנפרד לפי עלות החומרים, באישור החווה. | H33: סה״כ לתשלום (כולל מע״מ) | L33: =L31+L32 -> 8968
A34: =IF(הגדרות!$C$36="","","• "&הגדרות!$C$36)
A35: תנאי ביטול ותנאים כלליים
A36: ="• "&הגדרות!$C$39 -> • ביטול מלא של הסדנא: ביטול של עד 48 שעות לפני מועד הסדנא – ללא חיוב.
A37: ="• "&הגדרות!$C$40 -> • מספר המשתתפים: הסדנא מתוכננת ומוכנה מראש בהתאם למספר המשתתפים שסוכם, עד 6 משתתפים.
A38: ="• "&הגדרות!$C$41 -> • הפחתת מספר המשתתפים: יש לעדכן על שינוי במספר המשתתפים עד 24 שעות לפני הסדנא.
A39: ="• "&הגדרות!$C$42 -> • אי הגעה ללא עדכון מראש: במקרה שבו סוכם על 6 משתתפים ובפועל הגיעו פחות, ללא עדכון של 24 שעות לפני, החיוב יישאר בהתאם למספר המשתתפים שסוכם מראש, וזאת בשל הכנת ורכישת חומרי גלם מראש.
A42: ="בברכה, "&הגדרות!$C$6 -> בברכה, (למילוי) | H42: חתימה: ____________________

Sheet פברואר 2027
A1: הצעת מחיר | N1: =DATE(YEAR($I$11),MONTH($I$11),1) -> 46419
A2: =הגדרות!$C$17&" · "&"מפגש שבועי בימי "&הגדרות!$C$19&IF(הגדרות!$C$20="",""," ו"&הגדרות!$C$20)&IF(הגדרות!$C$18="",""," ("&הגדרות!$C$18&")")&" · "&CHOOSE(MONTH($N$1),"ינואר","פברואר","מרץ","אפריל","מאי","יוני","יולי","אוגוסט","ספטמבר","אוקטובר","נובמבר","דצמבר")&" "&YEAR($N$1) -> תכנית חוסן · מפגש שבועי בימי רביעי (הוותיקה) · פברואר 2027 | N2: =EOMONTH($N$1,0) -> 46446
A4: מאת | G4: לכבוד
A5: שם העסק | C5: =הגדרות!$C$5 -> הנגרייה | G5: שם הלקוח | I5: =הגדרות!$C$12 -> חוות רום
A6: שם מלא | C6: =הגדרות!$C$6 -> (למילוי) | G6: כתובת | I6: =הגדרות!$C$13 -> הר כמון
A7: עוסק מורשה | C7: =הגדרות!$C$7 -> (למילוי) | G7: איש קשר | I7: =הגדרות!$C$14 -> (למילוי)
A8: טלפון | C8: =הגדרות!$C$8 -> (למילוי)
A9: אימייל | C9: =הגדרות!$C$9 -> nettaamit21@gmail.com
A11: מס׳ הצעה | C11: ="חוסן-"&YEAR($N$1)&"-"&TEXT(MONTH($N$1),"00") -> חוסן-2027-02 | G11: חודש השירות | I11: 46419
A12: תאריך | C12: =$N$2 -> 46446 | G12: תמחור | I12: =TEXT(הגדרות!$C$26,"#,##0")&" ₪ למפגש + "&TEXT(הגדרות!$C$27,"#,##0")&" ₪ למשתתף" -> 1,300 ₪ למפגש + 100 ₪ למשתתף
A13: ="מפגשי "&הגדרות!$C$17 -> מפגשי תכנית חוסן | K13: פרויקטים מיוחדים – באישור החווה
A14: # | B14: תאריך | C14: יום | D14: סטטוס | E14: משתתפים שסוכמו | F14: הגיעו בפועל | G14: משתתפים לחיוב | H14: תשלום בסיסי (₪) | I14: תקציב עץ (₪) | J14: סה״כ למפגש (₪) | K14: פרויקט מיוחד – תיאור | L14: פרויקט מיוחד – סכום (₪)
A15: =IF(B15="","",COUNT($B$15:B15)) -> 1 | B15: =IF(N15="","",N15) -> 46421 | C15: =IF(B15="","",INDEX(הגדרות!$F$5:$F$11,WEEKDAY(B15))) -> רביעי | D15: התקיים | E15: =IF(B15="","",הגדרות!$C$28) -> 6 | G15: =IF(B15="","",IF(O15=0,0,MIN(הגדרות!$C$29,MAX(E15,F15)))) -> 6 | H15: =IF(B15="","",O15*הגדרות!$C$26) -> 1300 | I15: =IF(B15="","",O15*G15*הגדרות!$C$27) -> 600 | J15: =IF(B15="","",H15+I15) -> 1900 | N15: =$N$1+MIN(MOD(הגדרות!$D$19-WEEKDAY($N$1),7),MOD(הגדרות!$D$20-WEEKDAY($N$1),7)) -> 46421 | O15: =IF(B15="","",IF(D15="בוטל בהתראה",0,IF(D15="בוטל ללא התראה",הגדרות!$C$30,1))) -> 1
A16: =IF(B16="","",COUNT($B$15:B16)) -> 2 | B16: =IF(N16="","",N16) -> 46428 | C16: =IF(B16="","",INDEX(הגדרות!$F$5:$F$11,WEEKDAY(B16))) -> רביעי | D16: התקיים | E16: =IF(B16="","",הגדרות!$C$28) -> 6 | G16: =IF(B16="","",IF(O16=0,0,MIN(הגדרות!$C$29,MAX(E16,F16)))) -> 6 | H16: =IF(B16="","",O16*הגדרות!$C$26) -> 1300 | I16: =IF(B16="","",O16*G16*הגדרות!$C$27) -> 600 | J16: =IF(B16="","",H16+I16) -> 1900 | N16: =IF(N15="","",IF(N15+MIN(MOD(הגדרות!$D$19-WEEKDAY(N15)-1,7)+1,MOD(הגדרות!$D$20-WEEKDAY(N15)-1,7)+1)>$N$2,"",N15+MIN(MOD(הגדרות!$D$19-WEEKDAY(N15)-1,7)+1,MOD(הגדרות!$D$20-WEEKDAY(N15)-1,7)+1))) -> 46428 | O16: =IF(B16="","",IF(D16="בוטל בהתראה",0,IF(D16="בוטל ללא התראה",הגדרות!$C$30,1))) -> 1
A17: =IF(B17="","",COUNT($B$15:B17)) -> 3 | B17: =IF(N17="","",N17) -> 46435 | C17: =IF(B17="","",INDEX(הגדרות!$F$5:$F$11,WEEKDAY(B17))) -> רביעי | D17: התקיים | E17: =IF(B17="","",הגדרות!$C$28) -> 6 | G17: =IF(B17="","",IF(O17=0,0,MIN(הגדרות!$C$29,MAX(E17,F17)))) -> 6 | H17: =IF(B17="","",O17*הגדרות!$C$26) -> 1300 | I17: =IF(B17="","",O17*G17*הגדרות!$C$27) -> 600 | J17: =IF(B17="","",H17+I17) -> 1900 | N17: =IF(N16="","",IF(N16+MIN(MOD(הגדרות!$D$19-WEEKDAY(N16)-1,7)+1,MOD(הגדרות!$D$20-WEEKDAY(N16)-1,7)+1)>$N$2,"",N16+MIN(MOD(הגדרות!$D$19-WEEKDAY(N16)-1,7)+1,MOD(הגדרות!$D$20-WEEKDAY(N16)-1,7)+1))) -> 46435 | O17: =IF(B17="","",IF(D17="בוטל בהתראה",0,IF(D17="בוטל ללא התראה",הגדרות!$C$30,1))) -> 1
