Workbook

Sheet הוראות
B1: איך משתמשים בקובץ
B3: 1. פעם אחת | C3: ממלאים את גיליון "הגדרות": שם מלא, מס׳ עוסק מורשה, טלפון ואיש קשר בחווה. תאים צהובים = למילוי. כל גיליונות החודשים מושכים את הפרטים משם.
B4: 2. בסוף כל חודש | C4: פותחים את הגיליון של החודש (למשל "אוקטובר 2026"). התאריכים של ימי ראשון וחמישי בחודש מחושבים אוטומטית, וכך גם השעות והסכומים.
B5: 3. ימים שלא התקיימו | C5: בעמודה "התקיים?" בוחרים "לא" (חג, מחלה, ביטול) – השורה תימחק בקו והשעות יתאפסו.
B6: 4. ישיבת צוות | C6: אפשר לרשום את תאריך הישיבה (לא חובה). אם לא הייתה ישיבה החודש – בוחרים "לא".
B7: 5. פרויקטים פרטיים | C7: בשתי העמודות השמאליות ("פרויקט פרטי – תיאור" ו"פרויקט פרטי – סכום") רושמים כל פרויקט שהחווה הזמינה, בכל שורה פנויה. הסכום לפני מע״מ. הסכומים נכנסים לסיכום בנפרד מהשעות.
B8: 6. שליחה | C8: קובץ ← שמירה בשם / ייצוא ← PDF, ושולחים לחווה. הגיליון מוגדר לעמוד A4 אחד.
B9: חודש חדש אחרי ספטמבר 2027 | C9: לוחצים ימני על לשונית של חודש ← העבר או העתק ← יצירת עותק, ומשנים בעותק את התא "חודש השירות" לתאריך כלשהו בחודש החדש (למשל 1/10/2027).
B10: שינוי תעריף / שעות / ימים | C10: משנים בגיליון "הגדרות" – כל החודשים מתעדכנים.
B12: מקרא צבעים
C13: תא צהוב בגיליון "הגדרות" – למילוי פעם אחת
C14: תא ברקע שמנת בגיליון החודש – למילוי חודשי (חודש, ישיבת צוות, התקיים?, פרויקטים)
B16: דוגמה לשורת פרויקט פרטי
B17: פרויקט פרטי – תיאור | C17: פרויקט פרטי – סכום (₪)
B18: ספסל עץ לכניסה לחווה | C18: 600

Sheet הגדרות
B1: הגדרות קבועות – ממלאים פעם אחת
B2: תאים צהובים = למילוי. כל גיליונות החודשים מושכים את הנתונים מכאן.
B4: פרטי העסק (הספק) | F4: רשימת ימים
B5: שם העסק | C5: הנגרייה | F5: ראשון
B6: שם מלא | C6: (למילוי) | F6: שני
B7: עוסק מורשה מס׳ | C7: (למילוי) | F7: שלישי
B8: טלפון | C8: (למילוי) | F8: רביעי
B9: אימייל | C9: nettaamit21@gmail.com | F9: חמישי
F10: שישי
B11: פרטי הלקוח | F11: שבת
B12: שם הלקוח | C12: חוות רום
B13: כתובת | C13: הר כמון
B14: איש קשר | C14: (למילוי)
B16: שעות ותעריף
B17: תיאור השירות | C17: הדרכת שיקום | D17: מס׳ יום
B18: יום עבודה 1 | C18: ראשון | D18: =MATCH(C18,$F$5:$F$11,0) -> 1
B19: יום עבודה 2 | C19: חמישי | D19: =MATCH(C19,$F$5:$F$11,0) -> 5
B20: שעת התחלה | C20: 0.375
B21: שעת סיום | C21: 0.52083333
B22: שעות ליום (מחושב) | C22: =(C21-C20)*24 -> 3.5
B23: ישיבת צוות – שעות בחודש | C23: 1
B24: תעריף לשעה (₪, לא כולל מע״מ) | C24: 50
B25: שיעור מע״מ | C25: 0.18
B27: הערות שיופיעו בתחתית ההצעה
B28: הערה 1 | C28: התעריף השעתי אינו כולל מע״מ. מע״מ יתווסף כחוק.
B29: הערה 2 | C29: פרויקטים פרטיים מתומחרים בנפרד, לפי הזמנת החווה.
B30: הערה 3 (למשל תנאי תשלום)

Sheet אוקטובר 2026
A1: הצעת מחיר | K1: =DATE(YEAR($H$11),MONTH($H$11),1) -> 46296
A2: =הגדרות!$C$17&" · "&CHOOSE(MONTH($K$1),"ינואר","פברואר","מרץ","אפריל","מאי","יוני","יולי","אוגוסט","ספטמבר","אוקטובר","נובמבר","דצמבר")&" "&YEAR($K$1) -> הדרכת שיקום · אוקטובר 2026 | K2: =EOMONTH($K$1,0) -> 46326
A4: מאת | F4: לכבוד
A5: שם העסק | C5: =הגדרות!$C$5 -> הנגרייה | F5: שם הלקוח | H5: =הגדרות!$C$12 -> חוות רום
A6: שם מלא | C6: =הגדרות!$C$6 -> (למילוי) | F6: כתובת | H6: =הגדרות!$C$13 -> הר כמון
A7: עוסק מורשה | C7: =הגדרות!$C$7 -> (למילוי) | F7: איש קשר | H7: =הגדרות!$C$14 -> (למילוי)
A8: טלפון | C8: =הגדרות!$C$8 -> (למילוי)
A9: אימייל | C9: =הגדרות!$C$9 -> nettaamit21@gmail.com
A11: מס׳ הצעה | C11: =YEAR($K$1)&"-"&TEXT(MONTH($K$1),"00") -> 2026-10 | F11: חודש השירות | H11: 46296
A12: תאריך | C12: =$K$2 -> 46326 | F12: ימי עבודה | H12: =הגדרות!$C$18&" ו"&הגדרות!$C$19&", "&TEXT(HOUR(הגדרות!$C$20),"00")&":"&TEXT(MINUTE(הגדרות!$C$20),"00")&"–"&TEXT(HOUR(הגדרות!$C$21),"00")&":"&TEXT(MINUTE(הגדרות!$C$21),"00") -> ראשון וחמישי, 09:00–12:30
A13: הדרכת שיקום – לפי שעות | H13: פרויקטים פרטיים – תמחור נפרד
A14: # | B14: תאריך | C14: יום | D14: פירוט | E14: התקיים? | F14: שעות | G14: סכום (₪) | H14: פרויקט פרטי – תיאור | I14: פרויקט פרטי – סכום (₪)
A15: =IF(B15="","",ROW()-14) -> 1 | B15: =$K$1+MIN(MOD(הגדרות!$D$18-WEEKDAY($K$1),7),MOD(הגדרות!$D$19-WEEKDAY($K$1),7)) -> 46296 | C15: =IF(B15="","",INDEX(הגדרות!$F$5:$F$11,WEEKDAY(B15))) -> חמישי | D15: =IF(B15="","","הדרכה "&TEXT(HOUR(הגדרות!$C$20),"00")&":"&TEXT(MINUTE(הגדרות!$C$20),"00")&"–"&TEXT(HOUR(הגדרות!$C$21),"00")&":"&TEXT(MINUTE(הגדרות!$C$21),"00")) -> הדרכה 09:00–12:30 | E15: כן | F15: =IF(B15="","",IF(E15="לא",0,הגדרות!$C$22)) -> 3.5 | G15: =IF(B15="","",F15*הגדרות!$C$24) -> 175 | K15: =IF(B15="","",B15+MIN(MOD(הגדרות!$D$18-WEEKDAY(B15)-1,7)+1,MOD(הגדרות!$D$19-WEEKDAY(B15)-1,7)+1)) -> 46299
A16: =IF(B16="","",ROW()-14) -> 2 | B16: =IF(K15="","",IF(K15>$K$2,"",K15)) -> 46299 | C16: =IF(B16="","",INDEX(הגדרות!$F$5:$F$11,WEEKDAY(B16))) -> ראשון | D16: =IF(B16="","","הדרכה "&TEXT(HOUR(הגדרות!$C$20),"00")&":"&TEXT(MINUTE(הגדרות!$C$20),"00")&"–"&TEXT(HOUR(הגדרות!$C$21),"00")&":"&TEXT(MINUTE(הגדרות!$C$21),"00")) -> הדרכה 09:00–12:30 | E16: כן | F16: =IF(B16="","",IF(E16="לא",0,הגדרות!$C$22)) -> 3.5 | G16: =IF(B16="","",F16*הגדרות!$C$24) -> 175 | K16: =IF(B16="","",B16+MIN(MOD(הגדרות!$D$18-WEEKDAY(B16)-1,7)+1,MOD(הגדרות!$D$19-WEEKDAY(B16)-1,7)+1)) -> 46303
A17: =IF(B17="","",ROW()-14) -> 3 | B17: =IF(K16="","",IF(K16>$K$2,"",K16)) -> 46303 | C17: =IF(B17="","",INDEX(הגדרות!$F$5:$F$11,WEEKDAY(B17))) -> חמישי | D17: =IF(B17="","","הדרכה "&TEXT(HOUR(הגדרות!$C$20),"00")&":"&TEXT(MINUTE(הגדרות!$C$20),"00")&"–"&TEXT(HOUR(הגדרות!$C$21),"00")&":"&TEXT(MINUTE(הגדרות!$C$21),"00")) -> הדרכה 09:00–12:30 | E17: כן | F17: =IF(B17="","",IF(E17="לא",0,הגדרות!$C$22)) -> 3.5 | G17: =IF(B17="","",F17*הגדרות!$C$24) -> 175 | K17: =IF(B17="","",B17+MIN(MOD(הגדרות!$D$18-WEEKDAY(B17)-1,7)+1,MOD(הגדרות!$D$19-WEEKDAY(B17)-1,7)+1)) -> 46306
A18: =IF(B18="","",ROW()-14) -> 4 | B18: =IF(K17="","",IF(K17>$K$2,"",K17)) -> 46306 | C18: =IF(B18="","",INDEX(הגדרות!$F$5:$F$11,WEEKDAY(B18))) -> ראשון | D18: =IF(B18="","","הדרכה "&TEXT(HOUR(הגדרות!$C$20),"00")&":"&TEXT(MINUTE(הגדרות!$C$20),"00")&"–"&TEXT(HOUR(הגדרות!$C$21),"00")&":"&TEXT(MINUTE(הגדרות!$C$21),"00")) -> הדרכה 09:00–12:30 | E18: כן | F18: =IF(B18="","",IF(E18="לא",0,הגדרות!$C$22)) -> 3.5 | G18: =IF(B18="","",F18*הגדרות!$C$24) -> 175 | K18: =IF(B18="","",B18+MIN(MOD(הגדרות!$D$18-WEEKDAY(B18)-1,7)+1,MOD(הגדרות!$D$19-WEEKDAY(B18)-1,7)+1)) -> 46310
A19: =IF(B19="","",ROW()-14) -> 5 | B19: =IF(K18="","",IF(K18>$K$2,"",K18)) -> 46310 | C19: =IF(B19="","",INDEX(הגדרות!$F$5:$F$11,WEEKDAY(B19))) -> חמישי | D19: =IF(B19="","","הדרכה "&TEXT(HOUR(הגדרות!$C$20),"00")&":"&TEXT(MINUTE(הגדרות!$C$20),"00")&"–"&TEXT(HOUR(הגדרות!$C$21),"00")&":"&TEXT(MINUTE(הגדרות!$C$21),"00")) -> הדרכה 09:00–12:30 | E19: כן | F19: =IF(B19="","",IF(E19="לא",0,הגדרות!$C$22)) -> 3.5 | G19: =IF(B19="","",F19*הגדרות!$C$24) -> 175 | K19: =IF(B19="","",B19+MIN(MOD(הגדרות!$D$18-WEEKDAY(B19)-1,7)+1,MOD(הגדרות!$D$19-WEEKDAY(B19)-1,7)+1)) -> 46313
A20: =IF(B20="","",ROW()-14) -> 6 | B20: =IF(K19="","",IF(K19>$K$2,"",K19)) -> 46313 | C20: =IF(B20="","",INDEX(הגדרות!$F$5:$F$11,WEEKDAY(B20))) -> ראשון | D20: =IF(B20="","","הדרכה "&TEXT(HOUR(הגדרות!$C$20),"00")&":"&TEXT(MINUTE(הגדרות!$C$20),"00")&"–"&TEXT(HOUR(הגדרות!$C$21),"00")&":"&TEXT(MINUTE(הגדרות!$C$21),"00")) -> הדרכה 09:00–12:30 | E20: כן | F20: =IF(B20="","",IF(E20="לא",0,הגדרות!$C$22)) -> 3.5 | G20: =IF(B20="","",F20*הגדרות!$C$24) -> 175 | K20: =IF(B20="","",B20+MIN(MOD(הגדרות!$D$18-WEEKDAY(B20)-1,7)+1,MOD(הגדרות!$D$19-WEEKDAY(B20)-1,7)+1)) -> 46317
A21: =IF(B21="","",ROW()-14) -> 7 | B21: =IF(K20="","",IF(K20>$K$2,"",K20)) -> 46317 | C21: =IF(B21="","",INDEX(הגדרות!$F$5:$F$11,WEEKDAY(B21))) -> חמישי | D21: =IF(B21="","","הדרכה "&TEXT(HOUR(הגדרות!$C$20),"00")&":"&TEXT(MINUTE(הגדרות!$C$20),"00")&"–"&TEXT(HOUR(הגדרות!$C$21),"00")&":"&TEXT(MINUTE(הגדרות!$C$21),"00")) -> הדרכה 09:00–12:30 | E21: כן | F21: =IF(B21="","",IF(E21="לא",0,הגדרות!$C$22)) -> 3.5 | G21: =IF(B21="","",F21*הגדרות!$C$24) -> 175 | K21: =IF(B21="","",B21+MIN(MOD(הגדרות!$D$18-WEEKDAY(B21)-1,7)+1,MOD(הגדרות!$D$19-WEEKDAY(B21)-1,7)+1)) -> 46320
A22: =IF(B22="","",ROW()-14) -> 8 | B22: =IF(K21="","",IF(K21>$K$2,"",K21)) -> 46320 | C22: =IF(B22="","",INDEX(הגדרות!$F$5:$F$11,WEEKDAY(B22))) -> ראשון | D22: =IF(B22="","","הדרכה "&TEXT(HOUR(הגדרות!$C$20),"00")&":"&TEXT(MINUTE(הגדרות!$C$20),"00")&"–"&TEXT(HOUR(הגדרות!$C$21),"00")&":"&TEXT(MINUTE(הגדרות!$C$21),"00")) -> הדרכה 09:00–12:30 | E22: כן | F22: =IF(B22="","",IF(E22="לא",0,הגדרות!$C$22)) -> 3.5 | G22: =IF(B22="","",F22*הגדרות!$C$24) -> 175 | K22: =IF(B22="","",B22+MIN(MOD(הגדרות!$D$18-WEEKDAY(B22)-1,7)+1,MOD(הגדרות!$D$19-WEEKDAY(B22)-1,7)+1)) -> 46324
A23: =IF(B23="","",ROW()-14) -> 9 | B23: =IF(K22="","",IF(K22>$K$2,"",K22)) -> 46324 | C23: =IF(B23="","",INDEX(הגדרות!$F$5:$F$11,WEEKDAY(B23))) -> חמישי | D23: =IF(B23="","","הדרכה "&TEXT(HOUR(הגדרות!$C$20),"00")&":"&TEXT(MINUTE(הגדרות!$C$20),"00")&"–"&TEXT(HOUR(הגדרות!$C$21),"00")&":"&TEXT(MINUTE(הגדרות!$C$21),"00")) -> הדרכה 09:00–12:30 | E23: כן | F23: =IF(B23="","",IF(E23="לא",0,הגדרות!$C$22)) -> 3.5 | G23: =IF(B23="","",F23*הגדרות!$C$24) -> 175 | K23: =IF(B23="","",B23+MIN(MOD(הגדרות!$D$18-WEEKDAY(B23)-1,7)+1,MOD(הגדרות!$D$19-WEEKDAY(B23)-1,7)+1)) -> 46327
A24: =IF(B24="","",ROW()-14) | B24: =IF(K23="","",IF(K23>$K$2,"",K23)) | C24: =IF(B24="","",INDEX(הגדרות!$F$5:$F$11,WEEKDAY(B24))) | D24: =IF(B24="","","הדרכה "&TEXT(HOUR(הגדרות!$C$20),"00")&":"&TEXT(MINUTE(הגדרות!$C$20),"00")&"–"&TEXT(HOUR(הגדרות!$C$21),"00")&":"&TEXT(MINUTE(הגדרות!$C$21),"00")) | E24: כן | F24: =IF(B24="","",IF(E24="לא",0,הגדרות!$C$22)) | G24: =IF(B24="","",F24*הגדרות!$C$24) | K24: =IF(B24="","",B24+MIN(MOD(הגדרות!$D$18-WEEKDAY(B24)-1,7)+1,MOD(הגדרות!$D$19-WEEKDAY(B24)-1,7)+1))
A25: =COUNT($B$15:$B$24)+1 -> 10 | C25: =IF(B25="","",INDEX(הגדרות!$F$5:$F$11,WEEKDAY(B25))) | D25: ישיבת צוות חודשית | E25: כן | F25: =IF(E25="לא",0,הגדרות!$C$23) -> 1 | G25: =F25*הגדרות!$C$24 -> 50
A26: סה״כ | F26: =SUM(F15:F25) -> 32.5 | G26: =SUM(G15:G25) -> 1625 | I26: =SUM(I15:I25) -> 0
A28: הערות | F28: סה״כ שעות | I28: =F26 -> 32.5
A29: ="• "&הגדרות!$C$17&": ימי "&הגדרות!$C$18&" ו"&הגדרות!$C$19&", "&TEXT(HOUR(הגדרות!$C$20),"00")&":"&TEXT(MINUTE(הגדרות!$C$20),"00")&"–"&TEXT(HOUR(הגדרות!$C$21),"00")&":"&TEXT(MINUTE(הגדרות!$C$21),"00")&" ("&הגדרות!$C$22&" שעות ליום), וישיבת צוות חודשית ("&הגדרות!$C$23&" ש׳)." -> • הדרכת שיקום: ימי ראשון וחמישי, 09:00–12:30 (3.5 שעות ליום), וישיבת צוות חודשית (1 ש׳). | F29: ="הדרכת שיקום ("&TEXT(F26,"0.0")&" שעות × "&הגדרות!$C$24&" ₪)" -> הדרכת שיקום (32.5 שעות × 50 ₪) | I29: =G26 -> 1625
A30: =IF(הגדרות!$C$28="","","• "&הגדרות!$C$28) -> • התעריף השעתי אינו כולל מע״מ. מע״מ יתווסף כחוק. | F30: פרויקטים פרטיים | I30: =I26 -> 0
A31: =IF(הגדרות!$C$29="","","• "&הגדרות!$C$29) -> • פרויקטים פרטיים מתומחרים בנפרד, לפי הזמנת החווה. | F31: סה״כ לפני מע״מ | I31: =I29+I30 -> 1625
A32: =IF(הגדרות!$C$30="","","• "&הגדרות!$C$30) | F32: ="מע״מ "&ROUND(הגדרות!$C$25*100,1)&"%" -> מע״מ 18% | I32: =ROUND(I31*הגדרות!$C$25,2) -> 292.5
F33: סה״כ לתשלום (כולל מע״מ) | I33: =I31+I32 -> 1917.5
A36: ="בברכה, "&הגדרות!$C$6 -> בברכה, (למילוי) | F36: חתימה: ____________________

Sheet נובמבר 2026
A1: הצעת מחיר | K1: =DATE(YEAR($H$11),MONTH($H$11),1) -> 46327
A2: =הגדרות!$C$17&" · "&CHOOSE(MONTH($K$1),"ינואר","פברואר","מרץ","אפריל","מאי","יוני","יולי","אוגוסט","ספטמבר","אוקטובר","נובמבר","דצמבר")&" "&YEAR($K$1) -> הדרכת שיקום · נובמבר 2026 | K2: =EOMONTH($K$1,0) -> 46356
A4: מאת | F4: לכבוד
A5: שם העסק | C5: =הגדרות!$C$5 -> הנגרייה | F5: שם הלקוח | H5: =הגדרות!$C$12 -> חוות רום
A6: שם מלא | C6: =הגדרות!$C$6 -> (למילוי) | F6: כתובת | H6: =הגדרות!$C$13 -> הר כמון
A7: עוסק מורשה | C7: =הגדרות!$C$7 -> (למילוי) | F7: איש קשר | H7: =הגדרות!$C$14 -> (למילוי)
A8: טלפון | C8: =הגדרות!$C$8 -> (למילוי)
A9: אימייל | C9: =הגדרות!$C$9 -> nettaamit21@gmail.com
A11: מס׳ הצעה | C11: =YEAR($K$1)&"-"&TEXT(MONTH($K$1),"00") -> 2026-11 | F11: חודש השירות | H11: 46327
A12: תאריך | C12: =$K$2 -> 46356 | F12: ימי עבודה | H12: =הגדרות!$C$18&" ו"&הגדרות!$C$19&", "&TEXT(HOUR(הגדרות!$C$20),"00")&":"&TEXT(MINUTE(הגדרות!$C$20),"00")&"–"&TEXT(HOUR(הגדרות!$C$21),"00")&":"&TEXT(MINUTE(הגדרות!$C$21),"00") -> ראשון וחמישי, 09:00–12:30
A13: הדרכת שיקום – לפי שעות | H13: פרויקטים פרטיים – תמחור נפרד
A14: # | B14: תאריך | C14: יום | D14: פירוט | E14: התקיים? | F14: שעות | G14: סכום (₪) | H14: פרויקט פרטי – תיאור | I14: פרויקט פרטי – סכום (₪)
A15: =IF(B15="","",ROW()-14) -> 1 | B15: =$K$1+MIN(MOD(הגדרות!$D$18-WEEKDAY($K$1),7),MOD(הגדרות!$D$19-WEEKDAY($K$1),7)) -> 46327 | C15: =IF(B15="","",INDEX(הגדרות!$F$5:$F$11,WEEKDAY(B15))) -> ראשון | D15: =IF(B15="","","הדרכה "&TEXT(HOUR(הגדרות!$C$20),"00")&":"&TEXT(MINUTE(הגדרות!$C$20),"00")&"–"&TEXT(HOUR(הגדרות!$C$21),"00")&":"&TEXT(MINUTE(הגדרות!$C$21),"00")) -> הדרכה 09:00–12:30 | E15: כן | F15: =IF(B15="","",IF(E15="לא",0,הגדרות!$C$22)) -> 3.5 | G15: =IF(B15="","",F15*הגדרות!$C$24) -> 175 | K15: =IF(B15="","",B15+MIN(MOD(הגדרות!$D$18-WEEKDAY(B15)-1,7)+1,MOD(הגדרות!$D$19-WEEKDAY(B15)-1,7)+1)) -> 46331
A16: =IF(B16="","",ROW()-14) -> 2 | B16: =IF(K15="","",IF(K15>$K$2,"",K15)) -> 46331 | C16: =IF(B16="","",INDEX(הגדרות!$F$5:$F$11,WEEKDAY(B16))) -> חמישי | D16: =IF(B16="","","הדרכה "&TEXT(HOUR(הגדרות!$C$20),"00")&":"&TEXT(MINUTE(הגדרות!$C$20),"00")&"–"&TEXT(HOUR(הגדרות!$C$21),"00")&":"&TEXT(MINUTE(הגדרות!$C$21),"00")) -> הדרכה 09:00–12:30 | E16: כן | F16: =IF(B16="","",IF(E16="לא",0,הגדרות!$C$22)) -> 3.5 | G16: =IF(B16="","",F16*הגדרות!$C$24) -> 175 | K16: =IF(B16="","",B16+MIN(MOD(הגדרות!$D$18-WEEKDAY(B16)-1,7)+1,MOD(הגדרות!$D$19-WEEKDAY(B16)-1,7)+1)) -> 46334
A17: =IF(B17="","",ROW()-14) -> 3 | B17: =IF(K16="","",IF(K16>$K$2,"",K16)) -> 46334 | C17: =IF(B17="","",INDEX(הגדרות!$F$5:$F$11,WEEKDAY(B17))) -> ראשון | D17: =IF(B17="","","הדרכה "&TEXT(HOUR(הגדרות!$C$20),"00")&":"&TEXT(MINUTE(הגדרות!$C$20),"00")&"–"&TEXT(HOUR(הגדרות!$C$21),"00")&":"&TEXT(MINUTE(הגדרות!$C$21),"00")) -> הדרכה 09:00–12:30 | E17: כן | F17: =IF(B17="","",IF(E17="לא",0,הגדרות!$C$22)) -> 3.5 | G17: =IF(B17="","",F17*הגדרות!$C$24) -> 175 | K17: =IF(B17="","",B17+MIN(MOD(הגדרות!$D$18-WEEKDAY(B17)-1,7)+1,MOD(הגדרות!$D$19-WEEKDAY(B17)-1,7)+1)) -> 46338
A18: =IF(B18="","",ROW()-14) -> 4 | B18: =IF(K17="","",IF(K17>$K$2,"",K17)) -> 46338 | C18: =IF(B18="","",INDEX(הגדרות!$F$5:$F$11,WEEKDAY(B18))) -> חמישי | D18: =IF(B18="","","הדרכה "&TEXT(HOUR(הגדרות!$C$20),"00")&":"&TEXT(MINUTE(הגדרות!$C$20),"00")&"–"&TEXT(HOUR(הגדרות!$C$21),"00")&":"&TEXT(MINUTE(הגדרות!$C$21),"00")) -> הדרכה 09:00–12:30 | E18: כן | F18: =IF(B18="","",IF(E18="לא",0,הגדרות!$C$22)) -> 3.5 | G18: =IF(B18="","",F18*הגדרות!$C$24) -> 175 | K18: =IF(B18="","",B18+MIN(MOD(הגדרות!$D$18-WEEKDAY(B18)-1,7)+1,MOD(הגדרות!$D$19-WEEKDAY(B18)-1,7)+1)) -> 46341
A19: =IF(B19="","",ROW()-14) -> 5 | B19: =IF(K18="","",IF(K18>$K$2,"",K18)) -> 46341 | C19: =IF(B19="","",INDEX(הגדרות!$F$5:$F$11,WEEKDAY(B19))) -> ראשון | D19: =IF(B19="","","הדרכה "&TEXT(HOUR(הגדרות!$C$20),"00")&":"&TEXT(MINUTE(הגדרות!$C$20),"00")&"–"&TEXT(HOUR(הגדרות!$C$21),"00")&":"&TEXT(MINUTE(הגדרות!$C$21),"00")) -> הדרכה 09:00–12:30 | E19: כן | F19: =IF(B19="","",IF(E19="לא",0,הגדרות!$C$22)) -> 3.5 | G19: =IF(B19="","",F19*הגדרות!$C$24) -> 175 | K19: =IF(B19="","",B19+MIN(MOD(הגדרות!$D$18-WEEKDAY(B19)-1,7)+1,MOD(הגדרות!$D$19-WEEKDAY(B19)-1,7)+1)) -> 46345
A20: =IF(B20="","",ROW()-14) -> 6 | B20: =IF(K19="","",IF(K19>$K$2,"",K19)) -> 46345 | C20: =IF(B20="","",INDEX(הגדרות!$F$5:$F$11,WEEKDAY(B20))) -> חמישי | D20: =IF(B20="","","הדרכה "&TEXT(HOUR(הגדרות!$C$20),"00")&":"&TEXT(MINUTE(הגדרות!$C$20),"00")&"–"&TEXT(HOUR(הגדרות!$C$21),"00")&":"&TEXT(MINUTE(הגדרות!$C$21),"00")) -> הדרכה 09:00–12:30 | E20: כן | F20: =IF(B20="","",IF(E20="לא",0,הגדרות!$C$22)) -> 3.5 | G20: =IF(B20="","",F20*הגדרות!$C$24) -> 175 | K20: =IF(B20="","",B20+MIN(MOD(הגדרות!$D$18-WEEKDAY(B20)-1,7)+1,MOD(הגדרות!$D$19-WEEKDAY(B20)-1,7)+1)) -> 46348
A21: =IF(B21="","",ROW()-14) -> 7 | B21: =IF(K20="","",IF(K20>$K$2,"",K20)) -> 46348 | C21: =IF(B21="","",INDEX(הגדרות!$F$5:$F$11,WEEKDAY(B21))) -> ראשון | D21: =IF(B21="","","הדרכה "&TEXT(HOUR(הגדרות!$C$20),"00")&":"&TEXT(MINUTE(הגדרות!$C$20),"00")&"–"&TEXT(HOUR(הגדרות!$C$21),"00")&":"&TEXT(MINUTE(הגדרות!$C$21),"00")) -> הדרכה 09:00–12:30 | E21: כן | F21: =IF(B21="","",IF(E21="לא",0,הגדרות!$C$22)) -> 3.5 | G21: =IF(B21="","",F21*הגדרות!$C$24) -> 175 | K21: =IF(B21="","",B21+MIN(MOD(הגדרות!$D$18-WEEKDAY(B21)-1,7)+1,MOD(הגדרות!$D$19-WEEKDAY(B21)-1,7)+1)) -> 46352
A22: =IF(B22="","",ROW()-14) -> 8 | B22: =IF(K21="","",IF(K21>$K$2,"",K21)) -> 46352 | C22: =IF(B22="","",INDEX(הגדרות!$F$5:$F$11,WEEKDAY(B22))) -> חמישי | D22: =IF(B22="","","הדרכה "&TEXT(HOUR(הגדרות!$C$20),"00")&":"&TEXT(MINUTE(הגדרות!$C$20),"00")&"–"&TEXT(HOUR(הגדרות!$C$21),"00")&":"&TEXT(MINUTE(הגדרות!$C$21),"00")) -> הדרכה 09:00–12:30 | E22: כן | F22: =IF(B22="","",IF(E22="לא",0,הגדרות!$C$22)) -> 3.5 | G22: =IF(B22="","",F22*הגדרות!$C$24) -> 175 | K22: =IF(B22="","",B22+MIN(MOD(הגדרות!$D$18-WEEKDAY(B22)-1,7)+1,MOD(הגדרות!$D$19-WEEKDAY(B22)-1,7)+1)) -> 46355
A23: =IF(B23="","",ROW()-14) -> 9 | B23: =IF(K22="","",IF(K22>$K$2,"",K22)) -> 46355 | C23: =IF(B23="","",INDEX(הגדרות!$F$5:$F$11,WEEKDAY(B23))) -> ראשון | D23: =IF(B23="","","הדרכה "&TEXT(HOUR(הגדרות!$C$20),"00")&":"&TEXT(MINUTE(הגדרות!$C$20),"00")&"–"&TEXT(HOUR(הגדרות!$C$21),"00")&":"&TEXT(MINUTE(הגדרות!$C$21),"00")) -> הדרכה 09:00–12:30 | E23: כן | F23: =IF(B23="","",IF(E23="לא",0,הגדרות!$C$22)) -> 3.5 | G23: =IF(B23="","",F23*הגדרות!$C$24) -> 175 | K23: =IF(B23="","",B23+MIN(MOD(הגדרות!$D$18-WEEKDAY(B23)-1,7)+1,MOD(הגדרות!$D$19-WEEKDAY(B23)-1,7)+1)) -> 46359
A24: =IF(B24="","",ROW()-14) | B24: =IF(K23="","",IF(K23>$K$2,"",K23)) | C24: =IF(B24="","",INDEX(הגדרות!$F$5:$F$11,WEEKDAY(B24))) | D24: =IF(B24="","","הדרכה "&TEXT(HOUR(הגדרות!$C$20),"00")&":"&TEXT(MINUTE(הגדרות!$C$20),"00")&"–"&TEXT(HOUR(הגדרות!$C$21),"00")&":"&TEXT(MINUTE(הגדרות!$C$21),"00")) | E24: כן | F24: =IF(B24="","",IF(E24="לא",0,הגדרות!$C$22)) | G24: =IF(B24="","",F24*הגדרות!$C$24) | K24: =IF(B24="","",B24+MIN(MOD(הגדרות!$D$18-WEEKDAY(B24)-1,7)+1,MOD(הגדרות!$D$19-WEEKDAY(B24)-1,7)+1))
A25: =COUNT($B$15:$B$24)+1 -> 10 | C25: =IF(B25="","",INDEX(הגדרות!$F$5:$F$11,WEEKDAY(B25))) | D25: ישיבת צוות חודשית | E25: כן | F25: =IF(E25="לא",0,הגדרות!$C$23) -> 1 | G25: =F25*הגדרות!$C$24 -> 50
A26: סה״כ | F26: =SUM(F15:F25) -> 32.5 | G26: =SUM(G15:G25) -> 1625 | I26: =SUM(I15:I25) -> 0
A28: הערות | F28: סה״כ שעות | I28: =F26 -> 32.5
A29: ="• "&הגדרות!$C$17&": ימי "&הגדרות!$C$18&" ו"&הגדרות!$C$19&", "&TEXT(HOUR(הגדרות!$C$20),"00")&":"&TEXT(MINUTE(הגדרות!$C$20),"00")&"–"&TEXT(HOUR(הגדרות!$C$21),"00")&":"&TEXT(MINUTE(הגדרות!$C$21),"00")&" ("&הגדרות!$C$22&" שעות ליום), וישיבת צוות חודשית ("&הגדרות!$C$23&" ש׳)." -> • הדרכת שיקום: ימי ראשון וחמישי, 09:00–12:30 (3.5 שעות ליום), וישיבת צוות חודשית (1 ש׳). | F29: ="הדרכת שיקום ("&TEXT(F26,"0.0")&" שעות × "&הגדרות!$C$24&" ₪)" -> הדרכת שיקום (32.5 שעות × 50 ₪) | I29: =G26 -> 1625
A30: =IF(הגדרות!$C$28="","","• "&הגדרות!$C$28) -> • התעריף השעתי אינו כולל מע״מ. מע״מ יתווסף כחוק. | F30: פרויקטים פרטיים | I30: =I26 -> 0
A31: =IF(הגדרות!$C$29="","","• "&הגדרות!$C$29) -> • פרויקטים פרטיים מתומחרים בנפרד, לפי הזמנת החווה. | F31: סה״כ לפני מע״מ | I31: =I29+I30 -> 1625
A32: =IF(הגדרות!$C$30="","","• "&הגדרות!$C$30) | F32: ="מע״מ "&ROUND(הגדרות!$C$25*100,1)&"%" -> מע״מ 18% | I32: =ROUND(I31*הגדרות!$C$25,2) -> 292.5
F33: סה״כ לתשלום (כולל מע״מ) | I33: =I31+I32 -> 1917.5
A36: ="בברכה, "&הגדרות!$C$6 -> בברכה, (למילוי) | F36: חתימה: ____________________

Sheet דצמבר 2026
A1: הצעת מחיר | K1: =DATE(YEAR($H$11),MONTH($H$11),1) -> 46357
A2: =הגדרות!$C$17&" · "&CHOOSE(MONTH($K$1),"ינואר","פברואר","מרץ","אפריל","מאי","יוני","יולי","אוגוסט","ספטמבר","אוקטובר","נובמבר","דצמבר")&" "&YEAR($K$1) -> הדרכת שיקום · דצמבר 2026 | K2: =EOMONTH($K$1,0) -> 46387
A4: מאת | F4: לכבוד
A5: שם העסק | C5: =הגדרות!$C$5 -> הנגרייה | F5: שם הלקוח | H5: =הגדרות!$C$12 -> חוות רום
A6: שם מלא | C6: =הגדרות!$C$6 -> (למילוי) | F6: כתובת | H6: =הגדרות!$C$13 -> הר כמון
A7: עוסק מורשה | C7: =הגדרות!$C$7 -> (למילוי) | F7: איש קשר | H7: =הגדרות!$C$14 -> (למילוי)
A8: טלפון | C8: =הגדרות!$C$8 -> (למילוי)
A9: אימייל | C9: =הגדרות!$C$9 -> nettaamit21@gmail.com
A11: מס׳ הצעה | C11: =YEAR($K$1)&"-"&TEXT(MONTH($K$1),"00") -> 2026-12 | F11: חודש השירות | H11: 46357
A12: תאריך | C12: =$K$2 -> 46387 | F12: ימי עבודה | H12: =הגדרות!$C$18&" ו"&הגדרות!$C$19&", "&TEXT(HOUR(הגדרות!$C$20),"00")&":"&TEXT(MINUTE(הגדרות!$C$20),"00")&"–"&TEXT(HOUR(הגדרות!$C$21),"00")&":"&TEXT(MINUTE(הגדרות!$C$21),"00") -> ראשון וחמישי, 09:00–12:30
A13: הדרכת שיקום – לפי שעות | H13: פרויקטים פרטיים – תמחור נפרד
A14: # | B14: תאריך | C14: יום | D14: פירוט | E14: התקיים? | F14: שעות | G14: סכום (₪) | H14: פרויקט פרטי – תיאור | I14: פרויקט פרטי – סכום (₪)
A15: =IF(B15="","",ROW()-14) -> 1 | B15: =$K$1+MIN(MOD(הגדרות!$D$18-WEEKDAY($K$1),7),MOD(הגדרות!$D$19-WEEKDAY($K$1),7)) -> 46359 | C15: =IF(B15="","",INDEX(הגדרות!$F$5:$F$11,WEEKDAY(B15))) -> חמישי | D15: =IF(B15="","","הדרכה "&TEXT(HOUR(הגדרות!$C$20),"00")&":"&TEXT(MINUTE(הגדרות!$C$20),"00")&"–"&TEXT(HOUR(הגדרות!$C$21),"00")&":"&TEXT(MINUTE(הגדרות!$C$21),"00")) -> הדרכה 09:00–12:30 | E15: כן | F15: =IF(B15="","",IF(E15="לא",0,הגדרות!$C$22)) -> 3.5 | G15: =IF(B15="","",F15*הגדרות!$C$24) -> 175 | K15: =IF(B15="","",B15+MIN(MOD(הגדרות!$D$18-WEEKDAY(B15)-1,7)+1,MOD(הגדרות!$D$19-WEEKDAY(B15)-1,7)+1)) -> 46362
A16: =IF(B16="","",ROW()-14) -> 2 | B16: =IF(K15="","",IF(K15>$K$2,"",K15)) -> 46362 | C16: =IF(B16="","",INDEX(הגדרות!$F$5:$F$11,WEEKDAY(B16))) -> ראשון | D16: =IF(B16="","","הדרכה "&TEXT(HOUR(הגדרות!$C$20),"00")&":"&TEXT(MINUTE(הגדרות!$C$20),"00")&"–"&TEXT(HOUR(הגדרות!$C$21),"00")&":"&TEXT(MINUTE(הגדרות!$C$21),"00")) -> הדרכה 09:00–12:30 | E16: כן | F16: =IF(B16="","",IF(E16="לא",0,הגדרות!$C$22)) -> 3.5 | G16: =IF(B16="","",F16*הגדרות!$C$24) -> 175 | K16: =IF(B16="","",B16+MIN(MOD(הגדרות!$D$18-WEEKDAY(B16)-1,7)+1,MOD(הגדרות!$D$19-WEEKDAY(B16)-1,7)+1)) -> 46366
A17: =IF(B17="","",ROW()-14) -> 3 | B17: =IF(K16="","",IF(K16>$K$2,"",K16)) -> 46366 | C17: =IF(B17="","",INDEX(הגדרות!$F$5:$F$11,WEEKDAY(B17))) -> חמישי | D17: =IF(B17="","","הדרכה "&TEXT(HOUR(הגדרות!$C$20),"00")&":"&TEXT(MINUTE(הגדרות!$C$20),"00")&"–"&TEXT(HOUR(הגדרות!$C$21),"00")&":"&TEXT(MINUTE(הגדרות!$C$21),"00")) -> הדרכה 09:00–12:30 | E17: כן | F17: =IF(B17="","",IF(E17="לא",0,הגדרות!$C$22)) -> 3.5 | G17: =IF(B17="","",F17*הגדרות!$C$24) -> 175 | K17: =IF(B17="","",B17+MIN(MOD(הגדרות!$D$18-WEEKDAY(B17)-1,7)+1,MOD(הגדרות!$D$19-WEEKDAY(B17)-1,7)+1)) -> 46369
A18: =IF(B18="","",ROW()-14) -> 4 | B18: =IF(K17="","",IF(K17>$K$2,"",K17)) -> 46369 | C18: =IF(B18="","",INDEX(הגדרות!$F$5:$F$11,WEEKDAY(B18))) -> ראשון | D18: =IF(B18="","","הדרכה "&TEXT(HOUR(הגדרות!$C$20),"00")&":"&TEXT(MINUTE(הגדרות!$C$20),"00")&"–"&TEXT(HOUR(הגדרות!$C$21),"00")&":"&TEXT(MINUTE(הגדרות!$C$21),"00")) -> הדרכה 09:00–12:30 | E18: כן | F18: =IF(B18="","",IF(E18="לא",0,הגדרות!$C$22)) -> 3.5 | G18: =IF(B18="","",F18*הגדרות!$C$24) -> 175 | K18: =IF(B18="","",B18+MIN(MOD(הגדרות!$D$18-WEEKDAY(B18)-1,7)+1,MOD(הגדרות!$D$19-WEEKDAY(B18)-1,7)+1)) -> 46373
A19: =IF(B19="","",ROW()-14) -> 5 | B19: =IF(K18="","",IF(K18>$K$2,"",K18)) -> 46373 | C19: =IF(B19="","",INDEX(הגדרות!$F$5:$F$11,WEEKDAY(B19))) -> חמישי | D19: =IF(B19="","","הדרכה "&TEXT(HOUR(הגדרות!$C$20),"00")&":"&TEXT(MINUTE(הגדרות!$C$20),"00")&"–"&TEXT(HOUR(הגדרות!$C$21),"00")&":"&TEXT(MINUTE(הגדרות!$C$21),"00")) -> הדרכה 09:00–12:30 | E19: כן | F19: =IF(B19="","",IF(E19="לא",0,הגדרות!$C$22)) -> 3.5 | G19: =IF(B19="","",F19*הגדרות!$C$24) -> 175 | K19: =IF(B19="","",B19+MIN(MOD(הגדרות!$D$18-WEEKDAY(B19)-1,7)+1,MOD(הגדרות!$D$19-WEEKDAY(B19)-1,7)+1)) -> 46376
A20: =IF(B20="","",ROW()-14) -> 6 | B20: =IF(K19="","",IF(K19>$K$2,"",K19)) -> 46376 | C20: =IF(B20="","",INDEX(הגדרות!$F$5:$F$11,WEEKDAY(B20))) -> ראשון | D20: =IF(B20="","","הדרכה "&TEXT(HOUR(הגדרות!$C$20),"00")&":"&TEXT(MINUTE(הגדרות!$C$20),"00")&"–"&TEXT(HOUR(הגדרות!$C$21),"00")&":"&TEXT(MINUTE(הגדרות!$C$21),"00")) -> הדרכה 09:00–12:30 | E20: כן | F20: =IF(B20="","",IF(E20="לא",0,הגדרות!$C$22)) -> 3.5 | G20: =IF(B20="","",F20*הגדרות!$C$24) -> 175 | K20: =IF(B20="","",B20+MIN(MOD(הגדרות!$D$18-WEEKDAY(B20)-1,7)+1,MOD(הגדרות!$D$19-WEEKDAY(B20)-1,7)+1)) -> 46380
A21: =IF(B21="","",ROW()-14) -> 7 | B21: =IF(K20="","",IF(K20>$K$2,"",K20)) -> 46380 | C21: =IF(B21="","",INDEX(הגדרות!$F$5:$F$11,WEEKDAY(B21))) -> חמישי | D21: =IF(B21="","","הדרכה "&TEXT(HOUR(הגדרות!$C$20),"00")&":"&TEXT(MINUTE(הגדרות!$C$20),"00")&"–"&TEXT(HOUR(הגדרות!$C$21),"00")&":"&TEXT(MINUTE(הגדרות!$C$21),"00")) -> הדרכה 09:00–12:30 | E21: כן | F21: =IF(B21="","",IF(E21="לא",0,הגדרות!$C$22)) -> 3.5 | G21: =IF(B21="","",F21*הגדרות!$C$24) -> 175 | K21: =IF(B21="","",B21+MIN(MOD(הגדרות!$D$18-WEEKDAY(B21)-1,7)+1,MOD(הגדרות!$D$19-WEEKDAY(B21)-1,7)+1)) -> 46383
A22: =IF(B22="","",ROW()-14) -> 8 | B22: =IF(K21="","",IF(K21>$K$2,"",K21)) -> 46383 | C22: =IF(B22="","",INDEX(הגדרות!$F$5:$F$11,WEEKDAY(B22))) -> ראשון | D22: =IF(B22="","","הדרכה "&TEXT(HOUR(הגדרות!$C$20),"00")&":"&TEXT(MINUTE(הגדרות!$C$20),"00")&"–"&TEXT(HOUR(הגדרות!$C$21),"00")&":"&TEXT(MINUTE(הגדרות!$C$21),"00")) -> הדרכה 09:00–12:30 | E22: כן | F22: =IF(B22="","",IF(E22="לא",0,הגדרות!$C$22)) -> 3.5 | G22: =IF(B22="","",F22*הגדרות!$C$24) -> 175 | K22: =IF(B22="","",B22+MIN(MOD(הגדרות!$D$18-WEEKDAY(B22)-1,7)+1,MOD(הגדרות!$D$19-WEEKDAY(B22)-1,7)+1)) -> 46387
A23: =IF(B23="","",ROW()-14) -> 9 | B23: =IF(K22="","",IF(K22>$K$2,"",K22)) -> 46387 | C23: =IF(B23="","",INDEX(הגדרות!$F$5:$F$11,WEEKDAY(B23))) -> חמישי | D23: =IF(B23="","","הדרכה "&TEXT(HOUR(הגדרות!$C$20),"00")&":"&TEXT(MINUTE(הגדרות!$C$20),"00")&"–"&TEXT(HOUR(הגדרות!$C$21),"00")&":"&TEXT(MINUTE(הגדרות!$C$21),"00")) -> הדרכה 09:00–12:30 | E23: כן | F23: =IF(B23="","",IF(E23="לא",0,הגדרות!$C$22)) -> 3.5 | G23: =IF(B23="","",F23*הגדרות!$C$24) -> 175 | K23: =IF(B23="","",B23+MIN(MOD(הגדרות!$D$18-WEEKDAY(B23)-1,7)+1,MOD(הגדרות!$D$19-WEEKDAY(B23)-1,7)+1)) -> 46390
A24: =IF(B24="","",ROW()-14) | B24: =IF(K23="","",IF(K23>$K$2,"",K23)) | C24: =IF(B24="","",INDEX(הגדרות!$F$5:$F$11,WEEKDAY(B24))) | D24: =IF(B24="","","הדרכה "&TEXT(HOUR(הגדרות!$C$20),"00")&":"&TEXT(MINUTE(הגדרות!$C$20),"00")&"–"&TEXT(HOUR(הגדרות!$C$21),"00")&":"&TEXT(MINUTE(הגדרות!$C$21),"00")) | E24: כן | F24: =IF(B24="","",IF(E24="לא",0,הגדרות!$C$22)) | G24: =IF(B24="","",F24*הגדרות!$C$24) | K24: =IF(B24="","",B24+MIN(MOD(הגדרות!$D$18-WEEKDAY(B24)-1,7)+1,MOD(הגדרות!$D$19-WEEKDAY(B24)-1,7)+1))
A25: =COUNT($B$15:$B$24)+1 -> 10 | C25: =IF(B25="","",INDEX(הגדרות!$F$5:$F$11,WEEKDAY(B25))) | D25: ישיבת צוות חודשית | E25: כן | F25: =IF(E25="לא",0,הגדרות!$C$23) -> 1 | G25: =F25*הגדרות!$C$24 -> 50
A26: סה״כ | F26: =SUM(F15:F25) -> 32.5 | G26: =SUM(G15:G25) -> 1625 | I26: =SUM(I15:I25) -> 0
A28: הערות | F28: סה״כ שעות | I28: =F26 -> 32.5
A29: ="• "&הגדרות!$C$17&": ימי "&הגדרות!$C$18&" ו"&הגדרות!$C$19&", "&TEXT(HOUR(הגדרות!$C$20),"00")&":"&TEXT(MINUTE(הגדרות!$C$20),"00")&"–"&TEXT(HOUR(הגדרות!$C$21),"00")&":"&TEXT(MINUTE(הגדרות!$C$21),"00")&" ("&הגדרות!$C$22&" שעות ליום), וישיבת צוות חודשית ("&הגדרות!$C$23&" ש׳)." -> • הדרכת שיקום: ימי ראשון וחמישי, 09:00–12:30 (3.5 שעות ליום), וישיבת צוות חודשית (1 ש׳). | F29: ="הדרכת שיקום ("&TEXT(F26,"0.0")&" שעות × "&הגדרות!$C$24&" ₪)" -> הדרכת שיקום (32.5 שעות × 50 ₪) | I29: =G26 -> 1625
A30: =IF(הגדרות!$C$28="","","• "&הגדרות!$C$28) -> • התעריף השעתי אינו כולל מע״מ. מע״מ יתווסף כחוק. | F30: פרויקטים פרטיים | I30: =I26 -> 0
A31: =IF(הגדרות!$C$29="","","• "&הגדרות!$C$29) -> • פרויקטים פרטיים מתומחרים בנפרד, לפי הזמנת החווה. | F31: סה״כ לפני מע״מ | I31: =I29+I30 -> 1625
A32: =IF(הגדרות!$C$30="","","• "&הגדרות!$C$30) | F32: ="מע״מ "&ROUND(הגדרות!$C$25*100,1)&"%" -> מע״מ 18% | I32: =ROUND(I31*הגדרות!$C$25,2) -> 292.5
F33: סה״כ לתשלום (כולל מע״מ) | I33: =I31+I32 -> 1917.5
A36: ="בברכה, "&הגדרות!$C$6 -> בברכה, (למילוי) | F36: חתימה: ____________________

Sheet ינואר 2027
A1: הצעת מחיר | K1: =DATE(YEAR($H$11),MONTH($H$11),1) -> 46388
A2: =הגדרות!$C$17&" · "&CHOOSE(MONTH($K$1),"ינואר","פברואר","מרץ","אפריל","מאי","יוני","יולי","אוגוסט","ספטמבר","אוקטובר","נובמבר","דצמבר")&" "&YEAR($K$1) -> הדרכת שיקום · ינואר 2027 | K2: =EOMONTH($K$1,0) -> 46418
A4: מאת | F4: לכבוד
A5: שם העסק | C5: =הגדרות!$C$5 -> הנגרייה | F5: שם הלקוח | H5: =הגדרות!$C$12 -> חוות רום
A6: שם מלא | C6: =הגדרות!$C$6 -> (למילוי) | F6: כתובת | H6: =הגדרות!$C$13 -> הר כמון
A7: עוסק מורשה | C7: =הגדרות!$C$7 -> (למילוי) | F7: איש קשר | H7: =הגדרות!$C$14 -> (למילוי)
A8: טלפון | C8: =הגדרות!$C$8 -> (למילוי)
A9: אימייל | C9: =הגדרות!$C$9 -> nettaamit21@gmail.com
A11: מס׳ הצעה | C11: =YEAR($K$1)&"-"&TEXT(MONTH($K$1),"00") -> 2027-01 | F11: חודש השירות | H11: 46388
A12: תאריך | C12: =$K$2 -> 46418 | F12: ימי עבודה | H12: =הגדרות!$C$18&" ו"&הגדרות!$C$19&", "&TEXT(HOUR(הגדרות!$C$20),"00")&":"&TEXT(MINUTE(הגדרות!$C$20),"00")&"–"&TEXT(HOUR(הגדרות!$C$21),"00")&":"&TEXT(MINUTE(הגדרות!$C$21),"00") -> ראשון וחמישי, 09:00–12:30
A13: הדרכת שיקום – לפי שעות | H13: פרויקטים פרטיים – תמחור נפרד
A14: # | B14: תאריך | C14: יום | D14: פירוט | E14: התקיים? | F14: שעות | G14: סכום (₪) | H14: פרויקט פרטי – תיאור | I14: פרויקט פרטי – סכום (₪)
A15: =IF(B15="","",ROW()-14) -> 1 | B15: =$K$1+MIN(MOD(הגדרות!$D$18-WEEKDAY($K$1),7),MOD(הגדרות!$D$19-WEEKDAY($K$1),7)) -> 46390 | C15: =IF(B15="","",INDEX(הגדרות!$F$5:$F$11,WEEKDAY(B15))) -> ראשון | D15: =IF(B15="","","הדרכה "&TEXT(HOUR(הגדרות!$C$20),"00")&":"&TEXT(MINUTE(הגדרות!$C$20),"00")&"–"&TEXT(HOUR(הגדרות!$C$21),"00")&":"&TEXT(MINUTE(הגדרות!$C$21),"00")) -> הדרכה 09:00–12:30 | E15: כן | F15: =IF(B15="","",IF(E15="לא",0,הגדרות!$C$22)) -> 3.5 | G15: =IF(B15="","",F15*הגדרות!$C$24) -> 175 | K15: =IF(B15="","",B15+MIN(MOD(הגדרות!$D$18-WEEKDAY(B15)-1,7)+1,MOD(הגדרות!$D$19-WEEKDAY(B15)-1,7)+1)) -> 46394
A16: =IF(B16="","",ROW()-14) -> 2 | B16: =IF(K15="","",IF(K15>$K$2,"",K15)) -> 46394 | C16: =IF(B16="","",INDEX(הגדרות!$F$5:$F$11,WEEKDAY(B16))) -> חמישי | D16: =IF(B16="","","הדרכה "&TEXT(HOUR(הגדרות!$C$20),"00")&":"&TEXT(MINUTE(הגדרות!$C$20),"00")&"–"&TEXT(HOUR(הגדרות!$C$21),"00")&":"&TEXT(MINUTE(הגדרות!$C$21),"00")) -> הדרכה 09:00–12:30 | E16: כן | F16: =IF(B16="","",IF(E16="לא",0,הגדרות!$C$22)) -> 3.5 | G16: =IF(B16="","",F16*הגדרות!$C$24) -> 175 | K16: =IF(B16="","",B16+MIN(MOD(הגדרות!$D$18-WEEKDAY(B16)-1,7)+1,MOD(הגדרות!$D$19-WEEKDAY(B16)-1,7)+1)) -> 46397
A17: =IF(B17="","",ROW()-14) -> 3 | B17: =IF(K16="","",IF(K16>$K$2,"",K16)) -> 46397 | C17: =IF(B17="","",INDEX(הגדרות!$F$5:$F$11,WEEKDAY(B17))) -> ראשון | D17: =IF(B17="","","הדרכה "&TEXT(HOUR(הגדרות!$C$20),"00")&":"&TEXT(MINUTE(הגדרות!$C$20),"00")&"–"&TEXT(HOUR(הגדרות!$C$21),"00")&":"&TEXT(MINUTE(הגדרות!$C$21),"00")) -> הדרכה 09:00–12:30 | E17: כן | F17: =IF(B17="","",IF(E17="לא",0,הגדרות!$C$22)) -> 3.5 | G17: =IF(B17="","",F17*הגדרות!$C$24) -> 175 | K17: =IF(B17="","",B17+MIN(MOD(הגדרות!$D$18-WEEKDAY(B17)-1,7)+1,MOD(הגדרות!$D$19-WEEKDAY(B17)-1,7)+1)) -> 46401
A18: =IF(B18="","",ROW()-14) -> 4 | B18: =IF(K17="","",IF(K17>$K$2,"",K17)) -> 46401 | C18: =IF(B18="","",INDEX(הגדרות!$F$5:$F$11,WEEKDAY(B18))) -> חמישי | D18: =IF(B18="","","הדרכה "&TEXT(HOUR(הגדרות!$C$20),"00")&":"&TEXT(MINUTE(הגדרות!$C$20),"00")&"–"&TEXT(HOUR(הגדרות!$C$21),"00")&":"&TEXT(MINUTE(הגדרות!$C$21),"00")) -> הדרכה 09:00–12:30 | E18: כן | F18: =IF(B18="","",IF(E18="לא",0,הגדרות!$C$22)) -> 3.5 | G18: =IF(B18="","",F18*הגדרות!$C$24) -> 175 | K18: =IF(B18="","",B18+MIN(MOD(הגדרות!$D$18-WEEKDAY(B18)-1,7)+1,MOD(הגדרות!$D$19-WEEKDAY(B18)-1,7)+1)) -> 46404
A19: =IF(B19="","",ROW()-14) -> 5 | B19: =IF(K18="","",IF(K18>$K$2,"",K18)) -> 46404 | C19: =IF(B19="","",INDEX(הגדרות!$F$5:$F$11,WEEKDAY(B19))) -> ראשון | D19: =IF(B19="","","הדרכה "&TEXT(HOUR(הגדרות!$C$20),"00")&":"&TEXT(MINUTE(הגדרות!$C$20),"00")&"–"&TEXT(HOUR(הגדרות!$C$21),"00")&":"&TEXT(MINUTE(הגדרות!$C$21),"00")) -> הדרכה 09:00–12:30 | E19: כן | F19: =IF(B19="","",IF(E19="לא",0,הגדרות!$C$22)) -> 3.5 | G19: =IF(B19="","",F19*הגדרות!$C$24) -> 175 | K19: =IF(B19="","",B19+MIN(MOD(הגדרות!$D$18-WEEKDAY(B19)-1,7)+1,MOD(הגדרות!$D$19-WEEKDAY(B19)-1,7)+1)) -> 46408
A20: =IF(B20="","",ROW()-14) -> 6 | B20: =IF(K19="","",IF(K19>$K$2,"",K19)) -> 46408 | C20: =IF(B20="","",INDEX(הגדרות!$F$5:$F$11,WEEKDAY(B20))) -> חמישי | D20: =IF(B20="","","הדרכה "&TEXT(HOUR(הגדרות!$C$20),"00")&":"&TEXT(MINUTE(הגדרות!$C$20),"00")&"–"&TEXT(HOUR(הגדרות!$C$21),"00")&":"&TEXT(MINUTE(הגדרות!$C$21),"00")) -> הדרכה 09:00–12:30 | E20: כן | F20: =IF(B20="","",IF(E20="לא",0,הגדרות!$C$22)) -> 3.5 | G20: =IF(B20="","",F20*הגדרות!$C$24) -> 175 | K20: =IF(B20="","",B20+MIN(MOD(הגדרות!$D$18-WEEKDAY(B20)-1,7)+1,MOD(הגדרות!$D$19-WEEKDAY(B20)-1,7)+1)) -> 46411
A21: =IF(B21="","",ROW()-14) -> 7 | B21: =IF(K20="","",IF(K20>$K$2,"",K20)) -> 46411 | C21: =IF(B21="","",INDEX(הגדרות!$F$5:$F$11,WEEKDAY(B21))) -> ראשון | D21: =IF(B21="","","הדרכה "&TEXT(HOUR(הגדרות!$C$20),"00")&":"&TEXT(MINUTE(הגדרות!$C$20),"00")&"–"&TEXT(HOUR(הגדרות!$C$21),"00")&":"&TEXT(MINUTE(הגדרות!$C$21),"00")) -> הדרכה 09:00–12:30 | E21: כן | F21: =IF(B21="","",IF(E21="לא",0,הגדרות!$C$22)) -> 3.5 | G21: =IF(B21="","",F21*הגדרות!$C$24) -> 175 | K21: =IF(B21="","",B21+MIN(MOD(הגדרות!$D$18-WEEKDAY(B21)-1,7)+1,MOD(הגדרות!$D$19-WEEKDAY(B21)-1,7)+1)) -> 46415
A22: =IF(B22="","",ROW()-14) -> 8 | B22: =IF(K21="","",IF(K21>$K$2,"",K21)) -> 46415 | C22: =IF(B22="","",INDEX(הגדרות!$F$5:$F$11,WEEKDAY(B22))) -> חמישי | D22: =IF(B22="","","הדרכה "&TEXT(HOUR(הגדרות!$C$20),"00")&":"&TEXT(MINUTE(הגדרות!$C$20),"00")&"–"&TEXT(HOUR(הגדרות!$C$21),"00")&":"&TEXT(MINUTE(הגדרות!$C$21),"00")) -> הדרכה 09:00–12:30 | E22: כן | F22: =IF(B22="","",IF(E22="לא",0,הגדרות!$C$22)) -> 3.5 | G22: =IF(B22="","",F22*הגדרות!$C$24) -> 175 | K22: =IF(B22="","",B22+MIN(MOD(הגדרות!$D$18-WEEKDAY(B22)-1,7)+1,MOD(הגדרות!$D$19-WEEKDAY(B22)-1,7)+1)) -> 46418
A23: =IF(B23="","",ROW()-14) -> 9 | B23: =IF(K22="","",IF(K22>$K$2,"",K22)) -> 46418 | C23: =IF(B23="","",INDEX(הגדרות!$F$5:$F$11,WEEKDAY(B23))) -> ראשון | D23: =IF(B23="","","הדרכה "&TEXT(HOUR(הגדרות!$C$20),"00")&":"&TEXT(MINUTE(הגדרות!$C$20),"00")&"–"&TEXT(HOUR(הגדרות!$C$21),"00")&":"&TEXT(MINUTE(הגדרות!$C$21),"00")) -> הדרכה 09:00–12:30 | E23: כן | F23: =IF(B23="","",IF(E23="לא",0,הגדרות!$C$22)) -> 3.5 | G23: =IF(B23="","",F23*הגדרות!$C$24) -> 175 | K23: =IF(B23="","",B23+MIN(MOD(הגדרות!$D$18-WEEKDAY(B23)-1,7)+1,MOD(הגדרות!$D$19-WEEKDAY(B23)-1,7)+1)) -> 46422
A24: =IF(B24="","",ROW()-14) | B24: =IF(K23="","",IF(K23>$K$2,"",K23)) | C24: =IF(B24="","",INDEX(הגדרות!$F$5:$F$11,WEEKDAY(B24))) | D24: =IF(B24="","","הדרכה "&TEXT(HOUR(הגדרות!$C$20),"00")&":"&TEXT(MINUTE(הגדרות!$C$20),"00")&"–"&TEXT(HOUR(הגדרות!$C$21),"00")&":"&TEXT(MINUTE(הגדרות!$C$21),"00")) | E24: כן | F24: =IF(B24="","",IF(E24="לא",0,הגדרות!$C$22)) | G24: =IF(B24="","",F24*הגדרות!$C$24) | K24: =IF(B24="","",B24+MIN(MOD(הגדרות!$D$18-WEEKDAY(B24)-1,7)+1,MOD(הגדרות!$D$19-WEEKDAY(B24)-1,7)+1))
A25: =COUNT($B$15:$B$24)+1 -> 10 | C25: =IF(B25="","",INDEX(הגדרות!$F$5:$F$11,WEEKDAY(B25))) | D25: ישיבת צוות חודשית | E25: כן | F25: =IF(E25="לא",0,הגדרות!$C$23) -> 1 | G25: =F25*הגדרות!$C$24 -> 50
A26: סה״כ | F26: =SUM(F15:F25) -> 32.5 | G26: =SUM(G15:G25) -> 1625 | I26: =SUM(I15:I25) -> 0
A28: הערות | F28: סה״כ שעות | I28: =F26 -> 32.5
A29: ="• "&הגדרות!$C$17&": ימי "&הגדרות!$C$18&" ו"&הגדרות!$C$19&", "&TEXT(HOUR(הגדרות!$C$20),"00")&":"&TEXT(MINUTE(הגדרות!$C$20),"00")&"–"&TEXT(HOUR(הגדרות!$C$21),"00")&":"&TEXT(MINUTE(הגדרות!$C$21),"00")&" ("&הגדרות!$C$22&" שעות ליום), וישיבת צוות חודשית ("&הגדרות!$C$23&" ש׳)." -> • הדרכת שיקום: ימי ראשון וחמישי, 09:00–12:30 (3.5 שעות ליום), וישיבת צוות חודשית (1 ש׳). | F29: ="הדרכת שיקום ("&TEXT(F26,"0.0")&" שעות × "&הגדרות!$C$24&" ₪)" -> הדרכת שיקום (32.5 שעות × 50 ₪) | I29: =G26 -> 1625
A30: =IF(הגדרות!$C$28="","","• "&הגדרות!$C$28) -> • התעריף השעתי אינו כולל מע״מ. מע״מ יתווסף כחוק. | F30: פרויקטים פרטיים | I30: =I26 -> 0
A31: =IF(הגדרות!$C$29="","","• "&הגדרות!$C$29) -> • פרויקטים פרטיים מתומחרים בנפרד, לפי הזמנת החווה. | F31: סה״כ לפני מע״מ | I31: =I29+I30 -> 1625
A32: =IF(הגדרות!$C$30="","","• "&הגדרות!$C$30) | F32: ="מע״מ "&ROUND(הגדרות!$C$25*100,1)&"%" -> מע״מ 18% | I32: =ROUND(I31*הגדרות!$C$25,2) -> 292.5
F33: סה״כ לתשלום (כולל מע״מ) | I33: =I31+I32 -> 1917.5
A36: ="בברכה, "&הגדרות!$C$6 -> בברכה, (למילוי) | F36: חתימה: ____________________

Sheet פברואר 2027
A1: הצעת מחיר | K1: =DATE(YEAR($H$11),MONTH($H$11),1) -> 46419
A2: =הגדרות!$C$17&" · "&CHOOSE(MONTH($K$1),"ינואר","פברואר","מרץ","אפריל","מאי","יוני","יולי","אוגוסט","ספטמבר","אוקטובר","נובמבר","דצמבר")&" "&YEAR($K$1) -> הדרכת שיקום · פברואר 2027 | K2: =EOMONTH($K$1,0) -> 46446
A4: מאת | F4: לכבוד
A5: שם העסק | C5: =הגדרות!$C$5 -> הנגרייה | F5: שם הלקוח | H5: =הגדרות!$C$12 -> חוות רום
A6: שם מלא | C6: =הגדרות!$C$6 -> (למילוי) | F6: כתובת | H6: =הגדרות!$C$13 -> הר כמון
A7: עוסק מורשה | C7: =הגדרות!$C$7 -> (למילוי) | F7: איש קשר | H7: =הגדרות!$C$14 -> (למילוי)
A8: טלפון | C8: =הגדרות!$C$8 -> (למילוי)
A9: אימייל | C9: =הגדרות!$C$9 -> nettaamit21@gmail.com
A11: מס׳ הצעה | C11: =YEAR($K$1)&"-"&TEXT(MONTH($K$1),"00") -> 2027-02 | F11: חודש השירות | H11: 46419
A12: תאריך | C12: =$K$2 -> 46446 | F12: ימי עבודה | H12: =הגדרות!$C$18&" ו"&הגדרות!$C$19&", "&TEXT(HOUR(הגדרות!$C$20),"00")&":"&TEXT(MINUTE(הגדרות!$C$20),"00")&"–"&TEXT(HOUR(הגדרות!$C$21),"00")&":"&TEXT(MINUTE(הגדרות!$C$21),"00") -> ראשון וחמישי, 09:00–12:30
A13: הדרכת שיקום – לפי שעות | H13: פרויקטים פרטיים – תמחור נפרד
A14: # | B14: תאריך | C14: יום | D14: פירוט | E14: התקיים? | F14: שעות | G14: סכום (₪) | H14: פרויקט פרטי – תיאור | I14: פרויקט פרטי – סכום (₪)
A15: =IF(B15="","",ROW()-14) -> 1 | B15: =$K$1+MIN(MOD(הגדרות!$D$18-WEEKDAY($K$1),7),MOD(הגדרות!$D$19-WEEKDAY($K$1),7)) -> 46422 | C15: =IF(B15="","",INDEX(הגדרות!$F$5:$F$11,WEEKDAY(B15))) -> חמישי | D15: =IF(B15="","","הדרכה "&TEXT(HOUR(הגדרות!$C$20),"00")&":"&TEXT(MINUTE(הגדרות!$C$20),"00")&"–"&TEXT(HOUR(הגדרות!$C$21),"00")&":"&TEXT(MINUTE(הגדרות!$C$21),"00")) -> הדרכה 09:00–12:30 | E15: כן | F15: =IF(B15="","",IF(E15="לא",0,הגדרות!$C$22)) -> 3.5 | G15: =IF(B15="","",F15*הגדרות!$C$24) -> 175 | K15: =IF(B15="","",B15+MIN(MOD(הגדרות!$D$18-WEEKDAY(B15)-1,7)+1,MOD(הגדרות!$D$19-WEEKDAY(B15)-1,7)+1)) -> 46425
A16: =IF(B16="","",ROW()-14) -> 2 | B16: =IF(K15="","",IF(K15>$K$2,"",K15)) -> 46425 | C16: =IF(B16="","",INDEX(הגדרות!$F$5:$F$11,WEEKDAY(B16))) -> ראשון | D16: =IF(B16="","","הדרכה "&TEXT(HOUR(הגדרות!$C$20),"00")&":"&TEXT(MINUTE(הגדרות!$C$20),"00")&"–"&TEXT(HOUR(הגדרות!$C$21),"00")&":"&TEXT(MINUTE(הגדרות!$C$21),"00")) -> הדרכה 09:00–12:30 | E16: כן | F16: =IF(B16="","",IF(E16="לא",0,הגדרות!$C$22)) -> 3.5 | G16: =IF(B16="","",F16*הגדרות!$C$24) -> 175 | K16: =IF(B16="","",B16+MIN(MOD(הגדרות!$D$18-WEEKDAY(B16)-1,7)+1,MOD(הגדרות!$D$19-WEEKDAY(B16)-1,7)+1)) -> 46429
A17: =IF(B17="","",ROW()-14) -> 3 | B17: =IF(K16="","",IF(K16>$K$2,"",K16)) -> 46429 | C17: =IF(B17="","",INDEX(הגדרות!$F$5:$F$11,WEEKDAY(B17))) -> חמישי | D17: =IF(B17="","","הדרכה "&TEXT(HOUR(הגדרות!$C$20),"00")&":"&TEXT(MINUTE(הגדרות!$C$20),"00")&"–"&TEXT(HOUR(הגדרות!$C$21),"00")&":"&TEXT(MINUTE(הגדרות!$C$21),"00")) -> הדרכה 09:00–12:30 | E17: כן | F17: =IF(B17="","",IF(E17="לא",0,הגדרות!$C$22)) -> 3.5 | G17: =IF(B17="","",F17*הגדרות!$C$24) -> 175 | K17: =IF(B17="","",B17+MIN(MOD(הגדרות!$D$18-WEEKDAY(B17)-1,7)+1,MOD(הגדרות!$D$19-WEEKDAY(B17)-1,7)+1)) -> 46432
A18: =IF(B18="","",ROW()-14) -> 4 | B18: =IF(K17="","",IF(K17>$K$2,"",K17)) -> 46432 | C18: =IF(B18="","",INDEX(הגדרות!$F$5:$F$11,WEEKDAY(B18))) -> ראשון | D18: =IF(B18="","","הדרכה "&TEXT(HOUR(הגדרות!$C$20),"00")&":"&TEXT(MINUTE(הגדרות!$C$20),"00")&"–"&TEXT(HOUR(הגדרות!$C$21),"00")&":"&TEXT(MINUTE(הגדרות!$C$21),"00")) -> הדרכה 09:00–12:30 | E18: כן | F18: =IF(B18="","",IF(E18="לא",0,הגדרות!$C$22)) -> 3.5 | G18: =IF(B18="","",F18*הגדרות!$C$24) -> 175 | K18: =IF(B18="","",B18+MIN(MOD(הגדרות!$D$18-WEEKDAY(B18)-1,7)+1,MOD(הגדרות!$D$19-WEEKDAY(B18)-1,7)+1)) -> 46436
A19: =IF(B19="","",ROW()-14) -> 5 | B19: =IF(K18="","",IF(K18>$K$2,"",K18)) -> 46436 | C19: =IF(B19="","",INDEX(הגדרות!$F$5:$F$11,WEEKDAY(B19))) -> חמישי | D19: =IF(B19="","","הדרכה "&TEXT(HOUR(הגדרות!$C$20),"00")&":"&TEXT(MINUTE(הגדרות!$C$20),"00")&"–"&TEXT(HOUR(הגדרות!$C$21),"00")&":"&TEXT(MINUTE(הגדרות!$C$21),"00")) -> הדרכה 09:00–12:30 | E19: כן | F19: =IF(B19="","",IF(E19="לא",0,הגדרות!$C$22)) -> 3.5 | G19: =IF(B19="","",F19*הגדרות!$C$24) -> 175 | K19: =IF(B19="","",B19+MIN(MOD(הגדרות!$D$18-WEEKDAY(B19)-1,7)+1,MOD(הגדרות!$D$19-WEEKDAY(B19)-1,7)+1)) -> 46439
A20: =IF(B20="","",ROW()-14) -> 6 | B20: =IF(K19="","",IF(K19>$K$2,"",K19)) -> 46439 | C20: =IF(B20="","",INDEX(הגדרות!$F$5:$F$11,WEEKDAY(B20))) -> ראשון | D20: =IF(B20="","","הדרכה "&TEXT(HOUR(הגדרות!$C$20),"00")&":"&TEXT(MINUTE(הגדרות!$C$20),"00")&"–"&TEXT(HOUR(הגדרות!$C$21),"00")&":"&TEXT(MINUTE(הגדרות!$C$21),"00")) -> הדרכה 09:00–12:30 | E20: כן | F20: =IF(B20="","",IF(E20="לא",0,הגדרות!$C$22)) -> 3.5 | G20: =IF(B20="","",F20*הגדרות!$C$24) -> 175 | K20: =IF(B20="","",B20+MIN(MOD(הגדרות!$D$18-WEEKDAY(B20)-1,7)+1,MOD(הגדרות!$D$19-WEEKDAY(B20)-1,7)+1)) -> 46443
A21: =IF(B21="","",ROW()-14) -> 7 | B21: =IF(K20="","",IF(K20>$K$2,"",K20)) -> 46443 | C21: =IF(B21="","",INDEX(הגדרות!$F$5:$F$11,WEEKDAY(B21))) -> חמישי | D21: =IF(B21="","","הדרכה "&TEXT(HOUR(הגדרות!$C$20),"00")&":"&TEXT(MINUTE(הגדרות!$C$20),"00")&"–"&TEXT(HOUR(הגדרות!$C$21),"00")&":"&TEXT(MINUTE(הגדרות!$C$21),"00")) -> הדרכה 09:00–12:30 | E21: כן | F21: =IF(B21="","",IF(E21="לא",0,הגדרות!$C$22)) -> 3.5 | G21: =IF(B21="","",F21*הגדרות!$C$24) -> 175 | K21: =IF(B21="","",B21+MIN(MOD(הגדרות!$D$18-WEEKDAY(B21)-1,7)+1,MOD(הגדרות!$D$19-WEEKDAY(B21)-1,7)+1)) -> 46446
A22: =IF(B22="","",ROW()-14) -> 8 | B22: =IF(K21="","",IF(K21>$K$2,"",K21)) -> 46446 | C22: =IF(B22="","",INDEX(הגדרות!$F$5:$F$11,WEEKDAY(B22))) -> ראשון | D22: =IF(B22="","","הדרכה "&TEXT(HOUR(הגדרות!$C$20),"00")&":"&TEXT(MINUTE(הגדרות!$C$20),"00")&"–"&TEXT(HOUR(הגדרות!$C$21),"00")&":"&TEXT(MINUTE(הגדרות!$C$21),"00")) -> הדרכה 09:00–12:30 | E22: כן | F22: =IF(B22="","",IF(E22="לא",0,הגדרות!$C$22)) -> 3.5 | G22: =IF(B22="","",F22*הגדרות!$C$24) -> 175 | K22: =IF(B22="","",B22+MIN(MOD(הגדרות!$D$18-WEEKDAY(B22)-1,7)+1,MOD(הגדרות!$D$19-WEEKDAY(B22)-1,7)+1)) -> 46450
A23: =IF(B23="","",ROW()-14) | B23: =IF(K22="","",IF(K22>$K$2,"",K22)) | C23: =IF(B23="","",INDEX(הגדרות!$F$5:$F$11,WEEKDAY(B23))) | D23: =IF(B23="","","הדרכה "&TEXT(HOUR(הגדרות!$C$20),"00")&":"&TEXT(MINUTE(הגדרות!$C$20),"00")&"–"&TEXT(HOUR(הגדרות!$C$21),"00")&":"&TEXT(MINUTE(הגדרות!$C$21),"00")) | E23: כן | F23: =IF(B23="","",IF(E23="לא",0,הגדרות!$C$22)) | G23: =IF(B23="","",F23*הגדרות!$C$24) | K23: =IF(B23="","",B23+MIN(MOD(הגדרות!$D$18-WEEKDAY(B23)-1,7)+1,MOD(הגדרות!$D$19-WEEKDAY(B23)-1,7)+1))
A24: =IF(B24="","",ROW()-14) | B24: =IF(K23="","",IF(K23>$K$2,"",K23)) | C24: =IF(B24="","",INDEX(הגדרות!$F$5:$F$11,WEEKDAY(B24))) | D24: =IF(B24="","","הדרכה "&TEXT(HOUR(הגדרות!$C$20),"00")&":"&TEXT(MINUTE(הגדרות!$C$20),"00")&"–"&TEXT(HOUR(הגדרות!$C$21),"00")&":"&TEXT(MINUTE(הגדרות!$C$21),"00")) | E24: כן | F24: =IF(B24="","",IF(E24="לא",0,הגדרות!$C$22)) | G24: =IF(B24="","",F24*הגדרות!$C$24) | K24: =IF(B24="","",B24+MIN(MOD(הגדרות!$D$18-WEEKDAY(B24)-1,7)+1,MOD(הגדרות!$D$19-WEEKDAY(B24)-1,7)+1))
A25: =COUNT($B$15:$B$24)+1 -> 9 | C25: =IF(B25="","",INDEX(הגדרות!$F$5:$F$11,WEEKDAY(B25))) | D25: ישיבת צוות חודשית | E25: כן | F25: =IF(E25="לא",0,הגדרות!$C$23) -> 1 | G25: =F25*הגדרות!$C$24 -> 50
A26: סה״כ | F26: =SUM(F15:F25) -> 29 | G26: =SUM(G15:G25) -> 1450 | I26: =SUM(I15:I25) -> 0
A28: הערות | F28: סה״כ שעות | I28: =F26 -> 29
A29: ="• "&הגדרות!$C$17&": ימי "&הגדרות!$C$18&" ו"&הגדרות!$C$19&", "&TEXT(HOUR(הגדרות!$C$20),"00")&":"&TEXT(MINUTE(הגדרות!$C$20),"00")&"–"&TEXT(HOUR(הגדרות!$C$21),"00")&":"&TEXT(MINUTE(הגדרות!$C$21),"00")&" ("&הגדרות!$C$22&" שעות ליום), וישיבת צוות חודשית ("&הגדרות!$C$23&" ש׳)." -> • הדרכת שיקום: ימי ראשון וחמישי, 09:00–12:30 (3.5 שעות ליום), וישיבת צוות חודשית (1 ש׳). | F29: ="הדרכת שיקום ("&TEXT(F26,"0.0")&" שעות × "&הגדרות!$C$24&" ₪)" -> הדרכת שיקום (29.0 שעות × 50 ₪) | I29: =G26 -> 1450
A30: =IF(הגדרות!$C$28="","","• "&הגדרות!$C$28) -> • התעריף השעתי אינו כולל מע״מ. מע״מ יתווסף כחוק. | F30: פרויקטים פרטיים | I30: =I26 -> 0
A31: =IF(הגדרות!$C$29="","","• "&הגדרות!$C$29) -> • פרויקטים פרטיים מתומחרים בנפרד, לפי הזמנת החווה. | F31: סה״כ לפני מע״מ | I31: =I29+I30 -> 1450
A32: =IF(הגדרות!$C$30="","","• "&הגדרות!$C$30) | F32: ="מע״מ "&ROUND(הגדרות!$C$25*100,1)&"%" -> מע״מ 18% | I32: =ROUND(I31*הגדרות!$C$25,2) -> 261
F33: סה״כ לתשלום (כולל מע״מ) | I33: =I31+I32 -> 1711
A36: ="בברכה, "&הגדרות!$C$6 -> בברכה, (למילוי) | F36: חתימה: ____________________

Sheet מרץ 2027
A1: הצעת מחיר | K1: =DATE(YEAR($H$11),MONTH($H$11),1) -> 46447
A2: =הגדרות!$C$17&" · "&CHOOSE(MONTH($K$1),"ינואר","פברואר","מרץ","אפריל","מאי","יוני","יולי","אוגוסט","ספטמבר","אוקטובר","נובמבר","דצמבר")&" "&YEAR($K$1) -> הדרכת שיקום · מרץ 2027 | K2: =EOMONTH($K$1,0) -> 46477
A4: מאת | F4: לכבוד
A5: שם העסק | C5: =הגדרות!$C$5 -> הנגרייה | F5: שם הלקוח | H5: =הגדרות!$C$12 -> חוות רום
A6: שם מלא | C6: =הגדרות!$C$6 -> (למילוי) | F6: כתובת | H6: =הגדרות!$C$13 -> הר כמון
A7: עוסק מורשה | C7: =הגדרות!$C$7 -> (למילוי) | F7: איש קשר | H7: =הגדרות!$C$14 -> (למילוי)
A8: טלפון | C8: =הגדרות!$C$8 -> (למילוי)
A9: אימייל | C9: =הגדרות!$C$9 -> nettaamit21@gmail.com
A11: מס׳ הצעה | C11: =YEAR($K$1)&"-"&TEXT(MONTH($K$1),"00") -> 2027-03 | F11: חודש השירות | H11: 46447
A12: תאריך | C12: =$K$2 -> 46477 | F12: ימי עבודה | H12: =הגדרות!$C$18&" ו"&הגדרות!$C$19&", "&TEXT(HOUR(הגדרות!$C$20),"00")&":"&TEXT(MINUTE(הגדרות!$C$20),"00")&"–"&TEXT(HOUR(הגדרות!$C$21),"00")&":"&TEXT(MINUTE(הגדרות!$C$21),"00") -> ראשון וחמישי, 09:00–12:30
A13: הדרכת שיקום – לפי שעות | H13: פרויקטים פרטיים – תמחור נפרד
A14: # | B14: תאריך | C14: יום | D14: פירוט | E14: התקיים? | F14: שעות | G14: סכום (₪) | H14: פרויקט פרטי – תיאור | I14: פרויקט פרטי – סכום (₪)
A15: =IF(B15="","",ROW()-14) -> 1 | B15: =$K$1+MIN(MOD(הגדרות!$D$18-WEEKDAY($K$1),7),MOD(הגדרות!$D$19-WEEKDAY($K$1),7)) -> 46450 | C15: =IF(B15="","",INDEX(הגדרות!$F$5:$F$11,WEEKDAY(B15))) -> חמישי | D15: =IF(B15="","","הדרכה "&TEXT(HOUR(הגדרות!$C$20),"00")&":"&TEXT(MINUTE(הגדרות!$C$20),"00")&"–"&TEXT(HOUR(הגדרות!$C$21),"00")&":"&TEXT(MINUTE(הגדרות!$C$21),"00")) -> הדרכה 09:00–12:30 | E15: כן | F15: =IF(B15="","",IF(E15="לא",0,הגדרות!$C$22)) -> 3.5 | G15: =IF(B15="","",F15*הגדרות!$C$24) -> 175 | K15: =IF(B15="","",B15+MIN(MOD(הגדרות!$D$18-WEEKDAY(B15)-1,7)+1,MOD(הגדרות!$D$19-WEEKDAY(B15)-1,7)+1)) -> 46453
A16: =IF(B16="","",ROW()-14) -> 2 | B16: =IF(K15="","",IF(K15>$K$2,"",K15)) -> 46453 | C16: =IF(B16="","",INDEX(הגדרות!$F$5:$F$11,WEEKDAY(B16))) -> ראשון | D16: =IF(B16="","","הדרכה "&TEXT(HOUR(הגדרות!$C$20),"00")&":"&TEXT(MINUTE(הגדרות!$C$20),"00")&"–"&TEXT(HOUR(הגדרות!$C$21),"00")&":"&TEXT(MINUTE(הגדרות!$C$21),"00")) -> הדרכה 09:00–12:30 | E16: כן | F16: =IF(B16="","",IF(E16="לא",0,הגדרות!$C$22)) -> 3.5 | G16: =IF(B16="","",F16*הגדרות!$C$24) -> 175 | K16: =IF(B16="","",B16+MIN(MOD(הגדרות!$D$18-WEEKDAY(B16)-1,7)+1,MOD(הגדרות!$D$19-WEEKDAY(B16)-1,7)+1)) -> 46457
A17: =IF(B17="","",ROW()-14) -> 3 | B17: =IF(K16="","",IF(K16>$K$2,"",K16)) -> 46457 | C17: =IF(B17="","",INDEX(הגדרות!$F$5:$F$11,WEEKDAY(B17))) -> חמישי | D17: =IF(B17="","","הדרכה "&TEXT(HOUR(הגדרות!$C$20),"00")&":"&TEXT(MINUTE(הגדרות!$C$20),"00")&"–"&TEXT(HOUR(הגדרות!$C$21),"00")&":"&TEXT(MINUTE(הגדרות!$C$21),"00")) -> הדרכה 09:00–12:30 | E17: כן | F17: =IF(B17="","",IF(E17="לא",0,הגדרות!$C$22)) -> 3.5 | G17: =IF(B17="","",F17*הגדרות!$C$24) -> 175 | K17: =IF(B17="","",B17+MIN(MOD(הגדרות!$D$18-WEEKDAY(B17)-1,7)+1,MOD(הגדרות!$D$19-WEEKDAY(B17)-1,7)+1)) -> 46460
A18: =IF(B18="","",ROW()-14) -> 4 | B18: =IF(K17="","",IF(K17>$K$2,"",K17)) -> 46460 | C18: =IF(B18="","",INDEX(הגדרות!$F$5:$F$11,WEEKDAY(B18))) -> ראשון | D18: =IF(B18="","","הדרכה "&TEXT(HOUR(הגדרות!$C$20),"00")&":"&TEXT(MINUTE(הגדרות!$C$20),"00")&"–"&TEXT(HOUR(הגדרות!$C$21),"00")&":"&TEXT(MINUTE(הגדרות!$C$21),"00")) -> הדרכה 09:00–12:30 | E18: כן | F18: =IF(B18="","",IF(E18="לא",0,הגדרות!$C$22)) -> 3.5 | G18: =IF(B18="","",F18*הגדרות!$C$24) -> 175 | K18: =IF(B18="","",B18+MIN(MOD(הגדרות!$D$18-WEEKDAY(B18)-1,7)+1,MOD(הגדרות!$D$19-WEEKDAY(B18)-1,7)+1)) -> 46464
A19: =IF(B19="","",ROW()-14) -> 5 | B19: =IF(K18="","",IF(K18>$K$2,"",K18)) -> 46464 | C19: =IF(B19="","",INDEX(הגדרות!$F$5:$F$11,WEEKDAY(B19))) -> חמישי | D19: =IF(B19="","","הדרכה "&TEXT(HOUR(הגדרות!$C$20),"00")&":"&TEXT(MINUTE(הגדרות!$C$20),"00")&"–"&TEXT(HOUR(הגדרות!$C$21),"00")&":"&TEXT(MINUTE(הגדרות!$C$21),"00")) -> הדרכה 09:00–12:30 | E19: כן | F19: =IF(B19="","",IF(E19="לא",0,הגדרות!$C$22)) -> 3.5 | G19: =IF(B19="","",F19*הגדרות!$C$24) -> 175 | K19: =IF(B19="","",B19+MIN(MOD(הגדרות!$D$18-WEEKDAY(B19)-1,7)+1,MOD(הגדרות!$D$19-WEEKDAY(B19)-1,7)+1)) -> 46467
A20: =IF(B20="","",ROW()-14) -> 6 | B20: =IF(K19="","",IF(K19>$K$2,"",K19)) -> 46467 | C20: =IF(B20="","",INDEX(הגדרות!$F$5:$F$11,WEEKDAY(B20))) -> ראשון | D20: =IF(B20="","","הדרכה "&TEXT(HOUR(הגדרות!$C$20),"00")&":"&TEXT(MINUTE(הגדרות!$C$20),"00")&"–"&TEXT(HOUR(הגדרות!$C$21),"00")&":"&TEXT(MINUTE(הגדרות!$C$21),"00")) -> הדרכה 09:00–12:30 | E20: כן | F20: =IF(B20="","",IF(E20="לא",0,הגדרות!$C$22)) -> 3.5 | G20: =IF(B20="","",F20*הגדרות!$C$24) -> 175 | K20: =IF(B20="","",B20+MIN(MOD(הגדרות!$D$18-WEEKDAY(B20)-1,7)+1,MOD(הגדרות!$D$19-WEEKDAY(B20)-1,7)+1)) -> 46471
A21: =IF(B21="","",ROW()-14) -> 7 | B21: =IF(K20="","",IF(K20>$K$2,"",K20)) -> 46471 | C21: =IF(B21="","",INDEX(הגדרות!$F$5:$F$11,WEEKDAY(B21))) -> חמישי | D21: =IF(B21="","","הדרכה "&TEXT(HOUR(הגדרות!$C$20),"00")&":"&TEXT(MINUTE(הגדרות!$C$20),"00")&"–"&TEXT(HOUR(הגדרות!$C$21),"00")&":"&TEXT(MINUTE(הגדרות!$C$21),"00")) -> הדרכה 09:00–12:30 | E21: כן | F21: =IF(B21="","",IF(E21="לא",0,הגדרות!$C$22)) -> 3.5 | G21: =IF(B21="","",F21*הגדרות!$C$24) -> 175 | K21: =IF(B21="","",B21+MIN(MOD(הגדרות!$D$18-WEEKDAY(B21)-1,7)+1,MOD(הגדרות!$D$19-WEEKDAY(B21)-1,7)+1)) -> 46474
A22: =IF(B22="","",ROW()-14) -> 8 | B22: =IF(K21="","",IF(K21>$K$2,"",K21)) -> 46474 | C22: =IF(B22="","",INDEX(הגדרות!$F$5:$F$11,WEEKDAY(B22))) -> ראשון | D22: =IF(B22="","","הדרכה "&TEXT(HOUR(הגדרות!$C$20),"00")&":"&TEXT(MINUTE(הגדרות!$C$20),"00")&"–"&TEXT(HOUR(הגדרות!$C$21),"00")&":"&TEXT(MINUTE(הגדרות!$C$21),"00")) -> הדרכה 09:00–12:30 | E22: כן | F22: =IF(B22="","",IF(E22="לא",0,הגדרות!$C$22)) -> 3.5 | G22: =IF(B22="","",F22*הגדרות!$C$24) -> 175 | K22: =IF(B22="","",B22+MIN(MOD(הגדרות!$D$18-WEEKDAY(B22)-1,7)+1,MOD(הגדרות!$D$19-WEEKDAY(B22)-1,7)+1)) -> 46478
A23: =IF(B23="","",ROW()-14) | B23: =IF(K22="","",IF(K22>$K$2,"",K22)) | C23: =IF(B23="","",INDEX(הגדרות!$F$5:$F$11,WEEKDAY(B23))) | D23: =IF(B23="","","הדרכה "&TEXT(HOUR(הגדרות!$C$20),"00")&":"&TEXT(MINUTE(הגדרות!$C$20),"00")&"–"&TEXT(HOUR(הגדרות!$C$21),"00")&":"&TEXT(MINUTE(הגדרות!$C$21),"00")) | E23: כן | F23: =IF(B23="","",IF(E23="לא",0,הגדרות!$C$22)) | G23: =IF(B23="","",F23*הגדרות!$C$24) | K23: =IF(B23="","",B23+MIN(MOD(הגדרות!$D$18-WEEKDAY(B23)-1,7)+1,MOD(הגדרות!$D$19-WEEKDAY(B23)-1,7)+1))
A24: =IF(B24="","",ROW()-14) | B24: =IF(K23="","",IF(K23>$K$2,"",K23)) | C24: =IF(B24="","",INDEX(הגדרות!$F$5:$F$11,WEEKDAY(B24))) | D24: =IF(B24="","","הדרכה "&TEXT(HOUR(הגדרות!$C$20),"00")&":"&TEXT(MINUTE(הגדרות!$C$20),"00")&"–"&TEXT(HOUR(הגדרות!$C$21),"00")&":"&TEXT(MINUTE(הגדרות!$C$21),"00")) | E24: כן | F24: =IF(B24="","",IF(E24="לא",0,הגדרות!$C$22)) | G24: =IF(B24="","",F24*הגדרות!$C$24) | K24: =IF(B24="","",B24+MIN(MOD(הגדרות!$D$18-WEEKDAY(B24)-1,7)+1,MOD(הגדרות!$D$19-WEEKDAY(B24)-1,7)+1))
A25: =COUNT($B$15:$B$24)+1 -> 9 | C25: =IF(B25="","",INDEX(הגדרות!$F$5:$F$11,WEEKDAY(B25))) | D25: ישיבת צוות חודשית | E25: כן | F25: =IF(E25="לא",0,הגדרות!$C$23) -> 1 | G25: =F25*הגדרות!$C$24 -> 50
A26: סה״כ | F26: =SUM(F15:F25) -> 29 | G26: =SUM(G15:G25) -> 1450 | I26: =SUM(I15:I25) -> 0
A28: הערות | F28: סה״כ שעות | I28: =F26 -> 29
A29: ="• "&הגדרות!$C$17&": ימי "&הגדרות!$C$18&" ו"&הגדרות!$C$19&", "&TEXT(HOUR(הגדרות!$C$20),"00")&":"&TEXT(MINUTE(הגדרות!$C$20),"00")&"–"&TEXT(HOUR(הגדרות!$C$21),"00")&":"&TEXT(MINUTE(הגדרות!$C$21),"00")&" ("&הגדרות!$C$22&" שעות ליום), וישיבת צוות חודשית ("&הגדרות!$C$23&" ש׳)." -> • הדרכת שיקום: ימי ראשון וחמישי, 09:00–12:30 (3.5 שעות ליום), וישיבת צוות חודשית (1 ש׳). | F29: ="הדרכת שיקום ("&TEXT(F26,"0.0")&" שעות × "&הגדרות!$C$24&" ₪)" -> הדרכת שיקום (29.0 שעות × 50 ₪) | I29: =G26 -> 1450
A30: =IF(הגדרות!$C$28="","","• "&הגדרות!$C$28) -> • התעריף השעתי אינו כולל מע״מ. מע״מ יתווסף כחוק. | F30: פרויקטים פרטיים | I30: =I26 -> 0
A31: =IF(הגדרות!$C$29="","","• "&הגדרות!$C$29) -> • פרויקטים פרטיים מתומחרים בנפרד, לפי הזמנת החווה. | F31: סה״כ לפני מע״מ | I31: =I29+I30 -> 1450
A32: =IF(הגדרות!$C$30="","","• "&הגדרות!$C$30) | F32: ="מע״מ "&ROUND(הגדרות!$C$25*100,1)&"%" -> מע״מ 18% | I32: =ROUND(I31*הגדרות!$C$25,2) -> 261
F33: סה״כ לתשלום (כולל מע״מ) | I33: =I31+I32 -> 1711
A36: ="בברכה, "&הגדרות!$C$6 -> בברכה, (למילוי) | F36: חתימה: ____________________

Sheet אפריל 2027
A1: הצעת מחיר | K1: =DATE(YEAR($H$11),MONTH($H$11),1) -> 46478
A2: =הגדרות!$C$17&" · "&CHOOSE(MONTH($K$1),"ינואר","פברואר","מרץ","אפריל","מאי","יוני","יולי","אוגוסט","ספטמבר","אוקטובר","נובמבר","דצמבר")&" "&YEAR($K$1) -> הדרכת שיקום · אפריל 2027 | K2: =EOMONTH($K$1,0) -> 46507
A4: מאת | F4: לכבוד
A5: שם העסק | C5: =הגדרות!$C$5 -> הנגרייה | F5: שם הלקוח | H5: =הגדרות!$C$12 -> חוות רום
A6: שם מלא | C6: =הגדרות!$C$6 -> (למילוי) | F6: כתובת | H6: =הגדרות!$C$13 -> הר כמון
A7: עוסק מורשה | C7: =הגדרות!$C$7 -> (למילוי) | F7: איש קשר | H7: =הגדרות!$C$14 -> (למילוי)
A8: טלפון | C8: =הגדרות!$C$8 -> (למילוי)
A9: אימייל | C9: =הגדרות!$C$9 -> nettaamit21@gmail.com
A11: מס׳ הצעה | C11: =YEAR($K$1)&"-"&TEXT(MONTH($K$1),"00") -> 2027-04 | F11: חודש השירות | H11: 46478
A12: תאריך | C12: =$K$2 -> 46507 | F12: ימי עבודה | H12: =הגדרות!$C$18&" ו"&הגדרות!$C$19&", "&TEXT(HOUR(הגדרות!$C$20),"00")&":"&TEXT(MINUTE(הגדרות!$C$20),"00")&"–"&TEXT(HOUR(הגדרות!$C$21),"00")&":"&TEXT(MINUTE(הגדרות!$C$21),"00") -> ראשון וחמישי, 09:00–12:30
A13: הדרכת שיקום – לפי שעות | H13: פרויקטים פרטיים – תמחור נפרד
A14: # | B14: תאריך | C14: יום | D14: פירוט | E14: התקיים? | F14: שעות | G14: סכום (₪) | H14: פרויקט פרטי – תיאור | I14: פרויקט פרטי – סכום (₪)
A15: =IF(B15="","",ROW()-14) -> 1 | B15: =$K$1+MIN(MOD(הגדרות!$D$18-WEEKDAY($K$1),7),MOD(הגדרות!$D$19-WEEKDAY($K$1),7)) -> 46478 | C15: =IF(B15="","",INDEX(הגדרות!$F$5:$F$11,WEEKDAY(B15))) -> חמישי | D15: =IF(B15="","","הדרכה "&TEXT(HOUR(הגדרות!$C$20),"00")&":"&TEXT(MINUTE(הגדרות!$C$20),"00")&"–"&TEXT(HOUR(הגדרות!$C$21),"00")&":"&TEXT(MINUTE(הגדרות!$C$21),"00")) -> הדרכה 09:00–12:30 | E15: כן | F15: =IF(B15="","",IF(E15="לא",0,הגדרות!$C$22)) -> 3.5 | G15: =IF(B15="","",F15*הגדרות!$C$24) -> 175 | K15: =IF(B15="","",B15+MIN(MOD(הגדרות!$D$18-WEEKDAY(B15)-1,7)+1,MOD(הגדרות!$D$19-WEEKDAY(B15)-1,7)+1)) -> 46481
A16: =IF(B16="","",ROW()-14) -> 2 | B16: =IF(K15="","",IF(K15>$K$2,"",K15)) -> 46481 | C16: =IF(B16="","",INDEX(הגדרות!$F$5:$F$11,WEEKDAY(B16))) -> ראשון | D16: =IF(B16="","","הדרכה "&TEXT(HOUR(הגדרות!$C$20),"00")&":"&TEXT(MINUTE(הגדרות!$C$20),"00")&"–"&TEXT(HOUR(הגדרות!$C$21),"00")&":"&TEXT(MINUTE(הגדרות!$C$21),"00")) -> הדרכה 09:00–12:30 | E16: כן | F16: =IF(B16="","",IF(E16="לא",0,הגדרות!$C$22)) -> 3.5 | G16: =IF(B16="","",F16*הגדרות!$C$24) -> 175 | K16: =IF(B16="","",B16+MIN(MOD(הגדרות!$D$18-WEEKDAY(B16)-1,7)+1,MOD(הגדרות!$D$19-WEEKDAY(B16)-1,7)+1)) -> 46485
A17: =IF(B17="","",ROW()-14) -> 3 | B17: =IF(K16="","",IF(K16>$K$2,"",K16)) -> 46485 | C17: =IF(B17="","",INDEX(הגדרות!$F$5:$F$11,WEEKDAY(B17))) -> חמישי | D17: =IF(B17="","","הדרכה "&TEXT(HOUR(הגדרות!$C$20),"00")&":"&TEXT(MINUTE(הגדרות!$C$20),"00")&"–"&TEXT(HOUR(הגדרות!$C$21),"00")&":"&TEXT(MINUTE(הגדרות!$C$21),"00")) -> הדרכה 09:00–12:30 | E17: כן | F17: =IF(B17="","",IF(E17="לא",0,הגדרות!$C$22)) -> 3.5 | G17: =IF(B17="","",F17*הגדרות!$C$24) -> 175 | K17: =IF(B17="","",B17+MIN(MOD(הגדרות!$D$18-WEEKDAY(B17)-1,7)+1,MOD(הגדרות!$D$19-WEEKDAY(B17)-1,7)+1)) -> 46488
A18: =IF(B18="","",ROW()-14) -> 4 | B18: =IF(K17="","",IF(K17>$K$2,"",K17)) -> 46488 | C18: =IF(B18="","",INDEX(הגדרות!$F$5:$F$11,WEEKDAY(B18))) -> ראשון | D18: =IF(B18="","","הדרכה "&TEXT(HOUR(הגדרות!$C$20),"00")&":"&TEXT(MINUTE(הגדרות!$C$20),"00")&"–"&TEXT(HOUR(הגדרות!$C$21),"00")&":"&TEXT(MINUTE(הגדרות!$C$21),"00")) -> הדרכה 09:00–12:30 | E18: כן | F18: =IF(B18="","",IF(E18="לא",0,הגדרות!$C$22)) -> 3.5 | G18: =IF(B18="","",F18*הגדרות!$C$24) -> 175 | K18: =IF(B18="","",B18+MIN(MOD(הגדרות!$D$18-WEEKDAY(B18)-1,7)+1,MOD(הגדרות!$D$19-WEEKDAY(B18)-1,7)+1)) -> 46492
A19: =IF(B19="","",ROW()-14) -> 5 | B19: =IF(K18="","",IF(K18>$K$2,"",K18)) -> 46492 | C19: =IF(B19="","",INDEX(הגדרות!$F$5:$F$11,WEEKDAY(B19))) -> חמישי | D19: =IF(B19="","","הדרכה "&TEXT(HOUR(הגדרות!$C$20),"00")&":"&TEXT(MINUTE(הגדרות!$C$20),"00")&"–"&TEXT(HOUR(הגדרות!$C$21),"00")&":"&TEXT(MINUTE(הגדרות!$C$21),"00")) -> הדרכה 09:00–12:30 | E19: כן | F19: =IF(B19="","",IF(E19="לא",0,הגדרות!$C$22)) -> 3.5 | G19: =IF(B19="","",F19*הגדרות!$C$24) -> 175 | K19: =IF(B19="","",B19+MIN(MOD(הגדרות!$D$18-WEEKDAY(B19)-1,7)+1,MOD(הגדרות!$D$19-WEEKDAY(B19)-1,7)+1)) -> 46495
A20: =IF(B20="","",ROW()-14) -> 6 | B20: =IF(K19="","",IF(K19>$K$2,"",K19)) -> 46495 | C20: =IF(B20="","",INDEX(הגדרות!$F$5:$F$11,WEEKDAY(B20))) -> ראשון | D20: =IF(B20="","","הדרכה "&TEXT(HOUR(הגדרות!$C$20),"00")&":"&TEXT(MINUTE(הגדרות!$C$20),"00")&"–"&TEXT(HOUR(הגדרות!$C$21),"00")&":"&TEXT(MINUTE(הגדרות!$C$21),"00")) -> הדרכה 09:00–12:30 | E20: כן | F20: =IF(B20="","",IF(E20="לא",0,הגדרות!$C$22)) -> 3.5 | G20: =IF(B20="","",F20*הגדרות!$C$24) -> 175 | K20: =IF(B20="","",B20+MIN(MOD(הגדרות!$D$18-WEEKDAY(B20)-1,7)+1,MOD(הגדרות!$D$19-WEEKDAY(B20)-1,7)+1)) -> 46499
A21: =IF(B21="","",ROW()-14) -> 7 | B21: =IF(K20="","",IF(K20>$K$2,"",K20)) -> 46499 | C21: =IF(B21="","",INDEX(הגדרות!$F$5:$F$11,WEEKDAY(B21))) -> חמישי | D21: =IF(B21="","","הדרכה "&TEXT(HOUR(הגדרות!$C$20),"00")&":"&TEXT(MINUTE(הגדרות!$C$20),"00")&"–"&TEXT(HOUR(הגדרות!$C$21),"00")&":"&TEXT(MINUTE(הגדרות!$C$21),"00")) -> הדרכה 09:00–12:30 | E21: כן | F21: =IF(B21="","",IF(E21="לא",0,הגדרות!$C$22)) -> 3.5 | G21: =IF(B21="","",F21*הגדרות!$C$24) -> 175 | K21: =IF(B21="","",B21+MIN(MOD(הגדרות!$D$18-WEEKDAY(B21)-1,7)+1,MOD(הגדרות!$D$19-WEEKDAY(B21)-1,7)+1)) -> 46502
A22: =IF(B22="","",ROW()-14) -> 8 | B22: =IF(K21="","",IF(K21>$K$2,"",K21)) -> 46502 | C22: =IF(B22="","",INDEX(הגדרות!$F$5:$F$11,WEEKDAY(B22))) -> ראשון | D22: =IF(B22="","","הדרכה "&TEXT(HOUR(הגדרות!$C$20),"00")&":"&TEXT(MINUTE(הגדרות!$C$20),"00")&"–"&TEXT(HOUR(הגדרות!$C$21),"00")&":"&TEXT(MINUTE(הגדרות!$C$21),"00")) -> הדרכה 09:00–12:30 | E22: כן | F22: =IF(B22="","",IF(E22="לא",0,הגדרות!$C$22)) -> 3.5 | G22: =IF(B22="","",F22*הגדרות!$C$24) -> 175 | K22: =IF(B22="","",B22+MIN(MOD(הגדרות!$D$18-WEEKDAY(B22)-1,7)+1,MOD(הגדרות!$D$19-WEEKDAY(B22)-1,7)+1)) -> 46506
A23: =IF(B23="","",ROW()-14) -> 9 | B23: =IF(K22="","",IF(K22>$K$2,"",K22)) -> 46506 | C23: =IF(B23="","",INDEX(הגדרות!$F$5:$F$11,WEEKDAY(B23))) -> חמישי | D23: =IF(B23="","","הדרכה "&TEXT(HOUR(הגדרות!$C$20),"00")&":"&TEXT(MINUTE(הגדרות!$C$20),"00")&"–"&TEXT(HOUR(הגדרות!$C$21),"00")&":"&TEXT(MINUTE(הגדרות!$C$21),"00")) -> הדרכה 09:00–12:30 | E23: כן | F23: =IF(B23="","",IF(E23="לא",0,הגדרות!$C$22)) -> 3.5 | G23: =IF(B23="","",F23*הגדרות!$C$24) -> 175 | K23: =IF(B23="","",B23+MIN(MOD(הגדרות!$D$18-WEEKDAY(B23)-1,7)+1,MOD(הגדרות!$D$19-WEEKDAY(B23)-1,7)+1)) -> 46509
A24: =IF(B24="","",ROW()-14) | B24: =IF(K23="","",IF(K23>$K$2,"",K23)) | C24: =IF(B24="","",INDEX(הגדרות!$F$5:$F$11,WEEKDAY(B24))) | D24: =IF(B24="","","הדרכה "&TEXT(HOUR(הגדרות!$C$20),"00")&":"&TEXT(MINUTE(הגדרות!$C$20),"00")&"–"&TEXT(HOUR(הגדרות!$C$21),"00")&":"&TEXT(MINUTE(הגדרות!$C$21),"00")) | E24: כן | F24: =IF(B24="","",IF(E24="לא",0,הגדרות!$C$22)) | G24: =IF(B24="","",F24*הגדרות!$C$24) | K24: =IF(B24="","",B24+MIN(MOD(הגדרות!$D$18-WEEKDAY(B24)-1,7)+1,MOD(הגדרות!$D$19-WEEKDAY(B24)-1,7)+1))
A25: =COUNT($B$15:$B$24)+1 -> 10 | C25: =IF(B25="","",INDEX(הגדרות!$F$5:$F$11,WEEKDAY(B25))) | D25: ישיבת צוות חודשית | E25: כן | F25: =IF(E25="לא",0,הגדרות!$C$23) -> 1 | G25: =F25*הגדרות!$C$24 -> 50
A26: סה״כ | F26: =SUM(F15:F25) -> 32.5 | G26: =SUM(G15:G25) -> 1625 | I26: =SUM(I15:I25) -> 0
A28: הערות | F28: סה״כ שעות | I28: =F26 -> 32.5
